<?xml version="1.0" ?>
<robot name="converted_robot">
   <link name="world">
      <inertial>
         <origin xyz="0.0 0.0 0.0" rpy="0.0 0.0 0.0"/>
         <mass value="0.0"/>
         <inertia ixx="0.0" iyy="0.0" izz="0.0" ixy="0" ixz="0" iyz="0"/>
      </inertial>
   </link>
   <link name="connector_base">
      <inertial>
         <origin xyz="-8.875956983112415e-08 0.005853447472218917 0.010651220515507645" rpy="0.0 -1.546757664231415 1.5707963267948966"/>
         <mass value="0.07977435345832029"/>
         <inertia ixx="7.214481044209698e-05" iyy="7.16441197786828e-05" izz="1.2264239349426065e-05" ixy="0" ixz="0" iyz="0"/>
      </inertial>
      <visual name="connector_base">
         <origin xyz="-8.875956983112415e-08 0.005853447472218917 0.010651220515507645" rpy="0.0 -1.546757664231415 1.5707963267948966"/>
         <geometry>
            <mesh filename="package://viz/models/titans_hand/urdf/converted_mesh/converted_connector_base.stl"/>
         </geometry>
         <material name="white"/>
      </visual>
   </link>
   <link name="world2connector_base_fixed_jointbody">
      <inertial>
         <origin xyz="0.0 0.0 0.0" rpy="0.0 0.0 0.0"/>
         <mass value="0.001"/>
         <inertia ixx="1e-09" iyy="1e-09" izz="1e-09" ixy="0" ixz="0" iyz="0"/>
      </inertial>
   </link>
   <joint type="fixed" name="world2connector_base_fixed">
      <parent link="world"/>
      <child link="world2connector_base_fixed_jointbody"/>
      <origin xyz="0.0 0.0 0.0" rpy="0.0 0.0 0.0"/>
   </joint>
   <joint type="fixed" name="world2connector_base_fixed_offset">
      <parent link="world2connector_base_fixed_jointbody"/>
      <child link="connector_base"/>
      <origin xyz="-0.0 -0.0 -0.0" rpy="0.0 0.0 0.0"/>
   </joint>
   <link name="wrist">
      <inertial>
         <origin xyz="-2.7361539013302475e-05 0.006632790560902979 0.040716428324654094" rpy="1.582645583609881 0.00506883834586902 -0.0007430489014532693"/>
         <mass value="0.08032373127609675"/>
         <inertia ixx="8.009150976936333e-05" iyy="7.667345488727809e-05" izz="5.544966338921669e-06" ixy="0" ixz="0" iyz="0"/>
      </inertial>
      <visual name="wrist">
         <origin xyz="-2.7361539013302475e-05 0.006632790560902979 0.040716428324654094" rpy="1.5826455836098812 0.005068838345869242 -0.0007430489014533803"/>
         <geometry>
            <mesh filename="package://viz/models/titans_hand/urdf/converted_mesh/converted_wrist.stl"/>
         </geometry>
         <material name="white"/>
      </visual>
   </link>
   <link name="revolute_base_hand_jointbody">
      <inertial>
         <origin xyz="0.0 0.0 0.0" rpy="0.0 0.0 0.0"/>
         <mass value="0.001"/>
         <inertia ixx="1e-09" iyy="1e-09" izz="1e-09" ixy="0" ixz="0" iyz="0"/>
      </inertial>
   </link>
   <joint type="revolute" name="revolute_base_hand">
      <parent link="connector_base"/>
      <child link="revolute_base_hand_jointbody"/>
      <origin xyz="0.0 -0.0388 0.03" rpy="0.0 0.0 0.0"/>
      <axis xyz="0.0 1.0 0.0"/>
      <limit lower="-1.5707" upper="1.5707" effort="100" velocity="100"/>
   </joint>
   <joint type="fixed" name="revolute_base_hand_offset">
      <parent link="revolute_base_hand_jointbody"/>
      <child link="wrist"/>
      <origin xyz="-0.0 0.0388 -0.03" rpy="0.0 0.0 0.0"/>
   </joint>
   <link name="palm">
      <inertial>
         <origin xyz="0.0004985657687111454 0.012986231765808095 0.0842484060450945" rpy="1.8166143224613616 -0.034173445753463705 6.244104871999667e-05"/>
         <mass value="0.08495943957289792"/>
         <inertia ixx="7.262637133602139e-05" iyy="5.094037047738861e-05" izz="2.3939714595959797e-05" ixy="0" ixz="0" iyz="0"/>
      </inertial>
      <visual name="palm">
         <origin xyz="0.0004985657687111454 0.012986231765808095 0.0842484060450945" rpy="1.8166143224613618 -0.034173445753463705 6.244104871999667e-05"/>
         <geometry>
            <mesh filename="package://viz/models/titans_hand/urdf/converted_mesh/converted_palm.stl"/>
         </geometry>
         <material name="white"/>
      </visual>
   </link>
   <link name="wrist2palm_fixed_jointbody">
      <inertial>
         <origin xyz="0.0 0.0 0.0" rpy="0.0 0.0 0.0"/>
         <mass value="0.001"/>
         <inertia ixx="1e-09" iyy="1e-09" izz="1e-09" ixy="0" ixz="0" iyz="0"/>
      </inertial>
   </link>
   <joint type="fixed" name="wrist2palm_fixed">
      <parent link="wrist"/>
      <child link="wrist2palm_fixed_jointbody"/>
      <origin xyz="0.0 0.0 0.0" rpy="0.0 0.0 0.0"/>
   </joint>
   <joint type="fixed" name="wrist2palm_fixed_offset">
      <parent link="wrist2palm_fixed_jointbody"/>
      <child link="palm"/>
      <origin xyz="-0.0 -0.0 -0.0" rpy="0.0 0.0 0.0"/>
   </joint>
   <link name="thumb_base">
      <inertial>
         <origin xyz="-0.002984118367370552 0.05250829152323535 0.07641288937087239" rpy="-1.7761214941675143 -1.3757364534244798 -2.4692779894816543"/>
         <mass value="0.011927349600745834"/>
         <inertia ixx="1.331480796632207e-06" iyy="1.187307969976632e-06" izz="8.100218428031823e-07" ixy="0" ixz="0" iyz="0"/>
      </inertial>
      <visual name="thumb_hinge">
         <origin xyz="-0.002984118367370552 0.05250829152323535 0.07641288937087239" rpy="-1.7761214941675154 -1.3757364534244798 -2.469277989481654"/>
         <geometry>
            <mesh filename="package://viz/models/titans_hand/urdf/converted_mesh/converted_thumb_hinge.stl"/>
         </geometry>
         <material name="white"/>
      </visual>
   </link>
   <link name="thumb_hinge_jointbody">
      <inertial>
         <origin xyz="0.0 0.0 0.0" rpy="0.0 0.0 0.0"/>
         <mass value="0.001"/>
         <inertia ixx="1e-09" iyy="1e-09" izz="1e-09" ixy="0" ixz="0" iyz="0"/>
      </inertial>
   </link>
   <joint type="revolute" name="thumb_hinge">
      <parent link="palm"/>
      <child link="thumb_hinge_jointbody"/>
      <origin xyz="0.0 0.0393 0.06872" rpy="0.0 0.0 0.0"/>
      <axis xyz="0.0 0.3420201432984737 0.9396926207958065"/>
      <limit lower="-1.75" upper="0.786" effort="100" velocity="100"/>
   </joint>
   <joint type="fixed" name="thumb_hinge_offset">
      <parent link="thumb_hinge_jointbody"/>
      <child link="thumb_base"/>
      <origin xyz="-0.0 -0.0393 -0.06872" rpy="0.0 0.0 0.0"/>
   </joint>
   <link name="thumb_pp">
      <inertial>
         <origin xyz="-0.005119293729444471 0.06283677218500093 0.09475499291547582" rpy="-0.0010123569356891985 -0.072644491118802 0.0034530478183920008"/>
         <mass value="0.008517951004271104"/>
         <inertia ixx="1.3072129655499252e-06" iyy="1.2915714498132682e-06" izz="1.9551824716339084e-07" ixy="0" ixz="0" iyz="0"/>
      </inertial>
      <visual name="thumb_pp">
         <origin xyz="-0.005119293729444471 0.06283677218500093 0.09475499291547582" rpy="-0.0010123569356891985 -0.072644491118802 0.0034530478183920008"/>
         <geometry>
            <mesh filename="package://viz/models/titans_hand/urdf/converted_mesh/converted_thumb_pp.stl"/>
         </geometry>
         <material name="white"/>
      </visual>
   </link>
   <link name="thumb_base2pp_jointbody">
      <inertial>
         <origin xyz="0.0 0.0 0.0" rpy="0.0 0.0 0.0"/>
         <mass value="0.001"/>
         <inertia ixx="1e-09" iyy="1e-09" izz="1e-09" ixy="0" ixz="0" iyz="0"/>
      </inertial>
   </link>
   <joint type="revolute" name="thumb_base2pp">
      <parent link="thumb_base"/>
      <child link="thumb_base2pp_jointbody"/>
      <origin xyz="0.0 0.06283 0.07774" rpy="0.0 0.0 0.0"/>
      <axis xyz="1.0 0.0 0.0"/>
      <limit lower="-3.141592" upper="0.0" effort="100" velocity="100"/>
   </joint>
   <joint type="fixed" name="thumb_base2pp_offset">
      <parent link="thumb_base2pp_jointbody"/>
      <child link="thumb_pp"/>
      <origin xyz="-0.0 -0.06283 -0.07774" rpy="0.0 0.0 0.0"/>
   </joint>
   <link name="thumb_mp_virt">
      <inertial>
         <origin xyz="0.009525 -0.041187 0.083647" rpy="0.0 0.0 0.0"/>
         <mass value="0.001"/>
         <inertia ixx="4e-10" iyy="4e-10" izz="3e-10" ixy="0" ixz="0" iyz="0"/>
      </inertial>
   </link>
   <link name="thumb_pp2mp_virt_jointbody">
      <inertial>
         <origin xyz="0.0 0.0 0.0" rpy="0.0 0.0 0.0"/>
         <mass value="0.001"/>
         <inertia ixx="1e-09" iyy="1e-09" izz="1e-09" ixy="0" ixz="0" iyz="0"/>
      </inertial>
   </link>
   <joint type="revolute" name="thumb_pp2mp_virt">
      <parent link="thumb_pp"/>
      <child link="thumb_pp2mp_virt_jointbody"/>
      <origin xyz="-0.0079 0.06483 0.11245" rpy="0.0 0.0 0.0"/>
      <axis xyz="0.0 1.0 0.0"/>
      <limit lower="-0.131" upper="0.96" effort="100" velocity="100"/>
   </joint>
   <joint type="fixed" name="thumb_pp2mp_virt_offset">
      <parent link="thumb_pp2mp_virt_jointbody"/>
      <child link="thumb_mp_virt"/>
      <origin xyz="0.0079 -0.06483 -0.11245" rpy="0.0 0.0 0.0"/>
   </joint>
   <link name="thumb_mp">
      <inertial>
         <origin xyz="-0.00544140617032902 0.06282976935826087 0.13108060150754744" rpy="0.0034460599232097114 0.04055472747279598 0.005967982758740923"/>
         <mass value="0.0036257578156079634"/>
         <inertia ixx="2.3818490558554055e-07" iyy="2.0716154410734043e-07" izz="6.832850890110207e-08" ixy="0" ixz="0" iyz="0"/>
      </inertial>
      <visual name="thumb_mp">
         <origin xyz="-0.00544140617032902 0.06282976935826087 0.13108060150754744" rpy="0.0034460599232097123 0.040554727472796204 0.0059679827587409235"/>
         <geometry>
            <mesh filename="package://viz/models/titans_hand/urdf/converted_mesh/converted_thumb_mp.stl"/>
         </geometry>
         <material name="white"/>
      </visual>
   </link>
   <link name="thumb_pp2mp_jointbody">
      <inertial>
         <origin xyz="0.0 0.0 0.0" rpy="0.0 0.0 0.0"/>
         <mass value="0.001"/>
         <inertia ixx="1e-09" iyy="1e-09" izz="1e-09" ixy="0" ixz="0" iyz="0"/>
      </inertial>
   </link>
   <joint type="revolute" name="thumb_pp2mp">
      <parent link="thumb_mp_virt"/>
      <child link="thumb_pp2mp_jointbody"/>
      <origin xyz="-0.00696 0.06533 0.1236" rpy="0.0 0.0 0.0"/>
      <axis xyz="0.0 1.0 0.0"/>
      <limit lower="-0.131" upper="0.96" effort="100" velocity="100"/>
   </joint>
   <joint type="fixed" name="thumb_pp2mp_offset">
      <parent link="thumb_pp2mp_jointbody"/>
      <child link="thumb_mp"/>
      <origin xyz="0.00696 -0.06533 -0.1236" rpy="0.0 0.0 0.0"/>
   </joint>
   <link name="thumb_dp_virt">
      <inertial>
         <origin xyz="0.009525 -0.041187 0.083647" rpy="0.0 0.0 0.0"/>
         <mass value="0.001"/>
         <inertia ixx="4e-10" iyy="4e-10" izz="3e-10" ixy="0" ixz="0" iyz="0"/>
      </inertial>
   </link>
   <link name="thumb_mp2dp_virt_jointbody">
      <inertial>
         <origin xyz="0.0 0.0 0.0" rpy="0.0 0.0 0.0"/>
         <mass value="0.001"/>
         <inertia ixx="1e-09" iyy="1e-09" izz="1e-09" ixy="0" ixz="0" iyz="0"/>
      </inertial>
   </link>
   <joint type="revolute" name="thumb_mp2dp_virt">
      <parent link="thumb_mp"/>
      <child link="thumb_mp2dp_virt_jointbody"/>
      <origin xyz="-0.00586 0.06578 0.14053" rpy="0.0 0.0 0.0"/>
      <axis xyz="0.0 1.0 0.0"/>
      <limit lower="-0.093" upper="0.682" effort="100" velocity="100"/>
   </joint>
   <joint type="fixed" name="thumb_mp2dp_virt_offset">
      <parent link="thumb_mp2dp_virt_jointbody"/>
      <child link="thumb_dp_virt"/>
      <origin xyz="0.00586 -0.06578 -0.14053" rpy="0.0 0.0 0.0"/>
   </joint>
   <link name="thumb_dp">
      <inertial>
         <origin xyz="-0.004280178542039652 0.06282404268735813 0.15313159682784985" rpy="-0.0005379593086080135 -0.001433109929236842 -0.00011829808161197317"/>
         <mass value="0.0014065189510415494"/>
         <inertia ixx="7.157650835027881e-08" iyy="6.265685831321033e-08" izz="1.6891661726787585e-08" ixy="0" ixz="0" iyz="0"/>
      </inertial>
      <visual name="thumb_dp">
         <origin xyz="-0.004280178542039652 0.06282404268735813 0.15313159682784985" rpy="-0.0005379593086080135 -0.001433109929236842 -0.00011829808161197317"/>
         <geometry>
            <mesh filename="package://viz/models/titans_hand/urdf/converted_mesh/converted_thumb_dp.stl"/>
         </geometry>
         <material name="white"/>
      </visual>
   </link>
   <link name="thumb_mp2dp_jointbody">
      <inertial>
         <origin xyz="0.0 0.0 0.0" rpy="0.0 0.0 0.0"/>
         <mass value="0.001"/>
         <inertia ixx="1e-09" iyy="1e-09" izz="1e-09" ixy="0" ixz="0" iyz="0"/>
      </inertial>
   </link>
   <joint type="revolute" name="thumb_mp2dp">
      <parent link="thumb_dp_virt"/>
      <child link="thumb_mp2dp_jointbody"/>
      <origin xyz="-0.00464 0.0664 0.14872" rpy="0.0 0.0 0.0"/>
      <axis xyz="0.0 1.0 0.0"/>
      <limit lower="-0.093" upper="0.682" effort="100" velocity="100"/>
   </joint>
   <joint type="fixed" name="thumb_mp2dp_offset">
      <parent link="thumb_mp2dp_jointbody"/>
      <child link="thumb_dp"/>
      <origin xyz="0.00464 -0.0664 -0.14872" rpy="0.0 0.0 0.0"/>
   </joint>
   <link name="thumb_fingertip">
      <inertial>
         <origin xyz="0.0 0.0 0.0" rpy="0.0 0.0 0.0"/>
         <mass value="0.0"/>
         <inertia ixx="0.0" iyy="0.0" izz="0.0" ixy="0" ixz="0" iyz="0"/>
      </inertial>
   </link>
   <link name="thumb_dp2thumb_fingertip_fixed_jointbody">
      <inertial>
         <origin xyz="0.0 0.0 0.0" rpy="0.0 0.0 0.0"/>
         <mass value="0.001"/>
         <inertia ixx="1e-09" iyy="1e-09" izz="1e-09" ixy="0" ixz="0" iyz="0"/>
      </inertial>
   </link>
   <joint type="fixed" name="thumb_dp2thumb_fingertip_fixed">
      <parent link="thumb_dp"/>
      <child link="thumb_dp2thumb_fingertip_fixed_jointbody"/>
      <origin xyz="0.0 0.0 0.0" rpy="0.0 0.0 0.0"/>
   </joint>
   <joint type="fixed" name="thumb_dp2thumb_fingertip_fixed_offset">
      <parent link="thumb_dp2thumb_fingertip_fixed_jointbody"/>
      <child link="thumb_fingertip"/>
      <origin xyz="-0.0 -0.0 -0.0" rpy="0.0 0.0 0.0"/>
   </joint>
   <link name="index_base">
      <inertial>
         <origin xyz="-1.3760015381432599e-06 0.0001725668069039066 0.004475784071478828" rpy="-0.001820563394911212 0.2840263082023218 1.5629472627759466"/>
         <mass value="0.00362069274308756"/>
         <inertia ixx="1.660759019712417e-07" iyy="1.58396401779484e-07" izz="8.57537012752121e-08" ixy="0" ixz="0" iyz="0"/>
      </inertial>
      <visual name="index_base">
         <origin xyz="-1.3760015381432599e-06 0.0001725668069039066 0.004475784071478828" rpy="-0.001820563394911212 0.2840263082023218 1.5629472627759466"/>
         <geometry>
            <mesh filename="package://viz/models/titans_hand/urdf/converted_mesh/converted_index_base.stl"/>
         </geometry>
         <material name="white"/>
      </visual>
   </link>
   <link name="palm2index_base_fixed_jointbody">
      <inertial>
         <origin xyz="0.0 0.0 0.0" rpy="0.0 0.0 0.0"/>
         <mass value="0.001"/>
         <inertia ixx="1e-09" iyy="1e-09" izz="1e-09" ixy="0" ixz="0" iyz="0"/>
      </inertial>
   </link>
   <joint type="fixed" name="palm2index_base_fixed">
      <parent link="palm"/>
      <child link="palm2index_base_fixed_jointbody"/>
      <origin xyz="0.002 0.04096 0.118" rpy="0.0 0.0 1.57"/>
   </joint>
   <joint type="fixed" name="palm2index_base_fixed_offset">
      <parent link="palm2index_base_fixed_jointbody"/>
      <child link="index_base"/>
      <origin xyz="-0.0 -0.0 -0.0" rpy="0.0 0.0 0.0"/>
   </joint>
   <link name="index_um_virt">
      <inertial>
         <origin xyz="0.0 0.0 0.02317496" rpy="0.0 0.0 0.0"/>
         <mass value="0.001"/>
         <inertia ixx="4e-10" iyy="4e-10" izz="3e-10" ixy="0" ixz="0" iyz="0"/>
      </inertial>
   </link>
   <link name="index_abd_virt_jointbody">
      <inertial>
         <origin xyz="0.0 0.0 0.0" rpy="0.0 0.0 0.0"/>
         <mass value="0.001"/>
         <inertia ixx="1e-09" iyy="1e-09" izz="1e-09" ixy="0" ixz="0" iyz="0"/>
      </inertial>
   </link>
   <joint type="revolute" name="index_abd_virt">
      <parent link="index_base"/>
      <child link="index_abd_virt_jointbody"/>
      <origin xyz="0.0 0.0 0.00527505" rpy="0.0 0.0 0.0"/>
      <axis xyz="0.0 1.0 0.0"/>
      <limit lower="-0.264" upper="0.264" effort="100" velocity="100"/>
   </joint>
   <joint type="fixed" name="index_abd_virt_offset">
      <parent link="index_abd_virt_jointbody"/>
      <child link="index_um_virt"/>
      <origin xyz="-0.0 -0.0 -0.00527505" rpy="0.0 0.0 0.0"/>
   </joint>
   <link name="index_um">
      <inertial>
         <origin xyz="1.7370519164770844e-05 0.0012715146657108968 0.02004891848100365" rpy="3.120877986607322 -1.1804296781579997 -1.5514785003273175"/>
         <mass value="0.0020507778801623494"/>
         <inertia ixx="5.3021061398745245e-08" iyy="4.456771195857276e-08" izz="4.1862251466191607e-08" ixy="0" ixz="0" iyz="0"/>
      </inertial>
      <visual name="index_um">
         <origin xyz="1.7370519164770844e-05 0.0012715146657108968 0.02004891848100365" rpy="3.120877986607322 -1.1804296781579997 -1.5514785003273168"/>
         <geometry>
            <mesh filename="package://viz/models/titans_hand/urdf/converted_mesh/converted_index_um.stl"/>
         </geometry>
         <material name="white"/>
      </visual>
   </link>
   <link name="index_abd_jointbody">
      <inertial>
         <origin xyz="0.0 0.0 0.0" rpy="0.0 0.0 0.0"/>
         <mass value="0.001"/>
         <inertia ixx="1e-09" iyy="1e-09" izz="1e-09" ixy="0" ixz="0" iyz="0"/>
      </inertial>
   </link>
   <joint type="revolute" name="index_abd">
      <parent link="index_um_virt"/>
      <child link="index_abd_jointbody"/>
      <origin xyz="0.0 0.0 0.02317496" rpy="0.0 0.0 0.0"/>
      <axis xyz="0.0 1.0 0.0"/>
      <limit lower="-0.264" upper="0.264" effort="100" velocity="100"/>
   </joint>
   <joint type="fixed" name="index_abd_offset">
      <parent link="index_abd_jointbody"/>
      <child link="index_um"/>
      <origin xyz="-0.0 -0.0 -0.02317496" rpy="0.0 0.0 0.0"/>
   </joint>
   <link name="index_pp_virt">
      <inertial>
         <origin xyz="0.0 0.00314317 0.03414407" rpy="0.0 0.0 0.0"/>
         <mass value="0.001"/>
         <inertia ixx="4e-10" iyy="4e-10" izz="3e-10" ixy="0" ixz="0" iyz="0"/>
      </inertial>
   </link>
   <link name="root2index_pp_virt_jointbody">
      <inertial>
         <origin xyz="0.0 0.0 0.0" rpy="0.0 0.0 0.0"/>
         <mass value="0.001"/>
         <inertia ixx="1e-09" iyy="1e-09" izz="1e-09" ixy="0" ixz="0" iyz="0"/>
      </inertial>
   </link>
   <joint type="revolute" name="root2index_pp_virt">
      <parent link="index_um"/>
      <child link="root2index_pp_virt_jointbody"/>
      <origin xyz="0.0 0.0033 0.01691888" rpy="0.0 0.0 0.0"/>
      <axis xyz="1.0 0.0 0.0"/>
      <limit lower="-0.157" upper="0.829" effort="100" velocity="100"/>
   </joint>
   <joint type="fixed" name="root2index_pp_virt_offset">
      <parent link="root2index_pp_virt_jointbody"/>
      <child link="index_pp_virt"/>
      <origin xyz="-0.0 -0.0033 -0.01691888" rpy="0.0 0.0 0.0"/>
   </joint>
   <link name="index_pp">
      <inertial>
         <origin xyz="0.00011637335936397564 0.001638621934740265 0.04496627954912128" rpy="0.0018869935921097536 0.038976549934939486 1.5584299043450622"/>
         <mass value="0.007546046440107924"/>
         <inertia ixx="9.56353434554292e-07" iyy="9.274116917842254e-07" izz="1.7176054342320975e-07" ixy="0" ixz="0" iyz="0"/>
      </inertial>
      <visual name="index_pp">
         <origin xyz="0.00011637335936397564 0.001638621934740265 0.04496627954912128" rpy="0.0018869935921097536 0.038976549934939486 1.5584299043450622"/>
         <geometry>
            <mesh filename="package://viz/models/titans_hand/urdf/converted_mesh/converted_index_pp.stl"/>
         </geometry>
         <material name="white"/>
      </visual>
   </link>
   <link name="root2index_pp_jointbody">
      <inertial>
         <origin xyz="0.0 0.0 0.0" rpy="0.0 0.0 0.0"/>
         <mass value="0.001"/>
         <inertia ixx="1e-09" iyy="1e-09" izz="1e-09" ixy="0" ixz="0" iyz="0"/>
      </inertial>
   </link>
   <joint type="revolute" name="root2index_pp">
      <parent link="index_pp_virt"/>
      <child link="root2index_pp_jointbody"/>
      <origin xyz="0.0 0.00314317 0.03414407" rpy="0.0 0.0 0.0"/>
      <axis xyz="1.0 0.0 0.0"/>
      <limit lower="-0.157" upper="0.829" effort="100" velocity="100"/>
   </joint>
   <joint type="fixed" name="root2index_pp_offset">
      <parent link="root2index_pp_jointbody"/>
      <child link="index_pp"/>
      <origin xyz="-0.0 -0.00314317 -0.03414407" rpy="0.0 0.0 0.0"/>
   </joint>
   <link name="index_pp_sens">
      <inertial>
         <origin xyz="0.0 0.0 0.0" rpy="0.0 0.0 0.0"/>
         <mass value="0.0"/>
         <inertia ixx="0.0" iyy="0.0" izz="0.0" ixy="0" ixz="0" iyz="0"/>
      </inertial>
   </link>
   <link name="index_pp2index_pp_sens_fixed_jointbody">
      <inertial>
         <origin xyz="0.0 0.0 0.0" rpy="0.0 0.0 0.0"/>
         <mass value="0.001"/>
         <inertia ixx="1e-09" iyy="1e-09" izz="1e-09" ixy="0" ixz="0" iyz="0"/>
      </inertial>
   </link>
   <joint type="fixed" name="index_pp2index_pp_sens_fixed">
      <parent link="index_pp"/>
      <child link="index_pp2index_pp_sens_fixed_jointbody"/>
      <origin xyz="0.0 0.0 0.0" rpy="0.0 0.0 0.0"/>
   </joint>
   <joint type="fixed" name="index_pp2index_pp_sens_fixed_offset">
      <parent link="index_pp2index_pp_sens_fixed_jointbody"/>
      <child link="index_pp_sens"/>
      <origin xyz="-0.0 -0.0 -0.0" rpy="0.0 0.0 0.0"/>
   </joint>
   <link name="index_mp_virt">
      <inertial>
         <origin xyz="0.0 0.0029099 0.07130514" rpy="0.0 0.0 0.0"/>
         <mass value="0.001"/>
         <inertia ixx="4e-10" iyy="4e-10" izz="3e-10" ixy="0" ixz="0" iyz="0"/>
      </inertial>
   </link>
   <link name="index_pp2mp_virt_jointbody">
      <inertial>
         <origin xyz="0.0 0.0 0.0" rpy="0.0 0.0 0.0"/>
         <mass value="0.001"/>
         <inertia ixx="1e-09" iyy="1e-09" izz="1e-09" ixy="0" ixz="0" iyz="0"/>
      </inertial>
   </link>
   <joint type="revolute" name="index_pp2mp_virt">
      <parent link="index_pp"/>
      <child link="index_pp2mp_virt_jointbody"/>
      <origin xyz="0.0 0.00371958 0.06026209" rpy="0.0 0.0 0.0"/>
      <axis xyz="1.0 0.0 0.0"/>
      <limit lower="-0.131" upper="0.96" effort="100" velocity="100"/>
   </joint>
   <joint type="fixed" name="index_pp2mp_virt_offset">
      <parent link="index_pp2mp_virt_jointbody"/>
      <child link="index_mp_virt"/>
      <origin xyz="-0.0 -0.00371958 -0.06026209" rpy="0.0 0.0 0.0"/>
   </joint>
   <link name="index_mp">
      <inertial>
         <origin xyz="0.00029668965848413434 0.0017783639299142466 0.07889527150394414" rpy="0.0056787978904592196 0.009123149673579745 1.5738823026622906"/>
         <mass value="0.0036096163027472743"/>
         <inertia ixx="2.3670857595223327e-07" iyy="2.0588776340491657e-07" izz="6.81524873648359e-08" ixy="0" ixz="0" iyz="0"/>
      </inertial>
      <visual name="index_mp">
         <origin xyz="0.00029668965848413434 0.0017783639299142466 0.07889527150394414" rpy="0.0056787978904592196 0.009123149673579745 1.573882302662291"/>
         <geometry>
            <mesh filename="package://viz/models/titans_hand/urdf/converted_mesh/converted_index_mp.stl"/>
         </geometry>
         <material name="white"/>
      </visual>
   </link>
   <link name="index_pp2mp_jointbody">
      <inertial>
         <origin xyz="0.0 0.0 0.0" rpy="0.0 0.0 0.0"/>
         <mass value="0.001"/>
         <inertia ixx="1e-09" iyy="1e-09" izz="1e-09" ixy="0" ixz="0" iyz="0"/>
      </inertial>
   </link>
   <joint type="revolute" name="index_pp2mp">
      <parent link="index_mp_virt"/>
      <child link="index_pp2mp_jointbody"/>
      <origin xyz="0.0 0.0029099 0.07130514" rpy="0.0 0.0 0.0"/>
      <axis xyz="1.0 0.0 0.0"/>
      <limit lower="-0.131" upper="0.96" effort="100" velocity="100"/>
   </joint>
   <joint type="fixed" name="index_pp2mp_offset">
      <parent link="index_pp2mp_jointbody"/>
      <child link="index_mp"/>
      <origin xyz="-0.0 -0.0029099 -0.07130514" rpy="0.0 0.0 0.0"/>
   </joint>
   <link name="index_dp_virt">
      <inertial>
         <origin xyz="0.0 0.0017961 0.09655649" rpy="0.0 0.0 0.0"/>
         <mass value="0.001"/>
         <inertia ixx="4e-10" iyy="4e-10" izz="3e-10" ixy="0" ixz="0" iyz="0"/>
      </inertial>
   </link>
   <link name="index_mp2dp_virt_jointbody">
      <inertial>
         <origin xyz="0.0 0.0 0.0" rpy="0.0 0.0 0.0"/>
         <mass value="0.001"/>
         <inertia ixx="1e-09" iyy="1e-09" izz="1e-09" ixy="0" ixz="0" iyz="0"/>
      </inertial>
   </link>
   <joint type="revolute" name="index_mp2dp_virt">
      <parent link="index_mp"/>
      <child link="index_mp2dp_virt_jointbody"/>
      <origin xyz="0.0 0.00263391 0.0882811" rpy="0.0 0.0 0.0"/>
      <axis xyz="1.0 0.0 0.0"/>
      <limit lower="-0.093" upper="0.682" effort="100" velocity="100"/>
   </joint>
   <joint type="fixed" name="index_mp2dp_virt_offset">
      <parent link="index_mp2dp_virt_jointbody"/>
      <child link="index_dp_virt"/>
      <origin xyz="-0.0 -0.00263391 -0.0882811" rpy="0.0 0.0 0.0"/>
   </joint>
   <link name="index_dp">
      <inertial>
         <origin xyz="0.0004080281600351707 0.001635180393279046 0.10092332329872378" rpy="0.005320230753060984 0.04639366291748903 1.5713315351794575"/>
         <mass value="0.0014065189005047724"/>
         <inertia ixx="7.15765063531471e-08" iyy="6.265685623199896e-08" izz="1.6891661140100088e-08" ixy="0" ixz="0" iyz="0"/>
      </inertial>
      <visual name="index_dp">
         <origin xyz="0.0004080281600351707 0.001635180393279046 0.10092332329872378" rpy="0.005320230753060984 0.04639366291748925 1.571331535179458"/>
         <geometry>
            <mesh filename="package://viz/models/titans_hand/urdf/converted_mesh/converted_index_dp.stl"/>
         </geometry>
         <material name="white"/>
      </visual>
   </link>
   <link name="index_mp2dp_jointbody">
      <inertial>
         <origin xyz="0.0 0.0 0.0" rpy="0.0 0.0 0.0"/>
         <mass value="0.001"/>
         <inertia ixx="1e-09" iyy="1e-09" izz="1e-09" ixy="0" ixz="0" iyz="0"/>
      </inertial>
   </link>
   <joint type="revolute" name="index_mp2dp">
      <parent link="index_dp_virt"/>
      <child link="index_mp2dp_jointbody"/>
      <origin xyz="0.0 0.0017961 0.09655649" rpy="0.0 0.0 0.0"/>
      <axis xyz="1.0 0.0 0.0"/>
      <limit lower="-0.093" upper="0.682" effort="100" velocity="100"/>
   </joint>
   <joint type="fixed" name="index_mp2dp_offset">
      <parent link="index_mp2dp_jointbody"/>
      <child link="index_dp"/>
      <origin xyz="-0.0 -0.0017961 -0.09655649" rpy="0.0 0.0 0.0"/>
   </joint>
   <link name="index_fingertip">
      <inertial>
         <origin xyz="0.0 0.0 0.0" rpy="0.0 0.0 0.0"/>
         <mass value="0.0"/>
         <inertia ixx="0.0" iyy="0.0" izz="0.0" ixy="0" ixz="0" iyz="0"/>
      </inertial>
   </link>
   <link name="index_dp2index_fingertip_fixed_jointbody">
      <inertial>
         <origin xyz="0.0 0.0 0.0" rpy="0.0 0.0 0.0"/>
         <mass value="0.001"/>
         <inertia ixx="1e-09" iyy="1e-09" izz="1e-09" ixy="0" ixz="0" iyz="0"/>
      </inertial>
   </link>
   <joint type="fixed" name="index_dp2index_fingertip_fixed">
      <parent link="index_dp"/>
      <child link="index_dp2index_fingertip_fixed_jointbody"/>
      <origin xyz="0.0 0.0 0.0" rpy="0.0 0.0 0.0"/>
   </joint>
   <joint type="fixed" name="index_dp2index_fingertip_fixed_offset">
      <parent link="index_dp2index_fingertip_fixed_jointbody"/>
      <child link="index_fingertip"/>
      <origin xyz="-0.0 -0.0 -0.0" rpy="0.0 0.0 0.0"/>
   </joint>
   <link name="middle_base">
      <inertial>
         <origin xyz="-1.3760015381432599e-06 0.0001725668069039066 0.004475784071478828" rpy="-0.001820563394911212 0.2840263082023218 1.5629472627759466"/>
         <mass value="0.00362069274308756"/>
         <inertia ixx="1.660759019712417e-07" iyy="1.58396401779484e-07" izz="8.57537012752121e-08" ixy="0" ixz="0" iyz="0"/>
      </inertial>
      <visual name="middle_base">
         <origin xyz="-1.3760015381432599e-06 0.0001725668069039066 0.004475784071478828" rpy="-0.001820563394911212 0.2840263082023218 1.5629472627759466"/>
         <geometry>
            <mesh filename="package://viz/models/titans_hand/urdf/converted_mesh/converted_middle_base.stl"/>
         </geometry>
         <material name="white"/>
      </visual>
   </link>
   <link name="palm2middle_base_fixed_jointbody">
      <inertial>
         <origin xyz="0.0 0.0 0.0" rpy="0.0 0.0 0.0"/>
         <mass value="0.001"/>
         <inertia ixx="1e-09" iyy="1e-09" izz="1e-09" ixy="0" ixz="0" iyz="0"/>
      </inertial>
   </link>
   <joint type="fixed" name="palm2middle_base_fixed">
      <parent link="palm"/>
      <child link="palm2middle_base_fixed_jointbody"/>
      <origin xyz="0.002 0.02163081458 0.115168462" rpy="0.00014041394505603932 -0.17453294409230335 1.5699877153702502"/>
   </joint>
   <joint type="fixed" name="palm2middle_base_fixed_offset">
      <parent link="palm2middle_base_fixed_jointbody"/>
      <child link="middle_base"/>
      <origin xyz="-0.0 -0.0 -0.0" rpy="0.0 0.0 0.0"/>
   </joint>
   <link name="middle_um_virt">
      <inertial>
         <origin xyz="0.0 0.0 0.02317496" rpy="0.0 0.0 0.0"/>
         <mass value="0.001"/>
         <inertia ixx="4e-10" iyy="4e-10" izz="3e-10" ixy="0" ixz="0" iyz="0"/>
      </inertial>
   </link>
   <link name="middle_abd_virt_jointbody">
      <inertial>
         <origin xyz="0.0 0.0 0.0" rpy="0.0 0.0 0.0"/>
         <mass value="0.001"/>
         <inertia ixx="1e-09" iyy="1e-09" izz="1e-09" ixy="0" ixz="0" iyz="0"/>
      </inertial>
   </link>
   <joint type="revolute" name="middle_abd_virt">
      <parent link="middle_base"/>
      <child link="middle_abd_virt_jointbody"/>
      <origin xyz="0.0 0.0 0.00527505" rpy="0.0 0.0 0.0"/>
      <axis xyz="0.0 1.0 0.0"/>
      <limit lower="-0.264" upper="0.264" effort="100" velocity="100"/>
   </joint>
   <joint type="fixed" name="middle_abd_virt_offset">
      <parent link="middle_abd_virt_jointbody"/>
      <child link="middle_um_virt"/>
      <origin xyz="-0.0 -0.0 -0.00527505" rpy="0.0 0.0 0.0"/>
   </joint>
   <link name="middle_um">
      <inertial>
         <origin xyz="1.7370519164770844e-05 0.0012715146657108968 0.02004891848100365" rpy="3.120877986607322 -1.1804296781579997 -1.5514785003273175"/>
         <mass value="0.0020507778801623494"/>
         <inertia ixx="5.3021061398745245e-08" iyy="4.456771195857276e-08" izz="4.1862251466191607e-08" ixy="0" ixz="0" iyz="0"/>
      </inertial>
      <visual name="middle_um">
         <origin xyz="1.7370519164770844e-05 0.0012715146657108968 0.02004891848100365" rpy="3.120877986607322 -1.1804296781579997 -1.5514785003273168"/>
         <geometry>
            <mesh filename="package://viz/models/titans_hand/urdf/converted_mesh/converted_middle_um.stl"/>
         </geometry>
         <material name="white"/>
      </visual>
   </link>
   <link name="middle_abd_jointbody">
      <inertial>
         <origin xyz="0.0 0.0 0.0" rpy="0.0 0.0 0.0"/>
         <mass value="0.001"/>
         <inertia ixx="1e-09" iyy="1e-09" izz="1e-09" ixy="0" ixz="0" iyz="0"/>
      </inertial>
   </link>
   <joint type="revolute" name="middle_abd">
      <parent link="middle_um_virt"/>
      <child link="middle_abd_jointbody"/>
      <origin xyz="0.0 0.0 0.02317496" rpy="0.0 0.0 0.0"/>
      <axis xyz="0.0 1.0 0.0"/>
      <limit lower="-0.264" upper="0.264" effort="100" velocity="100"/>
   </joint>
   <joint type="fixed" name="middle_abd_offset">
      <parent link="middle_abd_jointbody"/>
      <child link="middle_um"/>
      <origin xyz="-0.0 -0.0 -0.02317496" rpy="0.0 0.0 0.0"/>
   </joint>
   <link name="middle_pp_virt">
      <inertial>
         <origin xyz="0.0 0.00314317 0.03414407" rpy="0.0 0.0 0.0"/>
         <mass value="0.001"/>
         <inertia ixx="4e-10" iyy="4e-10" izz="3e-10" ixy="0" ixz="0" iyz="0"/>
      </inertial>
   </link>
   <link name="root2middle_pp_virt_jointbody">
      <inertial>
         <origin xyz="0.0 0.0 0.0" rpy="0.0 0.0 0.0"/>
         <mass value="0.001"/>
         <inertia ixx="1e-09" iyy="1e-09" izz="1e-09" ixy="0" ixz="0" iyz="0"/>
      </inertial>
   </link>
   <joint type="revolute" name="root2middle_pp_virt">
      <parent link="middle_um"/>
      <child link="root2middle_pp_virt_jointbody"/>
      <origin xyz="0.0 0.0033 0.01691888" rpy="0.0 0.0 0.0"/>
      <axis xyz="1.0 0.0 0.0"/>
      <limit lower="-0.157" upper="0.829" effort="100" velocity="100"/>
   </joint>
   <joint type="fixed" name="root2middle_pp_virt_offset">
      <parent link="root2middle_pp_virt_jointbody"/>
      <child link="middle_pp_virt"/>
      <origin xyz="-0.0 -0.0033 -0.01691888" rpy="0.0 0.0 0.0"/>
   </joint>
   <link name="middle_pp">
      <inertial>
         <origin xyz="0.00011637335936397564 0.001638621934740265 0.04496627954912128" rpy="0.0018869935921097536 0.038976549934939486 1.5584299043450622"/>
         <mass value="0.007546046440107924"/>
         <inertia ixx="9.56353434554292e-07" iyy="9.274116917842254e-07" izz="1.7176054342320975e-07" ixy="0" ixz="0" iyz="0"/>
      </inertial>
      <visual name="middle_pp">
         <origin xyz="0.00011637335936397564 0.001638621934740265 0.04496627954912128" rpy="0.0018869935921097536 0.038976549934939486 1.5584299043450622"/>
         <geometry>
            <mesh filename="package://viz/models/titans_hand/urdf/converted_mesh/converted_middle_pp.stl"/>
         </geometry>
         <material name="white"/>
      </visual>
   </link>
   <link name="root2middle_pp_jointbody">
      <inertial>
         <origin xyz="0.0 0.0 0.0" rpy="0.0 0.0 0.0"/>
         <mass value="0.001"/>
         <inertia ixx="1e-09" iyy="1e-09" izz="1e-09" ixy="0" ixz="0" iyz="0"/>
      </inertial>
   </link>
   <joint type="revolute" name="root2middle_pp">
      <parent link="middle_pp_virt"/>
      <child link="root2middle_pp_jointbody"/>
      <origin xyz="0.0 0.00314317 0.03414407" rpy="0.0 0.0 0.0"/>
      <axis xyz="1.0 0.0 0.0"/>
      <limit lower="-0.157" upper="0.829" effort="100" velocity="100"/>
   </joint>
   <joint type="fixed" name="root2middle_pp_offset">
      <parent link="root2middle_pp_jointbody"/>
      <child link="middle_pp"/>
      <origin xyz="-0.0 -0.00314317 -0.03414407" rpy="0.0 0.0 0.0"/>
   </joint>
   <link name="middle_pp_sens">
      <inertial>
         <origin xyz="0.0 0.0 0.0" rpy="0.0 0.0 0.0"/>
         <mass value="0.0"/>
         <inertia ixx="0.0" iyy="0.0" izz="0.0" ixy="0" ixz="0" iyz="0"/>
      </inertial>
   </link>
   <link name="middle_pp2middle_pp_sens_fixed_jointbody">
      <inertial>
         <origin xyz="0.0 0.0 0.0" rpy="0.0 0.0 0.0"/>
         <mass value="0.001"/>
         <inertia ixx="1e-09" iyy="1e-09" izz="1e-09" ixy="0" ixz="0" iyz="0"/>
      </inertial>
   </link>
   <joint type="fixed" name="middle_pp2middle_pp_sens_fixed">
      <parent link="middle_pp"/>
      <child link="middle_pp2middle_pp_sens_fixed_jointbody"/>
      <origin xyz="0.0 0.0 0.0" rpy="0.0 0.0 0.0"/>
   </joint>
   <joint type="fixed" name="middle_pp2middle_pp_sens_fixed_offset">
      <parent link="middle_pp2middle_pp_sens_fixed_jointbody"/>
      <child link="middle_pp_sens"/>
      <origin xyz="-0.0 -0.0 -0.0" rpy="0.0 0.0 0.0"/>
   </joint>
   <link name="middle_mp_virt">
      <inertial>
         <origin xyz="0.0 0.0029099 0.07130514" rpy="0.0 0.0 0.0"/>
         <mass value="0.001"/>
         <inertia ixx="4e-10" iyy="4e-10" izz="3e-10" ixy="0" ixz="0" iyz="0"/>
      </inertial>
   </link>
   <link name="middle_pp2mp_virt_jointbody">
      <inertial>
         <origin xyz="0.0 0.0 0.0" rpy="0.0 0.0 0.0"/>
         <mass value="0.001"/>
         <inertia ixx="1e-09" iyy="1e-09" izz="1e-09" ixy="0" ixz="0" iyz="0"/>
      </inertial>
   </link>
   <joint type="revolute" name="middle_pp2mp_virt">
      <parent link="middle_pp"/>
      <child link="middle_pp2mp_virt_jointbody"/>
      <origin xyz="0.0 0.00371958 0.06026209" rpy="0.0 0.0 0.0"/>
      <axis xyz="1.0 0.0 0.0"/>
      <limit lower="-0.131" upper="0.96" effort="100" velocity="100"/>
   </joint>
   <joint type="fixed" name="middle_pp2mp_virt_offset">
      <parent link="middle_pp2mp_virt_jointbody"/>
      <child link="middle_mp_virt"/>
      <origin xyz="-0.0 -0.00371958 -0.06026209" rpy="0.0 0.0 0.0"/>
   </joint>
   <link name="middle_mp">
      <inertial>
         <origin xyz="0.00029668965848413434 0.0017783639299142466 0.07889527150394414" rpy="0.0056787978904592196 0.009123149673579745 1.5738823026622906"/>
         <mass value="0.0036096163027472743"/>
         <inertia ixx="2.3670857595223327e-07" iyy="2.0588776340491657e-07" izz="6.81524873648359e-08" ixy="0" ixz="0" iyz="0"/>
      </inertial>
      <visual name="middle_mp">
         <origin xyz="0.00029668965848413434 0.0017783639299142466 0.07889527150394414" rpy="0.0056787978904592196 0.009123149673579745 1.573882302662291"/>
         <geometry>
            <mesh filename="package://viz/models/titans_hand/urdf/converted_mesh/converted_middle_mp.stl"/>
         </geometry>
         <material name="white"/>
      </visual>
   </link>
   <link name="middle_pp2mp_jointbody">
      <inertial>
         <origin xyz="0.0 0.0 0.0" rpy="0.0 0.0 0.0"/>
         <mass value="0.001"/>
         <inertia ixx="1e-09" iyy="1e-09" izz="1e-09" ixy="0" ixz="0" iyz="0"/>
      </inertial>
   </link>
   <joint type="revolute" name="middle_pp2mp">
      <parent link="middle_mp_virt"/>
      <child link="middle_pp2mp_jointbody"/>
      <origin xyz="0.0 0.0029099 0.07130514" rpy="0.0 0.0 0.0"/>
      <axis xyz="1.0 0.0 0.0"/>
      <limit lower="-0.131" upper="0.96" effort="100" velocity="100"/>
   </joint>
   <joint type="fixed" name="middle_pp2mp_offset">
      <parent link="middle_pp2mp_jointbody"/>
      <child link="middle_mp"/>
      <origin xyz="-0.0 -0.0029099 -0.07130514" rpy="0.0 0.0 0.0"/>
   </joint>
   <link name="middle_dp_virt">
      <inertial>
         <origin xyz="0.0 0.0017961 0.09655649" rpy="0.0 0.0 0.0"/>
         <mass value="0.001"/>
         <inertia ixx="4e-10" iyy="4e-10" izz="3e-10" ixy="0" ixz="0" iyz="0"/>
      </inertial>
   </link>
   <link name="middle_mp2dp_virt_jointbody">
      <inertial>
         <origin xyz="0.0 0.0 0.0" rpy="0.0 0.0 0.0"/>
         <mass value="0.001"/>
         <inertia ixx="1e-09" iyy="1e-09" izz="1e-09" ixy="0" ixz="0" iyz="0"/>
      </inertial>
   </link>
   <joint type="revolute" name="middle_mp2dp_virt">
      <parent link="middle_mp"/>
      <child link="middle_mp2dp_virt_jointbody"/>
      <origin xyz="0.0 0.00263391 0.0882811" rpy="0.0 0.0 0.0"/>
      <axis xyz="1.0 0.0 0.0"/>
      <limit lower="-0.093" upper="0.682" effort="100" velocity="100"/>
   </joint>
   <joint type="fixed" name="middle_mp2dp_virt_offset">
      <parent link="middle_mp2dp_virt_jointbody"/>
      <child link="middle_dp_virt"/>
      <origin xyz="-0.0 -0.00263391 -0.0882811" rpy="0.0 0.0 0.0"/>
   </joint>
   <link name="middle_dp">
      <inertial>
         <origin xyz="0.0004080281600351707 0.001635180393279046 0.10092332329872378" rpy="0.005320230753060984 0.04639366291748903 1.5713315351794575"/>
         <mass value="0.0014065189005047724"/>
         <inertia ixx="7.15765063531471e-08" iyy="6.265685623199896e-08" izz="1.6891661140100088e-08" ixy="0" ixz="0" iyz="0"/>
      </inertial>
      <visual name="middle_dp">
         <origin xyz="0.0004080281600351707 0.001635180393279046 0.10092332329872378" rpy="0.005320230753060984 0.04639366291748925 1.571331535179458"/>
         <geometry>
            <mesh filename="package://viz/models/titans_hand/urdf/converted_mesh/converted_middle_dp.stl"/>
         </geometry>
         <material name="white"/>
      </visual>
   </link>
   <link name="middle_mp2dp_jointbody">
      <inertial>
         <origin xyz="0.0 0.0 0.0" rpy="0.0 0.0 0.0"/>
         <mass value="0.001"/>
         <inertia ixx="1e-09" iyy="1e-09" izz="1e-09" ixy="0" ixz="0" iyz="0"/>
      </inertial>
   </link>
   <joint type="revolute" name="middle_mp2dp">
      <parent link="middle_dp_virt"/>
      <child link="middle_mp2dp_jointbody"/>
      <origin xyz="0.0 0.0017961 0.09655649" rpy="0.0 0.0 0.0"/>
      <axis xyz="1.0 0.0 0.0"/>
      <limit lower="-0.093" upper="0.682" effort="100" velocity="100"/>
   </joint>
   <joint type="fixed" name="middle_mp2dp_offset">
      <parent link="middle_mp2dp_jointbody"/>
      <child link="middle_dp"/>
      <origin xyz="-0.0 -0.0017961 -0.09655649" rpy="0.0 0.0 0.0"/>
   </joint>
   <link name="middle_fingertip">
      <inertial>
         <origin xyz="0.0 0.0 0.0" rpy="0.0 0.0 0.0"/>
         <mass value="0.0"/>
         <inertia ixx="0.0" iyy="0.0" izz="0.0" ixy="0" ixz="0" iyz="0"/>
      </inertial>
   </link>
   <link name="middle_dp2middle_fingertip_fixed_jointbody">
      <inertial>
         <origin xyz="0.0 0.0 0.0" rpy="0.0 0.0 0.0"/>
         <mass value="0.001"/>
         <inertia ixx="1e-09" iyy="1e-09" izz="1e-09" ixy="0" ixz="0" iyz="0"/>
      </inertial>
   </link>
   <joint type="fixed" name="middle_dp2middle_fingertip_fixed">
      <parent link="middle_dp"/>
      <child link="middle_dp2middle_fingertip_fixed_jointbody"/>
      <origin xyz="0.0 0.0 0.0" rpy="0.0 0.0 0.0"/>
   </joint>
   <joint type="fixed" name="middle_dp2middle_fingertip_fixed_offset">
      <parent link="middle_dp2middle_fingertip_fixed_jointbody"/>
      <child link="middle_fingertip"/>
      <origin xyz="-0.0 -0.0 -0.0" rpy="0.0 0.0 0.0"/>
   </joint>
   <link name="ring_base">
      <inertial>
         <origin xyz="-1.3760015381432599e-06 0.0001725668069039066 0.004475784071478828" rpy="-0.001820563394911212 0.2840263082023218 1.5629472627759466"/>
         <mass value="0.00362069274308756"/>
         <inertia ixx="1.660759019712417e-07" iyy="1.58396401779484e-07" izz="8.57537012752121e-08" ixy="0" ixz="0" iyz="0"/>
      </inertial>
      <visual name="ring_base">
         <origin xyz="-1.3760015381432599e-06 0.0001725668069039066 0.004475784071478828" rpy="-0.001820563394911212 0.2840263082023218 1.5629472627759466"/>
         <geometry>
            <mesh filename="package://viz/models/titans_hand/urdf/converted_mesh/converted_ring_base.stl"/>
         </geometry>
         <material name="white"/>
      </visual>
   </link>
   <link name="palm2ring_base_fixed_jointbody">
      <inertial>
         <origin xyz="0.0 0.0 0.0" rpy="0.0 0.0 0.0"/>
         <mass value="0.001"/>
         <inertia ixx="1e-09" iyy="1e-09" izz="1e-09" ixy="0" ixz="0" iyz="0"/>
      </inertial>
   </link>
   <joint type="fixed" name="palm2ring_base_fixed">
      <parent link="palm"/>
      <child link="palm2ring_base_fixed_jointbody"/>
      <origin xyz="0.002 0.002691840889 0.1112506719" rpy="0.0002898392113429571 -0.34906573499662796 1.5699488935438706"/>
   </joint>
   <joint type="fixed" name="palm2ring_base_fixed_offset">
      <parent link="palm2ring_base_fixed_jointbody"/>
      <child link="ring_base"/>
      <origin xyz="-0.0 -0.0 -0.0" rpy="0.0 0.0 0.0"/>
   </joint>
   <link name="ring_um_virt">
      <inertial>
         <origin xyz="0.0 0.0 0.02317496" rpy="0.0 0.0 0.0"/>
         <mass value="0.001"/>
         <inertia ixx="4e-10" iyy="4e-10" izz="3e-10" ixy="0" ixz="0" iyz="0"/>
      </inertial>
   </link>
   <link name="ring_abd_virt_jointbody">
      <inertial>
         <origin xyz="0.0 0.0 0.0" rpy="0.0 0.0 0.0"/>
         <mass value="0.001"/>
         <inertia ixx="1e-09" iyy="1e-09" izz="1e-09" ixy="0" ixz="0" iyz="0"/>
      </inertial>
   </link>
   <joint type="revolute" name="ring_abd_virt">
      <parent link="ring_base"/>
      <child link="ring_abd_virt_jointbody"/>
      <origin xyz="0.0 0.0 0.00527505" rpy="0.0 0.0 0.0"/>
      <axis xyz="0.0 1.0 0.0"/>
      <limit lower="-0.264" upper="0.264" effort="100" velocity="100"/>
   </joint>
   <joint type="fixed" name="ring_abd_virt_offset">
      <parent link="ring_abd_virt_jointbody"/>
      <child link="ring_um_virt"/>
      <origin xyz="-0.0 -0.0 -0.00527505" rpy="0.0 0.0 0.0"/>
   </joint>
   <link name="ring_um">
      <inertial>
         <origin xyz="1.7370519164770844e-05 0.0012715146657108968 0.02004891848100365" rpy="3.120877986607322 -1.1804296781579997 -1.5514785003273175"/>
         <mass value="0.0020507778801623494"/>
         <inertia ixx="5.3021061398745245e-08" iyy="4.456771195857276e-08" izz="4.1862251466191607e-08" ixy="0" ixz="0" iyz="0"/>
      </inertial>
      <visual name="ring_um">
         <origin xyz="1.7370519164770844e-05 0.0012715146657108968 0.02004891848100365" rpy="3.120877986607322 -1.1804296781579997 -1.5514785003273168"/>
         <geometry>
            <mesh filename="package://viz/models/titans_hand/urdf/converted_mesh/converted_ring_um.stl"/>
         </geometry>
         <material name="white"/>
      </visual>
   </link>
   <link name="ring_abd_jointbody">
      <inertial>
         <origin xyz="0.0 0.0 0.0" rpy="0.0 0.0 0.0"/>
         <mass value="0.001"/>
         <inertia ixx="1e-09" iyy="1e-09" izz="1e-09" ixy="0" ixz="0" iyz="0"/>
      </inertial>
   </link>
   <joint type="revolute" name="ring_abd">
      <parent link="ring_um_virt"/>
      <child link="ring_abd_jointbody"/>
      <origin xyz="0.0 0.0 0.02317496" rpy="0.0 0.0 0.0"/>
      <axis xyz="0.0 1.0 0.0"/>
      <limit lower="-0.264" upper="0.264" effort="100" velocity="100"/>
   </joint>
   <joint type="fixed" name="ring_abd_offset">
      <parent link="ring_abd_jointbody"/>
      <child link="ring_um"/>
      <origin xyz="-0.0 -0.0 -0.02317496" rpy="0.0 0.0 0.0"/>
   </joint>
   <link name="ring_pp_virt">
      <inertial>
         <origin xyz="0.0 0.00314317 0.03414407" rpy="0.0 0.0 0.0"/>
         <mass value="0.001"/>
         <inertia ixx="4e-10" iyy="4e-10" izz="3e-10" ixy="0" ixz="0" iyz="0"/>
      </inertial>
   </link>
   <link name="root2ring_pp_virt_jointbody">
      <inertial>
         <origin xyz="0.0 0.0 0.0" rpy="0.0 0.0 0.0"/>
         <mass value="0.001"/>
         <inertia ixx="1e-09" iyy="1e-09" izz="1e-09" ixy="0" ixz="0" iyz="0"/>
      </inertial>
   </link>
   <joint type="revolute" name="root2ring_pp_virt">
      <parent link="ring_um"/>
      <child link="root2ring_pp_virt_jointbody"/>
      <origin xyz="0.0 0.0033 0.01691888" rpy="0.0 0.0 0.0"/>
      <axis xyz="1.0 0.0 0.0"/>
      <limit lower="-0.157" upper="0.829" effort="100" velocity="100"/>
   </joint>
   <joint type="fixed" name="root2ring_pp_virt_offset">
      <parent link="root2ring_pp_virt_jointbody"/>
      <child link="ring_pp_virt"/>
      <origin xyz="-0.0 -0.0033 -0.01691888" rpy="0.0 0.0 0.0"/>
   </joint>
   <link name="ring_pp">
      <inertial>
         <origin xyz="0.00011637335936397564 0.001638621934740265 0.04496627954912128" rpy="0.0018869935921097536 0.038976549934939486 1.5584299043450622"/>
         <mass value="0.007546046440107924"/>
         <inertia ixx="9.56353434554292e-07" iyy="9.274116917842254e-07" izz="1.7176054342320975e-07" ixy="0" ixz="0" iyz="0"/>
      </inertial>
      <visual name="ring_pp">
         <origin xyz="0.00011637335936397564 0.001638621934740265 0.04496627954912128" rpy="0.0018869935921097536 0.038976549934939486 1.5584299043450622"/>
         <geometry>
            <mesh filename="package://viz/models/titans_hand/urdf/converted_mesh/converted_ring_pp.stl"/>
         </geometry>
         <material name="white"/>
      </visual>
   </link>
   <link name="root2ring_pp_jointbody">
      <inertial>
         <origin xyz="0.0 0.0 0.0" rpy="0.0 0.0 0.0"/>
         <mass value="0.001"/>
         <inertia ixx="1e-09" iyy="1e-09" izz="1e-09" ixy="0" ixz="0" iyz="0"/>
      </inertial>
   </link>
   <joint type="revolute" name="root2ring_pp">
      <parent link="ring_pp_virt"/>
      <child link="root2ring_pp_jointbody"/>
      <origin xyz="0.0 0.00314317 0.03414407" rpy="0.0 0.0 0.0"/>
      <axis xyz="1.0 0.0 0.0"/>
      <limit lower="-0.157" upper="0.829" effort="100" velocity="100"/>
   </joint>
   <joint type="fixed" name="root2ring_pp_offset">
      <parent link="root2ring_pp_jointbody"/>
      <child link="ring_pp"/>
      <origin xyz="-0.0 -0.00314317 -0.03414407" rpy="0.0 0.0 0.0"/>
   </joint>
   <link name="ring_pp_sens">
      <inertial>
         <origin xyz="0.0 0.0 0.0" rpy="0.0 0.0 0.0"/>
         <mass value="0.0"/>
         <inertia ixx="0.0" iyy="0.0" izz="0.0" ixy="0" ixz="0" iyz="0"/>
      </inertial>
   </link>
   <link name="ring_pp2ring_pp_sens_fixed_jointbody">
      <inertial>
         <origin xyz="0.0 0.0 0.0" rpy="0.0 0.0 0.0"/>
         <mass value="0.001"/>
         <inertia ixx="1e-09" iyy="1e-09" izz="1e-09" ixy="0" ixz="0" iyz="0"/>
      </inertial>
   </link>
   <joint type="fixed" name="ring_pp2ring_pp_sens_fixed">
      <parent link="ring_pp"/>
      <child link="ring_pp2ring_pp_sens_fixed_jointbody"/>
      <origin xyz="0.0 0.0 0.0" rpy="0.0 0.0 0.0"/>
   </joint>
   <joint type="fixed" name="ring_pp2ring_pp_sens_fixed_offset">
      <parent link="ring_pp2ring_pp_sens_fixed_jointbody"/>
      <child link="ring_pp_sens"/>
      <origin xyz="-0.0 -0.0 -0.0" rpy="0.0 0.0 0.0"/>
   </joint>
   <link name="ring_mp_virt">
      <inertial>
         <origin xyz="0.0 0.0029099 0.07130514" rpy="0.0 0.0 0.0"/>
         <mass value="0.001"/>
         <inertia ixx="4e-10" iyy="4e-10" izz="3e-10" ixy="0" ixz="0" iyz="0"/>
      </inertial>
   </link>
   <link name="ring_pp2mp_virt_jointbody">
      <inertial>
         <origin xyz="0.0 0.0 0.0" rpy="0.0 0.0 0.0"/>
         <mass value="0.001"/>
         <inertia ixx="1e-09" iyy="1e-09" izz="1e-09" ixy="0" ixz="0" iyz="0"/>
      </inertial>
   </link>
   <joint type="revolute" name="ring_pp2mp_virt">
      <parent link="ring_pp"/>
      <child link="ring_pp2mp_virt_jointbody"/>
      <origin xyz="0.0 0.00371958 0.06026209" rpy="0.0 0.0 0.0"/>
      <axis xyz="1.0 0.0 0.0"/>
      <limit lower="-0.131" upper="0.96" effort="100" velocity="100"/>
   </joint>
   <joint type="fixed" name="ring_pp2mp_virt_offset">
      <parent link="ring_pp2mp_virt_jointbody"/>
      <child link="ring_mp_virt"/>
      <origin xyz="-0.0 -0.00371958 -0.06026209" rpy="0.0 0.0 0.0"/>
   </joint>
   <link name="ring_mp">
      <inertial>
         <origin xyz="0.00029668965848413434 0.0017783639299142466 0.07889527150394414" rpy="0.0056787978904592196 0.009123149673579745 1.5738823026622906"/>
         <mass value="0.0036096163027472743"/>
         <inertia ixx="2.3670857595223327e-07" iyy="2.0588776340491657e-07" izz="6.81524873648359e-08" ixy="0" ixz="0" iyz="0"/>
      </inertial>
      <visual name="ring_mp">
         <origin xyz="0.00029668965848413434 0.0017783639299142466 0.07889527150394414" rpy="0.0056787978904592196 0.009123149673579745 1.573882302662291"/>
         <geometry>
            <mesh filename="package://viz/models/titans_hand/urdf/converted_mesh/converted_ring_mp.stl"/>
         </geometry>
         <material name="white"/>
      </visual>
   </link>
   <link name="ring_pp2mp_jointbody">
      <inertial>
         <origin xyz="0.0 0.0 0.0" rpy="0.0 0.0 0.0"/>
         <mass value="0.001"/>
         <inertia ixx="1e-09" iyy="1e-09" izz="1e-09" ixy="0" ixz="0" iyz="0"/>
      </inertial>
   </link>
   <joint type="revolute" name="ring_pp2mp">
      <parent link="ring_mp_virt"/>
      <child link="ring_pp2mp_jointbody"/>
      <origin xyz="0.0 0.0029099 0.07130514" rpy="0.0 0.0 0.0"/>
      <axis xyz="1.0 0.0 0.0"/>
      <limit lower="-0.131" upper="0.96" effort="100" velocity="100"/>
   </joint>
   <joint type="fixed" name="ring_pp2mp_offset">
      <parent link="ring_pp2mp_jointbody"/>
      <child link="ring_mp"/>
      <origin xyz="-0.0 -0.0029099 -0.07130514" rpy="0.0 0.0 0.0"/>
   </joint>
   <link name="ring_dp_virt">
      <inertial>
         <origin xyz="0.0 0.0017961 0.09655649" rpy="0.0 0.0 0.0"/>
         <mass value="0.001"/>
         <inertia ixx="4e-10" iyy="4e-10" izz="3e-10" ixy="0" ixz="0" iyz="0"/>
      </inertial>
   </link>
   <link name="ring_mp2dp_virt_jointbody">
      <inertial>
         <origin xyz="0.0 0.0 0.0" rpy="0.0 0.0 0.0"/>
         <mass value="0.001"/>
         <inertia ixx="1e-09" iyy="1e-09" izz="1e-09" ixy="0" ixz="0" iyz="0"/>
      </inertial>
   </link>
   <joint type="revolute" name="ring_mp2dp_virt">
      <parent link="ring_mp"/>
      <child link="ring_mp2dp_virt_jointbody"/>
      <origin xyz="0.0 0.00263391 0.0882811" rpy="0.0 0.0 0.0"/>
      <axis xyz="1.0 0.0 0.0"/>
      <limit lower="-0.093" upper="0.682" effort="100" velocity="100"/>
   </joint>
   <joint type="fixed" name="ring_mp2dp_virt_offset">
      <parent link="ring_mp2dp_virt_jointbody"/>
      <child link="ring_dp_virt"/>
      <origin xyz="-0.0 -0.00263391 -0.0882811" rpy="0.0 0.0 0.0"/>
   </joint>
   <link name="ring_dp">
      <inertial>
         <origin xyz="0.0004080281600351707 0.001635180393279046 0.10092332329872378" rpy="0.005320230753060984 0.04639366291748903 1.5713315351794575"/>
         <mass value="0.0014065189005047724"/>
         <inertia ixx="7.15765063531471e-08" iyy="6.265685623199896e-08" izz="1.6891661140100088e-08" ixy="0" ixz="0" iyz="0"/>
      </inertial>
      <visual name="ring_dp">
         <origin xyz="0.0004080281600351707 0.001635180393279046 0.10092332329872378" rpy="0.005320230753060984 0.04639366291748925 1.571331535179458"/>
         <geometry>
            <mesh filename="package://viz/models/titans_hand/urdf/converted_mesh/converted_ring_dp.stl"/>
         </geometry>
         <material name="white"/>
      </visual>
   </link>
   <link name="ring_mp2dp_jointbody">
      <inertial>
         <origin xyz="0.0 0.0 0.0" rpy="0.0 0.0 0.0"/>
         <mass value="0.001"/>
         <inertia ixx="1e-09" iyy="1e-09" izz="1e-09" ixy="0" ixz="0" iyz="0"/>
      </inertial>
   </link>
   <joint type="revolute" name="ring_mp2dp">
      <parent link="ring_dp_virt"/>
      <child link="ring_mp2dp_jointbody"/>
      <origin xyz="0.0 0.0017961 0.09655649" rpy="0.0 0.0 0.0"/>
      <axis xyz="1.0 0.0 0.0"/>
      <limit lower="-0.093" upper="0.682" effort="100" velocity="100"/>
   </joint>
   <joint type="fixed" name="ring_mp2dp_offset">
      <parent link="ring_mp2dp_jointbody"/>
      <child link="ring_dp"/>
      <origin xyz="-0.0 -0.0017961 -0.09655649" rpy="0.0 0.0 0.0"/>
   </joint>
   <link name="ring_fingertip">
      <inertial>
         <origin xyz="0.0 0.0 0.0" rpy="0.0 0.0 0.0"/>
         <mass value="0.0"/>
         <inertia ixx="0.0" iyy="0.0" izz="0.0" ixy="0" ixz="0" iyz="0"/>
      </inertial>
   </link>
   <link name="ring_dp2ring_fingertip_fixed_jointbody">
      <inertial>
         <origin xyz="0.0 0.0 0.0" rpy="0.0 0.0 0.0"/>
         <mass value="0.001"/>
         <inertia ixx="1e-09" iyy="1e-09" izz="1e-09" ixy="0" ixz="0" iyz="0"/>
      </inertial>
   </link>
   <joint type="fixed" name="ring_dp2ring_fingertip_fixed">
      <parent link="ring_dp"/>
      <child link="ring_dp2ring_fingertip_fixed_jointbody"/>
      <origin xyz="0.0 0.0 0.0" rpy="0.0 0.0 0.0"/>
   </joint>
   <joint type="fixed" name="ring_dp2ring_fingertip_fixed_offset">
      <parent link="ring_dp2ring_fingertip_fixed_jointbody"/>
      <child link="ring_fingertip"/>
      <origin xyz="-0.0 -0.0 -0.0" rpy="0.0 0.0 0.0"/>
   </joint>
   <link name="pinky_base">
      <inertial>
         <origin xyz="-1.3760015381432599e-06 0.0001725668069039066 0.004475784071478828" rpy="-0.001820563394911212 0.2840263082023218 1.5629472627759466"/>
         <mass value="0.00362069274308756"/>
         <inertia ixx="1.660759019712417e-07" iyy="1.58396401779484e-07" izz="8.57537012752121e-08" ixy="0" ixz="0" iyz="0"/>
      </inertial>
      <visual name="pinky_base">
         <origin xyz="-1.3760015381432599e-06 0.0001725668069039066 0.004475784071478828" rpy="-0.001820563394911212 0.2840263082023218 1.5629472627759466"/>
         <geometry>
            <mesh filename="package://viz/models/titans_hand/urdf/converted_mesh/converted_pinky_base.stl"/>
         </geometry>
         <material name="white"/>
      </visual>
   </link>
   <link name="palm2pinky_base_fixed_jointbody">
      <inertial>
         <origin xyz="0.0 0.0 0.0" rpy="0.0 0.0 0.0"/>
         <mass value="0.001"/>
         <inertia ixx="1e-09" iyy="1e-09" izz="1e-09" ixy="0" ixz="0" iyz="0"/>
      </inertial>
   </link>
   <joint type="fixed" name="palm2pinky_base_fixed">
      <parent link="palm"/>
      <child link="palm2pinky_base_fixed_jointbody"/>
      <origin xyz="0.002 -0.01537994548 0.103767481" rpy="0.0003713332265421476 -0.43633216514869133 1.5699176774335144"/>
   </joint>
   <joint type="fixed" name="palm2pinky_base_fixed_offset">
      <parent link="palm2pinky_base_fixed_jointbody"/>
      <child link="pinky_base"/>
      <origin xyz="-0.0 -0.0 -0.0" rpy="0.0 0.0 0.0"/>
   </joint>
   <link name="pinky_um_virt">
      <inertial>
         <origin xyz="0.0 0.0 0.02317496" rpy="0.0 0.0 0.0"/>
         <mass value="0.001"/>
         <inertia ixx="4e-10" iyy="4e-10" izz="3e-10" ixy="0" ixz="0" iyz="0"/>
      </inertial>
   </link>
   <link name="pinky_abd_virt_jointbody">
      <inertial>
         <origin xyz="0.0 0.0 0.0" rpy="0.0 0.0 0.0"/>
         <mass value="0.001"/>
         <inertia ixx="1e-09" iyy="1e-09" izz="1e-09" ixy="0" ixz="0" iyz="0"/>
      </inertial>
   </link>
   <joint type="revolute" name="pinky_abd_virt">
      <parent link="pinky_base"/>
      <child link="pinky_abd_virt_jointbody"/>
      <origin xyz="0.0 0.0 0.00527505" rpy="0.0 0.0 0.0"/>
      <axis xyz="0.0 1.0 0.0"/>
      <limit lower="-0.264" upper="0.264" effort="100" velocity="100"/>
   </joint>
   <joint type="fixed" name="pinky_abd_virt_offset">
      <parent link="pinky_abd_virt_jointbody"/>
      <child link="pinky_um_virt"/>
      <origin xyz="-0.0 -0.0 -0.00527505" rpy="0.0 0.0 0.0"/>
   </joint>
   <link name="pinky_um">
      <inertial>
         <origin xyz="1.7370519164770844e-05 0.0012715146657108968 0.02004891848100365" rpy="3.120877986607322 -1.1804296781579997 -1.5514785003273175"/>
         <mass value="0.0020507778801623494"/>
         <inertia ixx="5.3021061398745245e-08" iyy="4.456771195857276e-08" izz="4.1862251466191607e-08" ixy="0" ixz="0" iyz="0"/>
      </inertial>
      <visual name="pinky_um">
         <origin xyz="1.7370519164770844e-05 0.0012715146657108968 0.02004891848100365" rpy="3.120877986607322 -1.1804296781579997 -1.5514785003273168"/>
         <geometry>
            <mesh filename="package://viz/models/titans_hand/urdf/converted_mesh/converted_pinky_um.stl"/>
         </geometry>
         <material name="white"/>
      </visual>
   </link>
   <link name="pinky_abd_jointbody">
      <inertial>
         <origin xyz="0.0 0.0 0.0" rpy="0.0 0.0 0.0"/>
         <mass value="0.001"/>
         <inertia ixx="1e-09" iyy="1e-09" izz="1e-09" ixy="0" ixz="0" iyz="0"/>
      </inertial>
   </link>
   <joint type="revolute" name="pinky_abd">
      <parent link="pinky_um_virt"/>
      <child link="pinky_abd_jointbody"/>
      <origin xyz="0.0 0.0 0.02317496" rpy="0.0 0.0 0.0"/>
      <axis xyz="0.0 1.0 0.0"/>
      <limit lower="-0.264" upper="0.264" effort="100" velocity="100"/>
   </joint>
   <joint type="fixed" name="pinky_abd_offset">
      <parent link="pinky_abd_jointbody"/>
      <child link="pinky_um"/>
      <origin xyz="-0.0 -0.0 -0.02317496" rpy="0.0 0.0 0.0"/>
   </joint>
   <link name="pinky_pp_virt">
      <inertial>
         <origin xyz="0.0 0.00314317 0.03414407" rpy="0.0 0.0 0.0"/>
         <mass value="0.001"/>
         <inertia ixx="4e-10" iyy="4e-10" izz="3e-10" ixy="0" ixz="0" iyz="0"/>
      </inertial>
   </link>
   <link name="root2pinky_pp_virt_jointbody">
      <inertial>
         <origin xyz="0.0 0.0 0.0" rpy="0.0 0.0 0.0"/>
         <mass value="0.001"/>
         <inertia ixx="1e-09" iyy="1e-09" izz="1e-09" ixy="0" ixz="0" iyz="0"/>
      </inertial>
   </link>
   <joint type="revolute" name="root2pinky_pp_virt">
      <parent link="pinky_um"/>
      <child link="root2pinky_pp_virt_jointbody"/>
      <origin xyz="0.0 0.0033 0.01691888" rpy="0.0 0.0 0.0"/>
      <axis xyz="1.0 0.0 0.0"/>
      <limit lower="-0.157" upper="0.829" effort="100" velocity="100"/>
   </joint>
   <joint type="fixed" name="root2pinky_pp_virt_offset">
      <parent link="root2pinky_pp_virt_jointbody"/>
      <child link="pinky_pp_virt"/>
      <origin xyz="-0.0 -0.0033 -0.01691888" rpy="0.0 0.0 0.0"/>
   </joint>
   <link name="pinky_pp">
      <inertial>
         <origin xyz="0.00011637335936397564 0.001638621934740265 0.04496627954912128" rpy="0.0018869935921097536 0.038976549934939486 1.5584299043450622"/>
         <mass value="0.007546046440107924"/>
         <inertia ixx="9.56353434554292e-07" iyy="9.274116917842254e-07" izz="1.7176054342320975e-07" ixy="0" ixz="0" iyz="0"/>
      </inertial>
      <visual name="pinky_pp">
         <origin xyz="0.00011637335936397564 0.001638621934740265 0.04496627954912128" rpy="0.0018869935921097536 0.038976549934939486 1.5584299043450622"/>
         <geometry>
            <mesh filename="package://viz/models/titans_hand/urdf/converted_mesh/converted_pinky_pp.stl"/>
         </geometry>
         <material name="white"/>
      </visual>
   </link>
   <link name="root2pinky_pp_jointbody">
      <inertial>
         <origin xyz="0.0 0.0 0.0" rpy="0.0 0.0 0.0"/>
         <mass value="0.001"/>
         <inertia ixx="1e-09" iyy="1e-09" izz="1e-09" ixy="0" ixz="0" iyz="0"/>
      </inertial>
   </link>
   <joint type="revolute" name="root2pinky_pp">
      <parent link="pinky_pp_virt"/>
      <child link="root2pinky_pp_jointbody"/>
      <origin xyz="0.0 0.00314317 0.03414407" rpy="0.0 0.0 0.0"/>
      <axis xyz="1.0 0.0 0.0"/>
      <limit lower="-0.157" upper="0.829" effort="100" velocity="100"/>
   </joint>
   <joint type="fixed" name="root2pinky_pp_offset">
      <parent link="root2pinky_pp_jointbody"/>
      <child link="pinky_pp"/>
      <origin xyz="-0.0 -0.00314317 -0.03414407" rpy="0.0 0.0 0.0"/>
   </joint>
   <link name="pinky_pp_sens">
      <inertial>
         <origin xyz="0.0 0.0 0.0" rpy="0.0 0.0 0.0"/>
         <mass value="0.0"/>
         <inertia ixx="0.0" iyy="0.0" izz="0.0" ixy="0" ixz="0" iyz="0"/>
      </inertial>
   </link>
   <link name="pinky_pp2pinky_pp_sens_fixed_jointbody">
      <inertial>
         <origin xyz="0.0 0.0 0.0" rpy="0.0 0.0 0.0"/>
         <mass value="0.001"/>
         <inertia ixx="1e-09" iyy="1e-09" izz="1e-09" ixy="0" ixz="0" iyz="0"/>
      </inertial>
   </link>
   <joint type="fixed" name="pinky_pp2pinky_pp_sens_fixed">
      <parent link="pinky_pp"/>
      <child link="pinky_pp2pinky_pp_sens_fixed_jointbody"/>
      <origin xyz="0.0 0.0 0.0" rpy="0.0 0.0 0.0"/>
   </joint>
   <joint type="fixed" name="pinky_pp2pinky_pp_sens_fixed_offset">
      <parent link="pinky_pp2pinky_pp_sens_fixed_jointbody"/>
      <child link="pinky_pp_sens"/>
      <origin xyz="-0.0 -0.0 -0.0" rpy="0.0 0.0 0.0"/>
   </joint>
   <link name="pinky_mp_virt">
      <inertial>
         <origin xyz="0.0 0.0029099 0.07130514" rpy="0.0 0.0 0.0"/>
         <mass value="0.001"/>
         <inertia ixx="4e-10" iyy="4e-10" izz="3e-10" ixy="0" ixz="0" iyz="0"/>
      </inertial>
   </link>
   <link name="pinky_pp2mp_virt_jointbody">
      <inertial>
         <origin xyz="0.0 0.0 0.0" rpy="0.0 0.0 0.0"/>
         <mass value="0.001"/>
         <inertia ixx="1e-09" iyy="1e-09" izz="1e-09" ixy="0" ixz="0" iyz="0"/>
      </inertial>
   </link>
   <joint type="revolute" name="pinky_pp2mp_virt">
      <parent link="pinky_pp"/>
      <child link="pinky_pp2mp_virt_jointbody"/>
      <origin xyz="0.0 0.00371958 0.06026209" rpy="0.0 0.0 0.0"/>
      <axis xyz="1.0 0.0 0.0"/>
      <limit lower="-0.131" upper="0.96" effort="100" velocity="100"/>
   </joint>
   <joint type="fixed" name="pinky_pp2mp_virt_offset">
      <parent link="pinky_pp2mp_virt_jointbody"/>
      <child link="pinky_mp_virt"/>
      <origin xyz="-0.0 -0.00371958 -0.06026209" rpy="0.0 0.0 0.0"/>
   </joint>
   <link name="pinky_mp">
      <inertial>
         <origin xyz="0.00029668965848413434 0.0017783639299142466 0.07889527150394414" rpy="0.0056787978904592196 0.009123149673579745 1.5738823026622906"/>
         <mass value="0.0036096163027472743"/>
         <inertia ixx="2.3670857595223327e-07" iyy="2.0588776340491657e-07" izz="6.81524873648359e-08" ixy="0" ixz="0" iyz="0"/>
      </inertial>
      <visual name="pinky_mp">
         <origin xyz="0.00029668965848413434 0.0017783639299142466 0.07889527150394414" rpy="0.0056787978904592196 0.009123149673579745 1.573882302662291"/>
         <geometry>
            <mesh filename="package://viz/models/titans_hand/urdf/converted_mesh/converted_pinky_mp.stl"/>
         </geometry>
         <material name="white"/>
      </visual>
   </link>
   <link name="pinky_pp2mp_jointbody">
      <inertial>
         <origin xyz="0.0 0.0 0.0" rpy="0.0 0.0 0.0"/>
         <mass value="0.001"/>
         <inertia ixx="1e-09" iyy="1e-09" izz="1e-09" ixy="0" ixz="0" iyz="0"/>
      </inertial>
   </link>
   <joint type="revolute" name="pinky_pp2mp">
      <parent link="pinky_mp_virt"/>
      <child link="pinky_pp2mp_jointbody"/>
      <origin xyz="0.0 0.0029099 0.07130514" rpy="0.0 0.0 0.0"/>
      <axis xyz="1.0 0.0 0.0"/>
      <limit lower="-0.131" upper="0.96" effort="100" velocity="100"/>
   </joint>
   <joint type="fixed" name="pinky_pp2mp_offset">
      <parent link="pinky_pp2mp_jointbody"/>
      <child link="pinky_mp"/>
      <origin xyz="-0.0 -0.0029099 -0.07130514" rpy="0.0 0.0 0.0"/>
   </joint>
   <link name="pinky_dp_virt">
      <inertial>
         <origin xyz="0.0 0.0017961 0.09655649" rpy="0.0 0.0 0.0"/>
         <mass value="0.001"/>
         <inertia ixx="4e-10" iyy="4e-10" izz="3e-10" ixy="0" ixz="0" iyz="0"/>
      </inertial>
   </link>
   <link name="pinky_mp2dp_virt_jointbody">
      <inertial>
         <origin xyz="0.0 0.0 0.0" rpy="0.0 0.0 0.0"/>
         <mass value="0.001"/>
         <inertia ixx="1e-09" iyy="1e-09" izz="1e-09" ixy="0" ixz="0" iyz="0"/>
      </inertial>
   </link>
   <joint type="revolute" name="pinky_mp2dp_virt">
      <parent link="pinky_mp"/>
      <child link="pinky_mp2dp_virt_jointbody"/>
      <origin xyz="0.0 0.00263391 0.0882811" rpy="0.0 0.0 0.0"/>
      <axis xyz="1.0 0.0 0.0"/>
      <limit lower="-0.093" upper="0.682" effort="100" velocity="100"/>
   </joint>
   <joint type="fixed" name="pinky_mp2dp_virt_offset">
      <parent link="pinky_mp2dp_virt_jointbody"/>
      <child link="pinky_dp_virt"/>
      <origin xyz="-0.0 -0.00263391 -0.0882811" rpy="0.0 0.0 0.0"/>
   </joint>
   <link name="pinky_dp">
      <inertial>
         <origin xyz="0.0004080281600351707 0.001635180393279046 0.10092332329872378" rpy="0.005320230753060984 0.04639366291748903 1.5713315351794575"/>
         <mass value="0.0014065189005047724"/>
         <inertia ixx="7.15765063531471e-08" iyy="6.265685623199896e-08" izz="1.6891661140100088e-08" ixy="0" ixz="0" iyz="0"/>
      </inertial>
      <visual name="pinky_dp">
         <origin xyz="0.0004080281600351707 0.001635180393279046 0.10092332329872378" rpy="0.005320230753060984 0.04639366291748925 1.571331535179458"/>
         <geometry>
            <mesh filename="package://viz/models/titans_hand/urdf/converted_mesh/converted_pinky_dp.stl"/>
         </geometry>
         <material name="white"/>
      </visual>
   </link>
   <link name="pinky_mp2dp_jointbody">
      <inertial>
         <origin xyz="0.0 0.0 0.0" rpy="0.0 0.0 0.0"/>
         <mass value="0.001"/>
         <inertia ixx="1e-09" iyy="1e-09" izz="1e-09" ixy="0" ixz="0" iyz="0"/>
      </inertial>
   </link>
   <joint type="revolute" name="pinky_mp2dp">
      <parent link="pinky_dp_virt"/>
      <child link="pinky_mp2dp_jointbody"/>
      <origin xyz="0.0 0.0017961 0.09655649" rpy="0.0 0.0 0.0"/>
      <axis xyz="1.0 0.0 0.0"/>
      <limit lower="-0.093" upper="0.682" effort="100" velocity="100"/>
   </joint>
   <joint type="fixed" name="pinky_mp2dp_offset">
      <parent link="pinky_mp2dp_jointbody"/>
      <child link="pinky_dp"/>
      <origin xyz="-0.0 -0.0017961 -0.09655649" rpy="0.0 0.0 0.0"/>
   </joint>
   <link name="pinky_fingertip">
      <inertial>
         <origin xyz="0.0 0.0 0.0" rpy="0.0 0.0 0.0"/>
         <mass value="0.0"/>
         <inertia ixx="0.0" iyy="0.0" izz="0.0" ixy="0" ixz="0" iyz="0"/>
      </inertial>
   </link>
   <link name="pinky_dp2pinky_fingertip_fixed_jointbody">
      <inertial>
         <origin xyz="0.0 0.0 0.0" rpy="0.0 0.0 0.0"/>
         <mass value="0.001"/>
         <inertia ixx="1e-09" iyy="1e-09" izz="1e-09" ixy="0" ixz="0" iyz="0"/>
      </inertial>
   </link>
   <joint type="fixed" name="pinky_dp2pinky_fingertip_fixed">
      <parent link="pinky_dp"/>
      <child link="pinky_dp2pinky_fingertip_fixed_jointbody"/>
      <origin xyz="0.0 0.0 0.0" rpy="0.0 0.0 0.0"/>
   </joint>
   <joint type="fixed" name="pinky_dp2pinky_fingertip_fixed_offset">
      <parent link="pinky_dp2pinky_fingertip_fixed_jointbody"/>
      <child link="pinky_fingertip"/>
      <origin xyz="-0.0 -0.0 -0.0" rpy="0.0 0.0 0.0"/>
   </joint>
   <material name="white">
      <color rgba="1 1 1 1"/>
   </material>
</robot>
