<?xml version="1.0" ?>
<robot name="converted_robot">
   <link name="world">
      <inertial>
         <origin xyz="0.0 0.0 0.0" rpy="0.0 0.0 0.0"/>
         <mass value="0.0"/>
         <inertia ixx="0.0" iyy="0.0" izz="0.0" ixy="0" ixz="0" iyz="0"/>
      </inertial>
   </link>
   <link name="wrist">
      <inertial>
         <origin xyz="0.006398304079219358 2.5601891628451577e-05 0.010751708112468374" rpy="1.5592440798138425 -0.004602196226064947 1.5700834195723419"/>
         <mass value="0.08354295839941446"/>
         <inertia ixx="8.100770050394494e-05" iyy="7.735567955308567e-05" izz="5.790938091619951e-06" ixy="0" ixz="0" iyz="0"/>
      </inertial>
      <visual name="wrist">
         <origin xyz="0.006398304079219358 2.5601891628451577e-05 0.010751708112468374" rpy="1.5592440798138423 -0.004602196226064947 1.570083419572342"/>
         <geometry>
            <mesh filename="package://viz/models/titans_hand/urdf/converted_mesh/converted_wrist.stl"/>
         </geometry>
         <material name="white"/>
      </visual>
   </link>
   <link name="world2wrist_fixed_jointbody">
      <inertial>
         <origin xyz="0.0 0.0 0.0" rpy="0.0 0.0 0.0"/>
         <mass value="0.001"/>
         <inertia ixx="1e-09" iyy="1e-09" izz="1e-09" ixy="0" ixz="0" iyz="0"/>
      </inertial>
   </link>
   <joint type="fixed" name="world2wrist_fixed">
      <parent link="world"/>
      <child link="world2wrist_fixed_jointbody"/>
      <origin xyz="0.0 0.0 0.03" rpy="0.0 0.0 0.0"/>
   </joint>
   <joint type="fixed" name="world2wrist_fixed_offset">
      <parent link="world2wrist_fixed_jointbody"/>
      <child link="wrist"/>
      <origin xyz="-0.0 -0.0 -0.0" rpy="0.0 0.0 0.0"/>
   </joint>
   <link name="connector_base">
      <inertial>
         <origin xyz="0.005853447472027522 8.875956500885724e-08 0.01065122051551691" rpy="3.141592653589793 -1.5467576642344818 0.0"/>
         <mass value="0.07977435345788764"/>
         <inertia ixx="7.21448104416082e-05" iyy="7.164411977791013e-05" izz="1.2264239349716238e-05" ixy="0" ixz="0" iyz="0"/>
      </inertial>
      <visual name="connector_base">
         <origin xyz="0.005853447472027522 8.875956500885724e-08 0.01065122051551691" rpy="3.141592653589793 -1.5467576642344818 0.0"/>
         <geometry>
            <mesh filename="package://viz/models/titans_hand/urdf/converted_mesh/converted_connector_base.stl"/>
         </geometry>
         <material name="white"/>
      </visual>
   </link>
   <link name="revolute_base_hand_jointbody">
      <inertial>
         <origin xyz="0.0 0.0 0.0" rpy="0.0 0.0 0.0"/>
         <mass value="0.001"/>
         <inertia ixx="1e-09" iyy="1e-09" izz="1e-09" ixy="0" ixz="0" iyz="0"/>
      </inertial>
   </link>
   <joint type="revolute" name="revolute_base_hand">
      <parent link="wrist"/>
      <child link="revolute_base_hand_jointbody"/>
      <origin xyz="0.0 0.0 0.0" rpy="0.0 0.0 0.0"/>
      <axis xyz="1.0 0.0 0.0"/>
      <limit lower="-1.5707" upper="1.5707" effort="100" velocity="100"/>
   </joint>
   <joint type="fixed" name="revolute_base_hand_offset">
      <parent link="revolute_base_hand_jointbody"/>
      <child link="connector_base"/>
      <origin xyz="-0.0 -0.0 -0.03" rpy="0.0 0.0 0.0"/>
   </joint>
   <link name="palm">
      <inertial>
         <origin xyz="0.010094656341180435 -0.000553803013384598 0.03105483028308372" rpy="1.1186074852383143 0.04430379895530989 1.5628041845350036"/>
         <mass value="0.0780873173122749"/>
         <inertia ixx="6.0901843645658024e-05" iyy="4.614673284183627e-05" izz="1.6826391963182344e-05" ixy="0" ixz="0" iyz="0"/>
      </inertial>
      <visual name="palm">
         <origin xyz="0.010094656341180435 -0.000553803013384598 0.03105483028308372" rpy="1.1186074852383143 0.04430379895530989 1.5628041845350036"/>
         <geometry>
            <mesh filename="package://viz/models/titans_hand/urdf/converted_mesh/converted_palm.stl"/>
         </geometry>
         <material name="white"/>
      </visual>
   </link>
   <link name="wrist2palm_fixed_jointbody">
      <inertial>
         <origin xyz="0.0 0.0 0.0" rpy="0.0 0.0 0.0"/>
         <mass value="0.001"/>
         <inertia ixx="1e-09" iyy="1e-09" izz="1e-09" ixy="0" ixz="0" iyz="0"/>
      </inertial>
   </link>
   <joint type="fixed" name="wrist2palm_fixed">
      <parent link="wrist"/>
      <child link="wrist2palm_fixed_jointbody"/>
      <origin xyz="0.0 0.0 0.025" rpy="0.0 0.0 0.0"/>
   </joint>
   <joint type="fixed" name="wrist2palm_fixed_offset">
      <parent link="wrist2palm_fixed_jointbody"/>
      <child link="palm"/>
      <origin xyz="-0.0 -0.0 -0.0" rpy="0.0 0.0 0.0"/>
   </joint>
   <link name="thumb_base">
      <inertial>
         <origin xyz="0.011215182830463539 0.0029841183673705515 0.0016463816005658494" rpy="0.7654982077617296 -1.0771840751614328 2.8158047209123054"/>
         <mass value="0.01192734960073518"/>
         <inertia ixx="1.331480796603526e-06" iyy="1.1873079694313647e-06" izz="8.100218433718486e-07" ixy="0" ixz="0" iyz="0"/>
      </inertial>
      <visual name="thumb_hinge">
         <origin xyz="0.011215182830463539 0.0029841183673705515 0.0016463816005658494" rpy="0.7654982077617296 -1.0771840751614326 2.8158047209123054"/>
         <geometry>
            <mesh filename="package://viz/models/titans_hand/urdf/converted_mesh/converted_thumb_hinge.stl"/>
         </geometry>
         <material name="white"/>
      </visual>
   </link>
   <link name="thumb_hinge_jointbody">
      <inertial>
         <origin xyz="0.0 0.0 0.0" rpy="0.0 0.0 0.0"/>
         <mass value="0.001"/>
         <inertia ixx="1e-09" iyy="1e-09" izz="1e-09" ixy="0" ixz="0" iyz="0"/>
      </inertial>
   </link>
   <joint type="revolute" name="thumb_hinge">
      <parent link="palm"/>
      <child link="thumb_hinge_jointbody"/>
      <origin xyz="0.0393 0.0 0.023115" rpy="0.0 0.3490658500000001 0.0"/>
      <axis xyz="0.0 0.0 1.0"/>
      <limit lower="-1.75" upper="0.1" effort="100" velocity="100"/>
   </joint>
   <joint type="fixed" name="thumb_hinge_offset">
      <parent link="thumb_hinge_jointbody"/>
      <child link="thumb_base"/>
      <origin xyz="-0.0 -0.0 -0.0" rpy="0.0 0.0 0.0"/>
   </joint>
   <link name="thumb_pp">
      <inertial>
         <origin xyz="6.2787683180604015e-06 0.005125346570550757 0.016264992915475812" rpy="-0.0010123569356892403 -0.07264449111880178 -1.5672469521816081"/>
         <mass value="0.008517951004271104"/>
         <inertia ixx="1.3072129655499252e-06" iyy="1.2915714498132682e-06" izz="1.9551824716339084e-07" ixy="0" ixz="0" iyz="0"/>
      </inertial>
      <visual name="thumb_pp">
         <origin xyz="6.2787683180604015e-06 0.005125346570550757 0.016264992915475812" rpy="-0.0010123569356892403 -0.07264449111880178 -1.5672469521816081"/>
         <geometry>
            <mesh filename="package://viz/models/titans_hand/urdf/converted_mesh/converted_thumb_pp.stl"/>
         </geometry>
         <material name="white"/>
      </visual>
   </link>
   <link name="thumb_base2pp_jointbody">
      <inertial>
         <origin xyz="0.0 0.0 0.0" rpy="0.0 0.0 0.0"/>
         <mass value="0.001"/>
         <inertia ixx="1e-09" iyy="1e-09" izz="1e-09" ixy="0" ixz="0" iyz="0"/>
      </inertial>
   </link>
   <joint type="revolute" name="thumb_base2pp">
      <parent link="thumb_base"/>
      <child link="thumb_base2pp_jointbody"/>
      <origin xyz="0.02053 0.0 0.007747733972" rpy="0.0 0.0 0.0"/>
      <axis xyz="0.0 1.0 0.0"/>
      <limit lower="-0.2" upper="1.35" effort="100" velocity="100"/>
   </joint>
   <joint type="fixed" name="thumb_base2pp_offset">
      <parent link="thumb_base2pp_jointbody"/>
      <child link="thumb_pp"/>
      <origin xyz="-0.0 -0.0 -0.0" rpy="0.0 0.0 0.0"/>
   </joint>
   <link name="thumb_mp_virt">
      <inertial>
         <origin xyz="0.0 0.0 0.0" rpy="0.0 0.0 0.0"/>
         <mass value="0.001"/>
         <inertia ixx="4e-10" iyy="4e-10" izz="3e-10" ixy="0" ixz="0" iyz="0"/>
      </inertial>
   </link>
   <link name="thumb_pp2mp_virt_jointbody">
      <inertial>
         <origin xyz="0.0 0.0 0.0" rpy="0.0 0.0 0.0"/>
         <mass value="0.001"/>
         <inertia ixx="1e-09" iyy="1e-09" izz="1e-09" ixy="0" ixz="0" iyz="0"/>
      </inertial>
   </link>
   <joint type="revolute" name="thumb_pp2mp_virt">
      <parent link="thumb_pp"/>
      <child link="thumb_pp2mp_virt_jointbody"/>
      <origin xyz="0.0 0.0079 0.03471" rpy="0.0 0.0 0.0"/>
      <axis xyz="1.0 0.0 0.0"/>
      <limit lower="-0.131" upper="0.96" effort="100" velocity="100"/>
   </joint>
   <joint type="fixed" name="thumb_pp2mp_virt_offset">
      <parent link="thumb_pp2mp_virt_jointbody"/>
      <child link="thumb_mp_virt"/>
      <origin xyz="-0.0 -0.0 -0.0" rpy="0.0 0.0 0.0"/>
   </joint>
   <link name="thumb_mp">
      <inertial>
         <origin xyz="-7.55086448478437e-07 -0.001512541664618965 0.007480601507547438" rpy="0.0034460599232096767 0.040554727472796204 -1.5647320172412593"/>
         <mass value="0.0036257578156079634"/>
         <inertia ixx="2.3818490558554055e-07" iyy="2.0716154410734043e-07" izz="6.832850890110207e-08" ixy="0" ixz="0" iyz="0"/>
      </inertial>
      <visual name="thumb_mp">
         <origin xyz="-7.55086448478437e-07 -0.001512541664618965 0.007480601507547438" rpy="0.0034460599232096767 0.040554727472796204 -1.5647320172412593"/>
         <geometry>
            <mesh filename="package://viz/models/titans_hand/urdf/converted_mesh/converted_thumb_mp.stl"/>
         </geometry>
         <material name="white"/>
      </visual>
   </link>
   <link name="thumb_pp2mp_jointbody">
      <inertial>
         <origin xyz="0.0 0.0 0.0" rpy="0.0 0.0 0.0"/>
         <mass value="0.001"/>
         <inertia ixx="1e-09" iyy="1e-09" izz="1e-09" ixy="0" ixz="0" iyz="0"/>
      </inertial>
   </link>
   <joint type="revolute" name="thumb_pp2mp">
      <parent link="thumb_mp_virt"/>
      <child link="thumb_pp2mp_jointbody"/>
      <origin xyz="0.0 -0.00094 0.01115" rpy="0.0 0.0 0.0"/>
      <axis xyz="1.0 0.0 0.0"/>
      <limit lower="-0.131" upper="0.96" effort="100" velocity="100"/>
   </joint>
   <joint type="fixed" name="thumb_pp2mp_offset">
      <parent link="thumb_pp2mp_jointbody"/>
      <child link="thumb_mp"/>
      <origin xyz="-0.0 -0.0 -0.0" rpy="0.0 0.0 0.0"/>
   </joint>
   <link name="thumb_dp_virt">
      <inertial>
         <origin xyz="0.0 0.0 -0.1" rpy="0.0 0.0 0.0"/>
         <mass value="0.001"/>
         <inertia ixx="4e-10" iyy="4e-10" izz="3e-10" ixy="0" ixz="0" iyz="0"/>
      </inertial>
   </link>
   <link name="thumb_mp2dp_virt_jointbody">
      <inertial>
         <origin xyz="0.0 0.0 0.0" rpy="0.0 0.0 0.0"/>
         <mass value="0.001"/>
         <inertia ixx="1e-09" iyy="1e-09" izz="1e-09" ixy="0" ixz="0" iyz="0"/>
      </inertial>
   </link>
   <joint type="revolute" name="thumb_mp2dp_virt">
      <parent link="thumb_mp"/>
      <child link="thumb_mp2dp_virt_jointbody"/>
      <origin xyz="0.0 -0.0011 0.01693" rpy="0.0 0.0 0.0"/>
      <axis xyz="1.0 0.0 0.0"/>
      <limit lower="-0.093" upper="0.682" effort="100" velocity="100"/>
   </joint>
   <joint type="fixed" name="thumb_mp2dp_virt_offset">
      <parent link="thumb_mp2dp_virt_jointbody"/>
      <child link="thumb_dp_virt"/>
      <origin xyz="-0.0 -0.0 -0.0" rpy="0.0 0.0 0.0"/>
   </joint>
   <link name="thumb_dp">
      <inertial>
         <origin xyz="3.630100010740267e-06 -0.0003437698391527567 0.00437159682784985" rpy="-0.0005379593086076717 -0.00143310992923662 -1.5708182980816119"/>
         <mass value="0.0014065189510415494"/>
         <inertia ixx="7.157650835027881e-08" iyy="6.265685831321033e-08" izz="1.6891661726787585e-08" ixy="0" ixz="0" iyz="0"/>
      </inertial>
      <visual name="thumb_dp">
         <origin xyz="3.630100010740267e-06 -0.0003437698391527567 0.00437159682784985" rpy="-0.0005379593086080048 -0.00143310992923662 -1.5708182980816119"/>
         <geometry>
            <mesh filename="package://viz/models/titans_hand/urdf/converted_mesh/converted_thumb_dp.stl"/>
         </geometry>
         <material name="white"/>
      </visual>
   </link>
   <link name="thumb_mp2dp_jointbody">
      <inertial>
         <origin xyz="0.0 0.0 0.0" rpy="0.0 0.0 0.0"/>
         <mass value="0.001"/>
         <inertia ixx="1e-09" iyy="1e-09" izz="1e-09" ixy="0" ixz="0" iyz="0"/>
      </inertial>
   </link>
   <joint type="revolute" name="thumb_mp2dp">
      <parent link="thumb_dp_virt"/>
      <child link="thumb_mp2dp_jointbody"/>
      <origin xyz="0.0 -0.00121 0.00845" rpy="0.0 0.0 0.0"/>
      <axis xyz="1.0 0.0 0.0"/>
      <limit lower="-0.093" upper="0.682" effort="100" velocity="100"/>
   </joint>
   <joint type="fixed" name="thumb_mp2dp_offset">
      <parent link="thumb_mp2dp_jointbody"/>
      <child link="thumb_dp"/>
      <origin xyz="-0.0 -0.0 -0.0" rpy="0.0 0.0 0.0"/>
   </joint>
   <link name="thumb_fingertip">
      <inertial>
         <origin xyz="0.0 0.0 0.01465" rpy="0.0 0.0 0.0"/>
         <mass value="0.0"/>
         <inertia ixx="0.0" iyy="0.0" izz="0.0" ixy="0" ixz="0" iyz="0"/>
      </inertial>
   </link>
   <link name="thumb_dp2thumb_fingertip_fixed_jointbody">
      <inertial>
         <origin xyz="0.0 0.0 0.0" rpy="0.0 0.0 0.0"/>
         <mass value="0.001"/>
         <inertia ixx="1e-09" iyy="1e-09" izz="1e-09" ixy="0" ixz="0" iyz="0"/>
      </inertial>
   </link>
   <joint type="fixed" name="thumb_dp2thumb_fingertip_fixed">
      <parent link="thumb_dp"/>
      <child link="thumb_dp2thumb_fingertip_fixed_jointbody"/>
      <origin xyz="0.0 0.0 0.01465" rpy="0.0 0.0 0.0"/>
   </joint>
   <joint type="fixed" name="thumb_dp2thumb_fingertip_fixed_offset">
      <parent link="thumb_dp2thumb_fingertip_fixed_jointbody"/>
      <child link="thumb_fingertip"/>
      <origin xyz="-0.0 -0.0 -0.0" rpy="0.0 0.0 0.0"/>
   </joint>
   <link name="index_base">
      <inertial>
         <origin xyz="-1.3760015381432599e-06 0.0001725668069039066 0.004475784071478828" rpy="-0.001820563394911212 0.2840263082023218 1.5629472627759466"/>
         <mass value="0.00362069274308756"/>
         <inertia ixx="1.660759019712417e-07" iyy="1.58396401779484e-07" izz="8.57537012752121e-08" ixy="0" ixz="0" iyz="0"/>
      </inertial>
      <visual name="index_base">
         <origin xyz="-1.3760015381432599e-06 0.0001725668069039066 0.004475784071478828" rpy="-0.001820563394911212 0.2840263082023218 1.5629472627759466"/>
         <geometry>
            <mesh filename="package://viz/models/titans_hand/urdf/converted_mesh/converted_index_base.stl"/>
         </geometry>
         <material name="white"/>
      </visual>
   </link>
   <link name="palm2index_base_fixed_jointbody">
      <inertial>
         <origin xyz="0.0 0.0 0.0" rpy="0.0 0.0 0.0"/>
         <mass value="0.001"/>
         <inertia ixx="1e-09" iyy="1e-09" izz="1e-09" ixy="0" ixz="0" iyz="0"/>
      </inertial>
   </link>
   <joint type="fixed" name="palm2index_base_fixed">
      <parent link="palm"/>
      <child link="palm2index_base_fixed_jointbody"/>
      <origin xyz="0.04096 -0.002 0.063" rpy="0.0 0.0 0.0"/>
   </joint>
   <joint type="fixed" name="palm2index_base_fixed_offset">
      <parent link="palm2index_base_fixed_jointbody"/>
      <child link="index_base"/>
      <origin xyz="-0.0 -0.0 -0.0" rpy="0.0 0.0 0.0"/>
   </joint>
   <link name="index_um_virt">
      <inertial>
         <origin xyz="0.0 0.0 0.0" rpy="0.0 0.0 0.0"/>
         <mass value="0.001"/>
         <inertia ixx="4e-10" iyy="4e-10" izz="3e-10" ixy="0" ixz="0" iyz="0"/>
      </inertial>
   </link>
   <link name="index_abd_virt_jointbody">
      <inertial>
         <origin xyz="0.0 0.0 0.0" rpy="0.0 0.0 0.0"/>
         <mass value="0.001"/>
         <inertia ixx="1e-09" iyy="1e-09" izz="1e-09" ixy="0" ixz="0" iyz="0"/>
      </inertial>
   </link>
   <joint type="revolute" name="index_abd_virt">
      <parent link="index_base"/>
      <child link="index_abd_virt_jointbody"/>
      <origin xyz="0.0 0.0 0.00527505" rpy="0.0 0.0 0.0"/>
      <axis xyz="0.0 1.0 0.0"/>
      <limit lower="-0.264" upper="0.264" effort="100" velocity="100"/>
   </joint>
   <joint type="fixed" name="index_abd_virt_offset">
      <parent link="index_abd_virt_jointbody"/>
      <child link="index_um_virt"/>
      <origin xyz="-0.0 -0.0 -0.0" rpy="0.0 0.0 0.0"/>
   </joint>
   <link name="index_um">
      <inertial>
         <origin xyz="1.7370519164770844e-05 0.0012715146657108968 -0.0031260415189963524" rpy="3.120877986607322 -1.1804296781579997 -1.5514785003273175"/>
         <mass value="0.0020507778801623494"/>
         <inertia ixx="5.3021061398745245e-08" iyy="4.456771195857276e-08" izz="4.1862251466191607e-08" ixy="0" ixz="0" iyz="0"/>
      </inertial>
      <visual name="index_um">
         <origin xyz="1.7370519164770844e-05 0.0012715146657108968 -0.0031260415189963524" rpy="3.120877986607322 -1.1804296781579997 -1.5514785003273168"/>
         <geometry>
            <mesh filename="package://viz/models/titans_hand/urdf/converted_mesh/converted_index_um.stl"/>
         </geometry>
         <material name="white"/>
      </visual>
   </link>
   <link name="index_abd_jointbody">
      <inertial>
         <origin xyz="0.0 0.0 0.0" rpy="0.0 0.0 0.0"/>
         <mass value="0.001"/>
         <inertia ixx="1e-09" iyy="1e-09" izz="1e-09" ixy="0" ixz="0" iyz="0"/>
      </inertial>
   </link>
   <joint type="revolute" name="index_abd">
      <parent link="index_um_virt"/>
      <child link="index_abd_jointbody"/>
      <origin xyz="0.0 0.0 0.01789991" rpy="0.0 0.0 0.0"/>
      <axis xyz="0.0 1.0 0.0"/>
      <limit lower="-0.264" upper="0.264" effort="100" velocity="100"/>
   </joint>
   <joint type="fixed" name="index_abd_offset">
      <parent link="index_abd_jointbody"/>
      <child link="index_um"/>
      <origin xyz="-0.0 -0.0 -0.0" rpy="0.0 0.0 0.0"/>
   </joint>
   <link name="index_pp_virt">
      <inertial>
         <origin xyz="0.0 0.0 0.0" rpy="0.0 0.0 0.0"/>
         <mass value="0.001"/>
         <inertia ixx="4e-10" iyy="4e-10" izz="3e-10" ixy="0" ixz="0" iyz="0"/>
      </inertial>
   </link>
   <link name="root2index_pp_virt_jointbody">
      <inertial>
         <origin xyz="0.0 0.0 0.0" rpy="0.0 0.0 0.0"/>
         <mass value="0.001"/>
         <inertia ixx="1e-09" iyy="1e-09" izz="1e-09" ixy="0" ixz="0" iyz="0"/>
      </inertial>
   </link>
   <joint type="revolute" name="root2index_pp_virt">
      <parent link="index_um"/>
      <child link="root2index_pp_virt_jointbody"/>
      <origin xyz="0.0 0.0033 -0.00625608" rpy="0.0 0.0 0.0"/>
      <axis xyz="1.0 0.0 0.0"/>
      <limit lower="-0.157" upper="0.829" effort="100" velocity="100"/>
   </joint>
   <joint type="fixed" name="root2index_pp_virt_offset">
      <parent link="root2index_pp_virt_jointbody"/>
      <child link="index_pp_virt"/>
      <origin xyz="-0.0 -0.0 -0.0" rpy="0.0 0.0 0.0"/>
   </joint>
   <link name="index_pp">
      <inertial>
         <origin xyz="0.00011637335936397564 -0.001818208065259735 0.010822209549121282" rpy="0.0018869935921097536 0.038976549934939486 1.5584299043450622"/>
         <mass value="0.007546046440107924"/>
         <inertia ixx="9.56353434554292e-07" iyy="9.274116917842254e-07" izz="1.7176054342320975e-07" ixy="0" ixz="0" iyz="0"/>
      </inertial>
      <visual name="index_pp">
         <origin xyz="0.00011637335936397564 -0.001818208065259735 0.010822209549121282" rpy="0.0018869935921097536 0.038976549934939486 1.5584299043450622"/>
         <geometry>
            <mesh filename="package://viz/models/titans_hand/urdf/converted_mesh/converted_index_pp.stl"/>
         </geometry>
         <material name="white"/>
      </visual>
   </link>
   <link name="root2index_pp_jointbody">
      <inertial>
         <origin xyz="0.0 0.0 0.0" rpy="0.0 0.0 0.0"/>
         <mass value="0.001"/>
         <inertia ixx="1e-09" iyy="1e-09" izz="1e-09" ixy="0" ixz="0" iyz="0"/>
      </inertial>
   </link>
   <joint type="revolute" name="root2index_pp">
      <parent link="index_pp_virt"/>
      <child link="root2index_pp_jointbody"/>
      <origin xyz="0.0 -0.00015683 0.01722519" rpy="0.0 0.0 0.0"/>
      <axis xyz="1.0 0.0 0.0"/>
      <limit lower="-0.157" upper="0.829" effort="100" velocity="100"/>
   </joint>
   <joint type="fixed" name="root2index_pp_offset">
      <parent link="root2index_pp_jointbody"/>
      <child link="index_pp"/>
      <origin xyz="-0.0 -0.0 -0.0" rpy="0.0 0.0 0.0"/>
   </joint>
   <link name="index_pp_sens">
      <inertial>
         <origin xyz="0.0 0.0 0.0" rpy="0.0 0.0 0.0"/>
         <mass value="0.0"/>
         <inertia ixx="0.0" iyy="0.0" izz="0.0" ixy="0" ixz="0" iyz="0"/>
      </inertial>
   </link>
   <link name="index_pp2index_pp_sens_fixed_jointbody">
      <inertial>
         <origin xyz="0.0 0.0 0.0" rpy="0.0 0.0 0.0"/>
         <mass value="0.001"/>
         <inertia ixx="1e-09" iyy="1e-09" izz="1e-09" ixy="0" ixz="0" iyz="0"/>
      </inertial>
   </link>
   <joint type="fixed" name="index_pp2index_pp_sens_fixed">
      <parent link="index_pp"/>
      <child link="index_pp2index_pp_sens_fixed_jointbody"/>
      <origin xyz="0.0 0.0 0.0" rpy="0.0 0.0 0.0"/>
   </joint>
   <joint type="fixed" name="index_pp2index_pp_sens_fixed_offset">
      <parent link="index_pp2index_pp_sens_fixed_jointbody"/>
      <child link="index_pp_sens"/>
      <origin xyz="-0.0 -0.0 -0.0" rpy="0.0 0.0 0.0"/>
   </joint>
   <link name="index_mp_virt">
      <inertial>
         <origin xyz="0.0 0.0 0.0" rpy="0.0 0.0 0.0"/>
         <mass value="0.001"/>
         <inertia ixx="4e-10" iyy="4e-10" izz="3e-10" ixy="0" ixz="0" iyz="0"/>
      </inertial>
   </link>
   <link name="index_pp2mp_virt_jointbody">
      <inertial>
         <origin xyz="0.0 0.0 0.0" rpy="0.0 0.0 0.0"/>
         <mass value="0.001"/>
         <inertia ixx="1e-09" iyy="1e-09" izz="1e-09" ixy="0" ixz="0" iyz="0"/>
      </inertial>
   </link>
   <joint type="revolute" name="index_pp2mp_virt">
      <parent link="index_pp"/>
      <child link="index_pp2mp_virt_jointbody"/>
      <origin xyz="0.0 0.00057641 0.02611802" rpy="0.0 0.0 0.0"/>
      <axis xyz="1.0 0.0 0.0"/>
      <limit lower="-0.131" upper="0.96" effort="100" velocity="100"/>
   </joint>
   <joint type="fixed" name="index_pp2mp_virt_offset">
      <parent link="index_pp2mp_virt_jointbody"/>
      <child link="index_mp_virt"/>
      <origin xyz="-0.0 -0.0 -0.0" rpy="0.0 0.0 0.0"/>
   </joint>
   <link name="index_mp">
      <inertial>
         <origin xyz="0.00029668965848413434 -0.0011315360700857534 0.007590131503944136" rpy="0.0056787978904592196 0.009123149673579745 1.5738823026622906"/>
         <mass value="0.0036096163027472743"/>
         <inertia ixx="2.3670857595223327e-07" iyy="2.0588776340491657e-07" izz="6.81524873648359e-08" ixy="0" ixz="0" iyz="0"/>
      </inertial>
      <visual name="index_mp">
         <origin xyz="0.00029668965848413434 -0.0011315360700857534 0.007590131503944136" rpy="0.0056787978904592196 0.009123149673579745 1.573882302662291"/>
         <geometry>
            <mesh filename="package://viz/models/titans_hand/urdf/converted_mesh/converted_index_mp.stl"/>
         </geometry>
         <material name="white"/>
      </visual>
   </link>
   <link name="index_pp2mp_jointbody">
      <inertial>
         <origin xyz="0.0 0.0 0.0" rpy="0.0 0.0 0.0"/>
         <mass value="0.001"/>
         <inertia ixx="1e-09" iyy="1e-09" izz="1e-09" ixy="0" ixz="0" iyz="0"/>
      </inertial>
   </link>
   <joint type="revolute" name="index_pp2mp">
      <parent link="index_mp_virt"/>
      <child link="index_pp2mp_jointbody"/>
      <origin xyz="0.0 -0.00080968 0.01104305" rpy="0.0 0.0 0.0"/>
      <axis xyz="1.0 0.0 0.0"/>
      <limit lower="-0.131" upper="0.96" effort="100" velocity="100"/>
   </joint>
   <joint type="fixed" name="index_pp2mp_offset">
      <parent link="index_pp2mp_jointbody"/>
      <child link="index_mp"/>
      <origin xyz="-0.0 -0.0 -0.0" rpy="0.0 0.0 0.0"/>
   </joint>
   <link name="index_dp_virt">
      <inertial>
         <origin xyz="0.0 0.0 -0.1" rpy="0.0 0.0 0.0"/>
         <mass value="0.001"/>
         <inertia ixx="4e-10" iyy="4e-10" izz="3e-10" ixy="0" ixz="0" iyz="0"/>
      </inertial>
   </link>
   <link name="index_mp2dp_virt_jointbody">
      <inertial>
         <origin xyz="0.0 0.0 0.0" rpy="0.0 0.0 0.0"/>
         <mass value="0.001"/>
         <inertia ixx="1e-09" iyy="1e-09" izz="1e-09" ixy="0" ixz="0" iyz="0"/>
      </inertial>
   </link>
   <joint type="revolute" name="index_mp2dp_virt">
      <parent link="index_mp"/>
      <child link="index_mp2dp_virt_jointbody"/>
      <origin xyz="0.0 -0.00027599 0.01697596" rpy="0.0 0.0 0.0"/>
      <axis xyz="1.0 0.0 0.0"/>
      <limit lower="-0.093" upper="0.682" effort="100" velocity="100"/>
   </joint>
   <joint type="fixed" name="index_mp2dp_virt_offset">
      <parent link="index_mp2dp_virt_jointbody"/>
      <child link="index_dp_virt"/>
      <origin xyz="-0.0 -0.0 -0.0" rpy="0.0 0.0 0.0"/>
   </joint>
   <link name="index_dp">
      <inertial>
         <origin xyz="0.0004080281600351707 -0.0001609196067209539 0.004366833298723782" rpy="0.005320230753060984 0.04639366291748903 1.5713315351794575"/>
         <mass value="0.0014065189005047724"/>
         <inertia ixx="7.15765063531471e-08" iyy="6.265685623199896e-08" izz="1.6891661140100088e-08" ixy="0" ixz="0" iyz="0"/>
      </inertial>
      <visual name="index_dp">
         <origin xyz="0.0004080281600351707 -0.0001609196067209539 0.004366833298723782" rpy="0.005320230753060984 0.04639366291748925 1.571331535179458"/>
         <geometry>
            <mesh filename="package://viz/models/titans_hand/urdf/converted_mesh/converted_index_dp.stl"/>
         </geometry>
         <material name="white"/>
      </visual>
   </link>
   <link name="index_mp2dp_jointbody">
      <inertial>
         <origin xyz="0.0 0.0 0.0" rpy="0.0 0.0 0.0"/>
         <mass value="0.001"/>
         <inertia ixx="1e-09" iyy="1e-09" izz="1e-09" ixy="0" ixz="0" iyz="0"/>
      </inertial>
   </link>
   <joint type="revolute" name="index_mp2dp">
      <parent link="index_dp_virt"/>
      <child link="index_mp2dp_jointbody"/>
      <origin xyz="0.0 -0.00083781 0.00827539" rpy="0.0 0.0 0.0"/>
      <axis xyz="1.0 0.0 0.0"/>
      <limit lower="-0.093" upper="0.682" effort="100" velocity="100"/>
   </joint>
   <joint type="fixed" name="index_mp2dp_offset">
      <parent link="index_mp2dp_jointbody"/>
      <child link="index_dp"/>
      <origin xyz="-0.0 -0.0 -0.0" rpy="0.0 0.0 0.0"/>
   </joint>
   <link name="index_fingertip">
      <inertial>
         <origin xyz="0.0 0.0 0.01309" rpy="0.0 0.0 0.0"/>
         <mass value="0.0"/>
         <inertia ixx="0.0" iyy="0.0" izz="0.0" ixy="0" ixz="0" iyz="0"/>
      </inertial>
   </link>
   <link name="index_dp2index_fingertip_fixed_jointbody">
      <inertial>
         <origin xyz="0.0 0.0 0.0" rpy="0.0 0.0 0.0"/>
         <mass value="0.001"/>
         <inertia ixx="1e-09" iyy="1e-09" izz="1e-09" ixy="0" ixz="0" iyz="0"/>
      </inertial>
   </link>
   <joint type="fixed" name="index_dp2index_fingertip_fixed">
      <parent link="index_dp"/>
      <child link="index_dp2index_fingertip_fixed_jointbody"/>
      <origin xyz="0.0 0.0 0.01309" rpy="0.0 0.0 0.0"/>
   </joint>
   <joint type="fixed" name="index_dp2index_fingertip_fixed_offset">
      <parent link="index_dp2index_fingertip_fixed_jointbody"/>
      <child link="index_fingertip"/>
      <origin xyz="-0.0 -0.0 -0.0" rpy="0.0 0.0 0.0"/>
   </joint>
   <link name="middle_base">
      <inertial>
         <origin xyz="-1.3760015381432599e-06 0.0001725668069039066 0.004475784071478828" rpy="-0.001820563394911212 0.2840263082023218 1.5629472627759466"/>
         <mass value="0.00362069274308756"/>
         <inertia ixx="1.660759019712417e-07" iyy="1.58396401779484e-07" izz="8.57537012752121e-08" ixy="0" ixz="0" iyz="0"/>
      </inertial>
      <visual name="middle_base">
         <origin xyz="-1.3760015381432599e-06 0.0001725668069039066 0.004475784071478828" rpy="-0.001820563394911212 0.2840263082023218 1.5629472627759466"/>
         <geometry>
            <mesh filename="package://viz/models/titans_hand/urdf/converted_mesh/converted_middle_base.stl"/>
         </geometry>
         <material name="white"/>
      </visual>
   </link>
   <link name="palm2middle_base_fixed_jointbody">
      <inertial>
         <origin xyz="0.0 0.0 0.0" rpy="0.0 0.0 0.0"/>
         <mass value="0.001"/>
         <inertia ixx="1e-09" iyy="1e-09" izz="1e-09" ixy="0" ixz="0" iyz="0"/>
      </inertial>
   </link>
   <joint type="fixed" name="palm2middle_base_fixed">
      <parent link="palm"/>
      <child link="palm2middle_base_fixed_jointbody"/>
      <origin xyz="0.02163081458 -0.002 0.060168462" rpy="0.0 -0.17453300000000005 0.0"/>
   </joint>
   <joint type="fixed" name="palm2middle_base_fixed_offset">
      <parent link="palm2middle_base_fixed_jointbody"/>
      <child link="middle_base"/>
      <origin xyz="-0.0 -0.0 -0.0" rpy="0.0 0.0 0.0"/>
   </joint>
   <link name="middle_um_virt">
      <inertial>
         <origin xyz="0.0 0.0 0.0" rpy="0.0 0.0 0.0"/>
         <mass value="0.001"/>
         <inertia ixx="4e-10" iyy="4e-10" izz="3e-10" ixy="0" ixz="0" iyz="0"/>
      </inertial>
   </link>
   <link name="middle_abd_virt_jointbody">
      <inertial>
         <origin xyz="0.0 0.0 0.0" rpy="0.0 0.0 0.0"/>
         <mass value="0.001"/>
         <inertia ixx="1e-09" iyy="1e-09" izz="1e-09" ixy="0" ixz="0" iyz="0"/>
      </inertial>
   </link>
   <joint type="revolute" name="middle_abd_virt">
      <parent link="middle_base"/>
      <child link="middle_abd_virt_jointbody"/>
      <origin xyz="0.0 0.0 0.00527505" rpy="0.0 0.0 0.0"/>
      <axis xyz="0.0 1.0 0.0"/>
      <limit lower="-0.264" upper="0.264" effort="100" velocity="100"/>
   </joint>
   <joint type="fixed" name="middle_abd_virt_offset">
      <parent link="middle_abd_virt_jointbody"/>
      <child link="middle_um_virt"/>
      <origin xyz="-0.0 -0.0 -0.0" rpy="0.0 0.0 0.0"/>
   </joint>
   <link name="middle_um">
      <inertial>
         <origin xyz="1.7370519164770844e-05 0.0012715146657108968 -0.0031260415189963524" rpy="3.120877986607322 -1.1804296781579997 -1.5514785003273175"/>
         <mass value="0.0020507778801623494"/>
         <inertia ixx="5.3021061398745245e-08" iyy="4.456771195857276e-08" izz="4.1862251466191607e-08" ixy="0" ixz="0" iyz="0"/>
      </inertial>
      <visual name="middle_um">
         <origin xyz="1.7370519164770844e-05 0.0012715146657108968 -0.0031260415189963524" rpy="3.120877986607322 -1.1804296781579997 -1.5514785003273168"/>
         <geometry>
            <mesh filename="package://viz/models/titans_hand/urdf/converted_mesh/converted_middle_um.stl"/>
         </geometry>
         <material name="white"/>
      </visual>
   </link>
   <link name="middle_abd_jointbody">
      <inertial>
         <origin xyz="0.0 0.0 0.0" rpy="0.0 0.0 0.0"/>
         <mass value="0.001"/>
         <inertia ixx="1e-09" iyy="1e-09" izz="1e-09" ixy="0" ixz="0" iyz="0"/>
      </inertial>
   </link>
   <joint type="revolute" name="middle_abd">
      <parent link="middle_um_virt"/>
      <child link="middle_abd_jointbody"/>
      <origin xyz="0.0 0.0 0.01789991" rpy="0.0 0.0 0.0"/>
      <axis xyz="0.0 1.0 0.0"/>
      <limit lower="-0.264" upper="0.264" effort="100" velocity="100"/>
   </joint>
   <joint type="fixed" name="middle_abd_offset">
      <parent link="middle_abd_jointbody"/>
      <child link="middle_um"/>
      <origin xyz="-0.0 -0.0 -0.0" rpy="0.0 0.0 0.0"/>
   </joint>
   <link name="middle_pp_virt">
      <inertial>
         <origin xyz="0.0 0.0 0.0" rpy="0.0 0.0 0.0"/>
         <mass value="0.001"/>
         <inertia ixx="4e-10" iyy="4e-10" izz="3e-10" ixy="0" ixz="0" iyz="0"/>
      </inertial>
   </link>
   <link name="root2middle_pp_virt_jointbody">
      <inertial>
         <origin xyz="0.0 0.0 0.0" rpy="0.0 0.0 0.0"/>
         <mass value="0.001"/>
         <inertia ixx="1e-09" iyy="1e-09" izz="1e-09" ixy="0" ixz="0" iyz="0"/>
      </inertial>
   </link>
   <joint type="revolute" name="root2middle_pp_virt">
      <parent link="middle_um"/>
      <child link="root2middle_pp_virt_jointbody"/>
      <origin xyz="0.0 0.0033 -0.00625608" rpy="0.0 0.0 0.0"/>
      <axis xyz="1.0 0.0 0.0"/>
      <limit lower="-0.157" upper="0.829" effort="100" velocity="100"/>
   </joint>
   <joint type="fixed" name="root2middle_pp_virt_offset">
      <parent link="root2middle_pp_virt_jointbody"/>
      <child link="middle_pp_virt"/>
      <origin xyz="-0.0 -0.0 -0.0" rpy="0.0 0.0 0.0"/>
   </joint>
   <link name="middle_pp">
      <inertial>
         <origin xyz="0.00011637335936397564 -0.001818208065259735 0.010822209549121282" rpy="0.0018869935921097536 0.038976549934939486 1.5584299043450622"/>
         <mass value="0.007546046440107924"/>
         <inertia ixx="9.56353434554292e-07" iyy="9.274116917842254e-07" izz="1.7176054342320975e-07" ixy="0" ixz="0" iyz="0"/>
      </inertial>
      <visual name="middle_pp">
         <origin xyz="0.00011637335936397564 -0.001818208065259735 0.010822209549121282" rpy="0.0018869935921097536 0.038976549934939486 1.5584299043450622"/>
         <geometry>
            <mesh filename="package://viz/models/titans_hand/urdf/converted_mesh/converted_middle_pp.stl"/>
         </geometry>
         <material name="white"/>
      </visual>
   </link>
   <link name="root2middle_pp_jointbody">
      <inertial>
         <origin xyz="0.0 0.0 0.0" rpy="0.0 0.0 0.0"/>
         <mass value="0.001"/>
         <inertia ixx="1e-09" iyy="1e-09" izz="1e-09" ixy="0" ixz="0" iyz="0"/>
      </inertial>
   </link>
   <joint type="revolute" name="root2middle_pp">
      <parent link="middle_pp_virt"/>
      <child link="root2middle_pp_jointbody"/>
      <origin xyz="0.0 -0.00015683 0.01722519" rpy="0.0 0.0 0.0"/>
      <axis xyz="1.0 0.0 0.0"/>
      <limit lower="-0.157" upper="0.829" effort="100" velocity="100"/>
   </joint>
   <joint type="fixed" name="root2middle_pp_offset">
      <parent link="root2middle_pp_jointbody"/>
      <child link="middle_pp"/>
      <origin xyz="-0.0 -0.0 -0.0" rpy="0.0 0.0 0.0"/>
   </joint>
   <link name="middle_pp_sens">
      <inertial>
         <origin xyz="0.0 0.0 0.0" rpy="0.0 0.0 0.0"/>
         <mass value="0.0"/>
         <inertia ixx="0.0" iyy="0.0" izz="0.0" ixy="0" ixz="0" iyz="0"/>
      </inertial>
   </link>
   <link name="middle_pp2middle_pp_sens_fixed_jointbody">
      <inertial>
         <origin xyz="0.0 0.0 0.0" rpy="0.0 0.0 0.0"/>
         <mass value="0.001"/>
         <inertia ixx="1e-09" iyy="1e-09" izz="1e-09" ixy="0" ixz="0" iyz="0"/>
      </inertial>
   </link>
   <joint type="fixed" name="middle_pp2middle_pp_sens_fixed">
      <parent link="middle_pp"/>
      <child link="middle_pp2middle_pp_sens_fixed_jointbody"/>
      <origin xyz="0.0 0.0 0.0" rpy="0.0 0.0 0.0"/>
   </joint>
   <joint type="fixed" name="middle_pp2middle_pp_sens_fixed_offset">
      <parent link="middle_pp2middle_pp_sens_fixed_jointbody"/>
      <child link="middle_pp_sens"/>
      <origin xyz="-0.0 -0.0 -0.0" rpy="0.0 0.0 0.0"/>
   </joint>
   <link name="middle_mp_virt">
      <inertial>
         <origin xyz="0.0 0.0 0.0" rpy="0.0 0.0 0.0"/>
         <mass value="0.001"/>
         <inertia ixx="4e-10" iyy="4e-10" izz="3e-10" ixy="0" ixz="0" iyz="0"/>
      </inertial>
   </link>
   <link name="middle_pp2mp_virt_jointbody">
      <inertial>
         <origin xyz="0.0 0.0 0.0" rpy="0.0 0.0 0.0"/>
         <mass value="0.001"/>
         <inertia ixx="1e-09" iyy="1e-09" izz="1e-09" ixy="0" ixz="0" iyz="0"/>
      </inertial>
   </link>
   <joint type="revolute" name="middle_pp2mp_virt">
      <parent link="middle_pp"/>
      <child link="middle_pp2mp_virt_jointbody"/>
      <origin xyz="0.0 0.00057641 0.02611802" rpy="0.0 0.0 0.0"/>
      <axis xyz="1.0 0.0 0.0"/>
      <limit lower="-0.131" upper="0.96" effort="100" velocity="100"/>
   </joint>
   <joint type="fixed" name="middle_pp2mp_virt_offset">
      <parent link="middle_pp2mp_virt_jointbody"/>
      <child link="middle_mp_virt"/>
      <origin xyz="-0.0 -0.0 -0.0" rpy="0.0 0.0 0.0"/>
   </joint>
   <link name="middle_mp">
      <inertial>
         <origin xyz="0.00029668965848413434 -0.0011315360700857534 0.007590131503944136" rpy="0.0056787978904592196 0.009123149673579745 1.5738823026622906"/>
         <mass value="0.0036096163027472743"/>
         <inertia ixx="2.3670857595223327e-07" iyy="2.0588776340491657e-07" izz="6.81524873648359e-08" ixy="0" ixz="0" iyz="0"/>
      </inertial>
      <visual name="middle_mp">
         <origin xyz="0.00029668965848413434 -0.0011315360700857534 0.007590131503944136" rpy="0.0056787978904592196 0.009123149673579745 1.573882302662291"/>
         <geometry>
            <mesh filename="package://viz/models/titans_hand/urdf/converted_mesh/converted_middle_mp.stl"/>
         </geometry>
         <material name="white"/>
      </visual>
   </link>
   <link name="middle_pp2mp_jointbody">
      <inertial>
         <origin xyz="0.0 0.0 0.0" rpy="0.0 0.0 0.0"/>
         <mass value="0.001"/>
         <inertia ixx="1e-09" iyy="1e-09" izz="1e-09" ixy="0" ixz="0" iyz="0"/>
      </inertial>
   </link>
   <joint type="revolute" name="middle_pp2mp">
      <parent link="middle_mp_virt"/>
      <child link="middle_pp2mp_jointbody"/>
      <origin xyz="0.0 -0.00080968 0.01104305" rpy="0.0 0.0 0.0"/>
      <axis xyz="1.0 0.0 0.0"/>
      <limit lower="-0.131" upper="0.96" effort="100" velocity="100"/>
   </joint>
   <joint type="fixed" name="middle_pp2mp_offset">
      <parent link="middle_pp2mp_jointbody"/>
      <child link="middle_mp"/>
      <origin xyz="-0.0 -0.0 -0.0" rpy="0.0 0.0 0.0"/>
   </joint>
   <link name="middle_dp_virt">
      <inertial>
         <origin xyz="0.0 0.0 -0.1" rpy="0.0 0.0 0.0"/>
         <mass value="0.001"/>
         <inertia ixx="4e-10" iyy="4e-10" izz="3e-10" ixy="0" ixz="0" iyz="0"/>
      </inertial>
   </link>
   <link name="middle_mp2dp_virt_jointbody">
      <inertial>
         <origin xyz="0.0 0.0 0.0" rpy="0.0 0.0 0.0"/>
         <mass value="0.001"/>
         <inertia ixx="1e-09" iyy="1e-09" izz="1e-09" ixy="0" ixz="0" iyz="0"/>
      </inertial>
   </link>
   <joint type="revolute" name="middle_mp2dp_virt">
      <parent link="middle_mp"/>
      <child link="middle_mp2dp_virt_jointbody"/>
      <origin xyz="0.0 -0.00027599 0.01697596" rpy="0.0 0.0 0.0"/>
      <axis xyz="1.0 0.0 0.0"/>
      <limit lower="-0.093" upper="0.682" effort="100" velocity="100"/>
   </joint>
   <joint type="fixed" name="middle_mp2dp_virt_offset">
      <parent link="middle_mp2dp_virt_jointbody"/>
      <child link="middle_dp_virt"/>
      <origin xyz="-0.0 -0.0 -0.0" rpy="0.0 0.0 0.0"/>
   </joint>
   <link name="middle_dp">
      <inertial>
         <origin xyz="0.0004080281600351707 -0.0001609196067209539 0.004366833298723782" rpy="0.005320230753060984 0.04639366291748903 1.5713315351794575"/>
         <mass value="0.0014065189005047724"/>
         <inertia ixx="7.15765063531471e-08" iyy="6.265685623199896e-08" izz="1.6891661140100088e-08" ixy="0" ixz="0" iyz="0"/>
      </inertial>
      <visual name="middle_dp">
         <origin xyz="0.0004080281600351707 -0.0001609196067209539 0.004366833298723782" rpy="0.005320230753060984 0.04639366291748925 1.571331535179458"/>
         <geometry>
            <mesh filename="package://viz/models/titans_hand/urdf/converted_mesh/converted_middle_dp.stl"/>
         </geometry>
         <material name="white"/>
      </visual>
   </link>
   <link name="middle_mp2dp_jointbody">
      <inertial>
         <origin xyz="0.0 0.0 0.0" rpy="0.0 0.0 0.0"/>
         <mass value="0.001"/>
         <inertia ixx="1e-09" iyy="1e-09" izz="1e-09" ixy="0" ixz="0" iyz="0"/>
      </inertial>
   </link>
   <joint type="revolute" name="middle_mp2dp">
      <parent link="middle_dp_virt"/>
      <child link="middle_mp2dp_jointbody"/>
      <origin xyz="0.0 -0.00083781 0.00827539" rpy="0.0 0.0 0.0"/>
      <axis xyz="1.0 0.0 0.0"/>
      <limit lower="-0.093" upper="0.682" effort="100" velocity="100"/>
   </joint>
   <joint type="fixed" name="middle_mp2dp_offset">
      <parent link="middle_mp2dp_jointbody"/>
      <child link="middle_dp"/>
      <origin xyz="-0.0 -0.0 -0.0" rpy="0.0 0.0 0.0"/>
   </joint>
   <link name="middle_fingertip">
      <inertial>
         <origin xyz="0.0 0.0 0.01309" rpy="0.0 0.0 0.0"/>
         <mass value="0.0"/>
         <inertia ixx="0.0" iyy="0.0" izz="0.0" ixy="0" ixz="0" iyz="0"/>
      </inertial>
   </link>
   <link name="middle_dp2middle_fingertip_fixed_jointbody">
      <inertial>
         <origin xyz="0.0 0.0 0.0" rpy="0.0 0.0 0.0"/>
         <mass value="0.001"/>
         <inertia ixx="1e-09" iyy="1e-09" izz="1e-09" ixy="0" ixz="0" iyz="0"/>
      </inertial>
   </link>
   <joint type="fixed" name="middle_dp2middle_fingertip_fixed">
      <parent link="middle_dp"/>
      <child link="middle_dp2middle_fingertip_fixed_jointbody"/>
      <origin xyz="0.0 0.0 0.01309" rpy="0.0 0.0 0.0"/>
   </joint>
   <joint type="fixed" name="middle_dp2middle_fingertip_fixed_offset">
      <parent link="middle_dp2middle_fingertip_fixed_jointbody"/>
      <child link="middle_fingertip"/>
      <origin xyz="-0.0 -0.0 -0.0" rpy="0.0 0.0 0.0"/>
   </joint>
   <link name="ring_base">
      <inertial>
         <origin xyz="-1.3760015381432599e-06 0.0001725668069039066 0.004475784071478828" rpy="-0.001820563394911212 0.2840263082023218 1.5629472627759466"/>
         <mass value="0.00362069274308756"/>
         <inertia ixx="1.660759019712417e-07" iyy="1.58396401779484e-07" izz="8.57537012752121e-08" ixy="0" ixz="0" iyz="0"/>
      </inertial>
      <visual name="ring_base">
         <origin xyz="-1.3760015381432599e-06 0.0001725668069039066 0.004475784071478828" rpy="-0.001820563394911212 0.2840263082023218 1.5629472627759466"/>
         <geometry>
            <mesh filename="package://viz/models/titans_hand/urdf/converted_mesh/converted_ring_base.stl"/>
         </geometry>
         <material name="white"/>
      </visual>
   </link>
   <link name="palm2ring_base_fixed_jointbody">
      <inertial>
         <origin xyz="0.0 0.0 0.0" rpy="0.0 0.0 0.0"/>
         <mass value="0.001"/>
         <inertia ixx="1e-09" iyy="1e-09" izz="1e-09" ixy="0" ixz="0" iyz="0"/>
      </inertial>
   </link>
   <joint type="fixed" name="palm2ring_base_fixed">
      <parent link="palm"/>
      <child link="palm2ring_base_fixed_jointbody"/>
      <origin xyz="0.002691840889 -0.002 0.056250672" rpy="0.0 -0.34906585040000015 0.0"/>
   </joint>
   <joint type="fixed" name="palm2ring_base_fixed_offset">
      <parent link="palm2ring_base_fixed_jointbody"/>
      <child link="ring_base"/>
      <origin xyz="-0.0 -0.0 -0.0" rpy="0.0 0.0 0.0"/>
   </joint>
   <link name="ring_um_virt">
      <inertial>
         <origin xyz="0.0 0.0 0.0" rpy="0.0 0.0 0.0"/>
         <mass value="0.001"/>
         <inertia ixx="4e-10" iyy="4e-10" izz="3e-10" ixy="0" ixz="0" iyz="0"/>
      </inertial>
   </link>
   <link name="ring_abd_virt_jointbody">
      <inertial>
         <origin xyz="0.0 0.0 0.0" rpy="0.0 0.0 0.0"/>
         <mass value="0.001"/>
         <inertia ixx="1e-09" iyy="1e-09" izz="1e-09" ixy="0" ixz="0" iyz="0"/>
      </inertial>
   </link>
   <joint type="revolute" name="ring_abd_virt">
      <parent link="ring_base"/>
      <child link="ring_abd_virt_jointbody"/>
      <origin xyz="0.0 0.0 0.00527505" rpy="0.0 0.0 0.0"/>
      <axis xyz="0.0 1.0 0.0"/>
      <limit lower="-0.264" upper="0.264" effort="100" velocity="100"/>
   </joint>
   <joint type="fixed" name="ring_abd_virt_offset">
      <parent link="ring_abd_virt_jointbody"/>
      <child link="ring_um_virt"/>
      <origin xyz="-0.0 -0.0 -0.0" rpy="0.0 0.0 0.0"/>
   </joint>
   <link name="ring_um">
      <inertial>
         <origin xyz="1.7370519164770844e-05 0.0012715146657108968 -0.0031260415189963524" rpy="3.120877986607322 -1.1804296781579997 -1.5514785003273175"/>
         <mass value="0.0020507778801623494"/>
         <inertia ixx="5.3021061398745245e-08" iyy="4.456771195857276e-08" izz="4.1862251466191607e-08" ixy="0" ixz="0" iyz="0"/>
      </inertial>
      <visual name="ring_um">
         <origin xyz="1.7370519164770844e-05 0.0012715146657108968 -0.0031260415189963524" rpy="3.120877986607322 -1.1804296781579997 -1.5514785003273168"/>
         <geometry>
            <mesh filename="package://viz/models/titans_hand/urdf/converted_mesh/converted_ring_um.stl"/>
         </geometry>
         <material name="white"/>
      </visual>
   </link>
   <link name="ring_abd_jointbody">
      <inertial>
         <origin xyz="0.0 0.0 0.0" rpy="0.0 0.0 0.0"/>
         <mass value="0.001"/>
         <inertia ixx="1e-09" iyy="1e-09" izz="1e-09" ixy="0" ixz="0" iyz="0"/>
      </inertial>
   </link>
   <joint type="revolute" name="ring_abd">
      <parent link="ring_um_virt"/>
      <child link="ring_abd_jointbody"/>
      <origin xyz="0.0 0.0 0.01789991" rpy="0.0 0.0 0.0"/>
      <axis xyz="0.0 1.0 0.0"/>
      <limit lower="-0.264" upper="0.264" effort="100" velocity="100"/>
   </joint>
   <joint type="fixed" name="ring_abd_offset">
      <parent link="ring_abd_jointbody"/>
      <child link="ring_um"/>
      <origin xyz="-0.0 -0.0 -0.0" rpy="0.0 0.0 0.0"/>
   </joint>
   <link name="ring_pp_virt">
      <inertial>
         <origin xyz="0.0 0.0 0.0" rpy="0.0 0.0 0.0"/>
         <mass value="0.001"/>
         <inertia ixx="4e-10" iyy="4e-10" izz="3e-10" ixy="0" ixz="0" iyz="0"/>
      </inertial>
   </link>
   <link name="root2ring_pp_virt_jointbody">
      <inertial>
         <origin xyz="0.0 0.0 0.0" rpy="0.0 0.0 0.0"/>
         <mass value="0.001"/>
         <inertia ixx="1e-09" iyy="1e-09" izz="1e-09" ixy="0" ixz="0" iyz="0"/>
      </inertial>
   </link>
   <joint type="revolute" name="root2ring_pp_virt">
      <parent link="ring_um"/>
      <child link="root2ring_pp_virt_jointbody"/>
      <origin xyz="0.0 0.0033 -0.00625608" rpy="0.0 0.0 0.0"/>
      <axis xyz="1.0 0.0 0.0"/>
      <limit lower="-0.157" upper="0.829" effort="100" velocity="100"/>
   </joint>
   <joint type="fixed" name="root2ring_pp_virt_offset">
      <parent link="root2ring_pp_virt_jointbody"/>
      <child link="ring_pp_virt"/>
      <origin xyz="-0.0 -0.0 -0.0" rpy="0.0 0.0 0.0"/>
   </joint>
   <link name="ring_pp">
      <inertial>
         <origin xyz="0.00011637335936397564 -0.001818208065259735 0.010822209549121282" rpy="0.0018869935921097536 0.038976549934939486 1.5584299043450622"/>
         <mass value="0.007546046440107924"/>
         <inertia ixx="9.56353434554292e-07" iyy="9.274116917842254e-07" izz="1.7176054342320975e-07" ixy="0" ixz="0" iyz="0"/>
      </inertial>
      <visual name="ring_pp">
         <origin xyz="0.00011637335936397564 -0.001818208065259735 0.010822209549121282" rpy="0.0018869935921097536 0.038976549934939486 1.5584299043450622"/>
         <geometry>
            <mesh filename="package://viz/models/titans_hand/urdf/converted_mesh/converted_ring_pp.stl"/>
         </geometry>
         <material name="white"/>
      </visual>
   </link>
   <link name="root2ring_pp_jointbody">
      <inertial>
         <origin xyz="0.0 0.0 0.0" rpy="0.0 0.0 0.0"/>
         <mass value="0.001"/>
         <inertia ixx="1e-09" iyy="1e-09" izz="1e-09" ixy="0" ixz="0" iyz="0"/>
      </inertial>
   </link>
   <joint type="revolute" name="root2ring_pp">
      <parent link="ring_pp_virt"/>
      <child link="root2ring_pp_jointbody"/>
      <origin xyz="0.0 -0.00015683 0.01722519" rpy="0.0 0.0 0.0"/>
      <axis xyz="1.0 0.0 0.0"/>
      <limit lower="-0.157" upper="0.829" effort="100" velocity="100"/>
   </joint>
   <joint type="fixed" name="root2ring_pp_offset">
      <parent link="root2ring_pp_jointbody"/>
      <child link="ring_pp"/>
      <origin xyz="-0.0 -0.0 -0.0" rpy="0.0 0.0 0.0"/>
   </joint>
   <link name="ring_pp_sens">
      <inertial>
         <origin xyz="0.0 0.0 0.0" rpy="0.0 0.0 0.0"/>
         <mass value="0.0"/>
         <inertia ixx="0.0" iyy="0.0" izz="0.0" ixy="0" ixz="0" iyz="0"/>
      </inertial>
   </link>
   <link name="ring_pp2ring_pp_sens_fixed_jointbody">
      <inertial>
         <origin xyz="0.0 0.0 0.0" rpy="0.0 0.0 0.0"/>
         <mass value="0.001"/>
         <inertia ixx="1e-09" iyy="1e-09" izz="1e-09" ixy="0" ixz="0" iyz="0"/>
      </inertial>
   </link>
   <joint type="fixed" name="ring_pp2ring_pp_sens_fixed">
      <parent link="ring_pp"/>
      <child link="ring_pp2ring_pp_sens_fixed_jointbody"/>
      <origin xyz="0.0 0.0 0.0" rpy="0.0 0.0 0.0"/>
   </joint>
   <joint type="fixed" name="ring_pp2ring_pp_sens_fixed_offset">
      <parent link="ring_pp2ring_pp_sens_fixed_jointbody"/>
      <child link="ring_pp_sens"/>
      <origin xyz="-0.0 -0.0 -0.0" rpy="0.0 0.0 0.0"/>
   </joint>
   <link name="ring_mp_virt">
      <inertial>
         <origin xyz="0.0 0.0 0.0" rpy="0.0 0.0 0.0"/>
         <mass value="0.001"/>
         <inertia ixx="4e-10" iyy="4e-10" izz="3e-10" ixy="0" ixz="0" iyz="0"/>
      </inertial>
   </link>
   <link name="ring_pp2mp_virt_jointbody">
      <inertial>
         <origin xyz="0.0 0.0 0.0" rpy="0.0 0.0 0.0"/>
         <mass value="0.001"/>
         <inertia ixx="1e-09" iyy="1e-09" izz="1e-09" ixy="0" ixz="0" iyz="0"/>
      </inertial>
   </link>
   <joint type="revolute" name="ring_pp2mp_virt">
      <parent link="ring_pp"/>
      <child link="ring_pp2mp_virt_jointbody"/>
      <origin xyz="0.0 0.00057641 0.02611802" rpy="0.0 0.0 0.0"/>
      <axis xyz="1.0 0.0 0.0"/>
      <limit lower="-0.131" upper="0.96" effort="100" velocity="100"/>
   </joint>
   <joint type="fixed" name="ring_pp2mp_virt_offset">
      <parent link="ring_pp2mp_virt_jointbody"/>
      <child link="ring_mp_virt"/>
      <origin xyz="-0.0 -0.0 -0.0" rpy="0.0 0.0 0.0"/>
   </joint>
   <link name="ring_mp">
      <inertial>
         <origin xyz="0.00029668965848413434 -0.0011315360700857534 0.007590131503944136" rpy="0.0056787978904592196 0.009123149673579745 1.5738823026622906"/>
         <mass value="0.0036096163027472743"/>
         <inertia ixx="2.3670857595223327e-07" iyy="2.0588776340491657e-07" izz="6.81524873648359e-08" ixy="0" ixz="0" iyz="0"/>
      </inertial>
      <visual name="ring_mp">
         <origin xyz="0.00029668965848413434 -0.0011315360700857534 0.007590131503944136" rpy="0.0056787978904592196 0.009123149673579745 1.573882302662291"/>
         <geometry>
            <mesh filename="package://viz/models/titans_hand/urdf/converted_mesh/converted_ring_mp.stl"/>
         </geometry>
         <material name="white"/>
      </visual>
   </link>
   <link name="ring_pp2mp_jointbody">
      <inertial>
         <origin xyz="0.0 0.0 0.0" rpy="0.0 0.0 0.0"/>
         <mass value="0.001"/>
         <inertia ixx="1e-09" iyy="1e-09" izz="1e-09" ixy="0" ixz="0" iyz="0"/>
      </inertial>
   </link>
   <joint type="revolute" name="ring_pp2mp">
      <parent link="ring_mp_virt"/>
      <child link="ring_pp2mp_jointbody"/>
      <origin xyz="0.0 -0.00080968 0.01104305" rpy="0.0 0.0 0.0"/>
      <axis xyz="1.0 0.0 0.0"/>
      <limit lower="-0.131" upper="0.96" effort="100" velocity="100"/>
   </joint>
   <joint type="fixed" name="ring_pp2mp_offset">
      <parent link="ring_pp2mp_jointbody"/>
      <child link="ring_mp"/>
      <origin xyz="-0.0 -0.0 -0.0" rpy="0.0 0.0 0.0"/>
   </joint>
   <link name="ring_dp_virt">
      <inertial>
         <origin xyz="0.0 0.0 0.01" rpy="0.0 0.0 0.0"/>
         <mass value="0.001"/>
         <inertia ixx="4e-10" iyy="4e-10" izz="3e-10" ixy="0" ixz="0" iyz="0"/>
      </inertial>
   </link>
   <link name="ring_mp2dp_virt_jointbody">
      <inertial>
         <origin xyz="0.0 0.0 0.0" rpy="0.0 0.0 0.0"/>
         <mass value="0.001"/>
         <inertia ixx="1e-09" iyy="1e-09" izz="1e-09" ixy="0" ixz="0" iyz="0"/>
      </inertial>
   </link>
   <joint type="revolute" name="ring_mp2dp_virt">
      <parent link="ring_mp"/>
      <child link="ring_mp2dp_virt_jointbody"/>
      <origin xyz="0.0 -0.00027599 0.01697596" rpy="0.0 0.0 0.0"/>
      <axis xyz="1.0 0.0 0.0"/>
      <limit lower="-0.093" upper="0.682" effort="100" velocity="100"/>
   </joint>
   <joint type="fixed" name="ring_mp2dp_virt_offset">
      <parent link="ring_mp2dp_virt_jointbody"/>
      <child link="ring_dp_virt"/>
      <origin xyz="-0.0 -0.0 -0.0" rpy="0.0 0.0 0.0"/>
   </joint>
   <link name="ring_dp">
      <inertial>
         <origin xyz="0.0004080281600351707 -0.0001609196067209539 0.004366833298723782" rpy="0.005320230753060984 0.04639366291748903 1.5713315351794575"/>
         <mass value="0.0014065189005047724"/>
         <inertia ixx="7.15765063531471e-08" iyy="6.265685623199896e-08" izz="1.6891661140100088e-08" ixy="0" ixz="0" iyz="0"/>
      </inertial>
      <visual name="ring_dp">
         <origin xyz="0.0004080281600351707 -0.0001609196067209539 0.004366833298723782" rpy="0.005320230753060984 0.04639366291748925 1.571331535179458"/>
         <geometry>
            <mesh filename="package://viz/models/titans_hand/urdf/converted_mesh/converted_ring_dp.stl"/>
         </geometry>
         <material name="white"/>
      </visual>
   </link>
   <link name="ring_mp2dp_jointbody">
      <inertial>
         <origin xyz="0.0 0.0 0.0" rpy="0.0 0.0 0.0"/>
         <mass value="0.001"/>
         <inertia ixx="1e-09" iyy="1e-09" izz="1e-09" ixy="0" ixz="0" iyz="0"/>
      </inertial>
   </link>
   <joint type="revolute" name="ring_mp2dp">
      <parent link="ring_dp_virt"/>
      <child link="ring_mp2dp_jointbody"/>
      <origin xyz="0.0 -0.00083781 0.00827539" rpy="0.0 0.0 0.0"/>
      <axis xyz="1.0 0.0 0.0"/>
      <limit lower="-0.093" upper="0.682" effort="100" velocity="100"/>
   </joint>
   <joint type="fixed" name="ring_mp2dp_offset">
      <parent link="ring_mp2dp_jointbody"/>
      <child link="ring_dp"/>
      <origin xyz="-0.0 -0.0 -0.0" rpy="0.0 0.0 0.0"/>
   </joint>
   <link name="ring_fingertip">
      <inertial>
         <origin xyz="0.0 0.0 0.01309" rpy="0.0 0.0 0.0"/>
         <mass value="0.0"/>
         <inertia ixx="0.0" iyy="0.0" izz="0.0" ixy="0" ixz="0" iyz="0"/>
      </inertial>
   </link>
   <link name="ring_dp2ring_fingertip_fixed_jointbody">
      <inertial>
         <origin xyz="0.0 0.0 0.0" rpy="0.0 0.0 0.0"/>
         <mass value="0.001"/>
         <inertia ixx="1e-09" iyy="1e-09" izz="1e-09" ixy="0" ixz="0" iyz="0"/>
      </inertial>
   </link>
   <joint type="fixed" name="ring_dp2ring_fingertip_fixed">
      <parent link="ring_dp"/>
      <child link="ring_dp2ring_fingertip_fixed_jointbody"/>
      <origin xyz="0.0 0.0 0.01309" rpy="0.0 0.0 0.0"/>
   </joint>
   <joint type="fixed" name="ring_dp2ring_fingertip_fixed_offset">
      <parent link="ring_dp2ring_fingertip_fixed_jointbody"/>
      <child link="ring_fingertip"/>
      <origin xyz="-0.0 -0.0 -0.0" rpy="0.0 0.0 0.0"/>
   </joint>
   <link name="pinky_base">
      <inertial>
         <origin xyz="-1.3760015381432599e-06 0.0001725668069039066 0.004475784071478828" rpy="-0.001820563394911212 0.2840263082023218 1.5629472627759466"/>
         <mass value="0.00362069274308756"/>
         <inertia ixx="1.660759019712417e-07" iyy="1.58396401779484e-07" izz="8.57537012752121e-08" ixy="0" ixz="0" iyz="0"/>
      </inertial>
      <visual name="pinky_base">
         <origin xyz="-1.3760015381432599e-06 0.0001725668069039066 0.004475784071478828" rpy="-0.001820563394911212 0.2840263082023218 1.5629472627759466"/>
         <geometry>
            <mesh filename="package://viz/models/titans_hand/urdf/converted_mesh/converted_pinky_base.stl"/>
         </geometry>
         <material name="white"/>
      </visual>
   </link>
   <link name="palm2pinky_base_fixed_jointbody">
      <inertial>
         <origin xyz="0.0 0.0 0.0" rpy="0.0 0.0 0.0"/>
         <mass value="0.001"/>
         <inertia ixx="1e-09" iyy="1e-09" izz="1e-09" ixy="0" ixz="0" iyz="0"/>
      </inertial>
   </link>
   <joint type="fixed" name="palm2pinky_base_fixed">
      <parent link="palm"/>
      <child link="palm2pinky_base_fixed_jointbody"/>
      <origin xyz="-0.01537994548 -0.002 0.048767481" rpy="0.0 -0.4363323130000001 0.0"/>
   </joint>
   <joint type="fixed" name="palm2pinky_base_fixed_offset">
      <parent link="palm2pinky_base_fixed_jointbody"/>
      <child link="pinky_base"/>
      <origin xyz="-0.0 -0.0 -0.0" rpy="0.0 0.0 0.0"/>
   </joint>
   <link name="pinky_um_virt">
      <inertial>
         <origin xyz="0.0 0.0 0.0" rpy="0.0 0.0 0.0"/>
         <mass value="0.001"/>
         <inertia ixx="4e-10" iyy="4e-10" izz="3e-10" ixy="0" ixz="0" iyz="0"/>
      </inertial>
   </link>
   <link name="pinky_abd_virt_jointbody">
      <inertial>
         <origin xyz="0.0 0.0 0.0" rpy="0.0 0.0 0.0"/>
         <mass value="0.001"/>
         <inertia ixx="1e-09" iyy="1e-09" izz="1e-09" ixy="0" ixz="0" iyz="0"/>
      </inertial>
   </link>
   <joint type="revolute" name="pinky_abd_virt">
      <parent link="pinky_base"/>
      <child link="pinky_abd_virt_jointbody"/>
      <origin xyz="0.0 0.0 0.00527505" rpy="0.0 0.0 0.0"/>
      <axis xyz="0.0 1.0 0.0"/>
      <limit lower="-0.264" upper="0.264" effort="100" velocity="100"/>
   </joint>
   <joint type="fixed" name="pinky_abd_virt_offset">
      <parent link="pinky_abd_virt_jointbody"/>
      <child link="pinky_um_virt"/>
      <origin xyz="-0.0 -0.0 -0.0" rpy="0.0 0.0 0.0"/>
   </joint>
   <link name="pinky_um">
      <inertial>
         <origin xyz="1.7370519164770844e-05 0.0012715146657108968 -0.0031260415189963524" rpy="3.120877986607322 -1.1804296781579997 -1.5514785003273175"/>
         <mass value="0.0020507778801623494"/>
         <inertia ixx="5.3021061398745245e-08" iyy="4.456771195857276e-08" izz="4.1862251466191607e-08" ixy="0" ixz="0" iyz="0"/>
      </inertial>
      <visual name="pinky_um">
         <origin xyz="1.7370519164770844e-05 0.0012715146657108968 -0.0031260415189963524" rpy="3.120877986607322 -1.1804296781579997 -1.5514785003273168"/>
         <geometry>
            <mesh filename="package://viz/models/titans_hand/urdf/converted_mesh/converted_pinky_um.stl"/>
         </geometry>
         <material name="white"/>
      </visual>
   </link>
   <link name="pinky_abd_jointbody">
      <inertial>
         <origin xyz="0.0 0.0 0.0" rpy="0.0 0.0 0.0"/>
         <mass value="0.001"/>
         <inertia ixx="1e-09" iyy="1e-09" izz="1e-09" ixy="0" ixz="0" iyz="0"/>
      </inertial>
   </link>
   <joint type="revolute" name="pinky_abd">
      <parent link="pinky_um_virt"/>
      <child link="pinky_abd_jointbody"/>
      <origin xyz="0.0 0.0 0.01789991" rpy="0.0 0.0 0.0"/>
      <axis xyz="0.0 1.0 0.0"/>
      <limit lower="-0.264" upper="0.264" effort="100" velocity="100"/>
   </joint>
   <joint type="fixed" name="pinky_abd_offset">
      <parent link="pinky_abd_jointbody"/>
      <child link="pinky_um"/>
      <origin xyz="-0.0 -0.0 -0.0" rpy="0.0 0.0 0.0"/>
   </joint>
   <link name="pinky_pp_virt">
      <inertial>
         <origin xyz="0.0 0.0 0.0" rpy="0.0 0.0 0.0"/>
         <mass value="0.001"/>
         <inertia ixx="4e-10" iyy="4e-10" izz="3e-10" ixy="0" ixz="0" iyz="0"/>
      </inertial>
   </link>
   <link name="root2pinky_pp_virt_jointbody">
      <inertial>
         <origin xyz="0.0 0.0 0.0" rpy="0.0 0.0 0.0"/>
         <mass value="0.001"/>
         <inertia ixx="1e-09" iyy="1e-09" izz="1e-09" ixy="0" ixz="0" iyz="0"/>
      </inertial>
   </link>
   <joint type="revolute" name="root2pinky_pp_virt">
      <parent link="pinky_um"/>
      <child link="root2pinky_pp_virt_jointbody"/>
      <origin xyz="0.0 0.0033 -0.00625608" rpy="0.0 0.0 0.0"/>
      <axis xyz="1.0 0.0 0.0"/>
      <limit lower="-0.157" upper="0.829" effort="100" velocity="100"/>
   </joint>
   <joint type="fixed" name="root2pinky_pp_virt_offset">
      <parent link="root2pinky_pp_virt_jointbody"/>
      <child link="pinky_pp_virt"/>
      <origin xyz="-0.0 -0.0 -0.0" rpy="0.0 0.0 0.0"/>
   </joint>
   <link name="pinky_pp">
      <inertial>
         <origin xyz="0.00011637335936397564 -0.001818208065259735 0.010822209549121282" rpy="0.0018869935921097536 0.038976549934939486 1.5584299043450622"/>
         <mass value="0.007546046440107924"/>
         <inertia ixx="9.56353434554292e-07" iyy="9.274116917842254e-07" izz="1.7176054342320975e-07" ixy="0" ixz="0" iyz="0"/>
      </inertial>
      <visual name="pinky_pp">
         <origin xyz="0.00011637335936397564 -0.001818208065259735 0.010822209549121282" rpy="0.0018869935921097536 0.038976549934939486 1.5584299043450622"/>
         <geometry>
            <mesh filename="package://viz/models/titans_hand/urdf/converted_mesh/converted_pinky_pp.stl"/>
         </geometry>
         <material name="white"/>
      </visual>
   </link>
   <link name="root2pinky_pp_jointbody">
      <inertial>
         <origin xyz="0.0 0.0 0.0" rpy="0.0 0.0 0.0"/>
         <mass value="0.001"/>
         <inertia ixx="1e-09" iyy="1e-09" izz="1e-09" ixy="0" ixz="0" iyz="0"/>
      </inertial>
   </link>
   <joint type="revolute" name="root2pinky_pp">
      <parent link="pinky_pp_virt"/>
      <child link="root2pinky_pp_jointbody"/>
      <origin xyz="0.0 -0.00015683 0.01722519" rpy="0.0 0.0 0.0"/>
      <axis xyz="1.0 0.0 0.0"/>
      <limit lower="-0.157" upper="0.829" effort="100" velocity="100"/>
   </joint>
   <joint type="fixed" name="root2pinky_pp_offset">
      <parent link="root2pinky_pp_jointbody"/>
      <child link="pinky_pp"/>
      <origin xyz="-0.0 -0.0 -0.0" rpy="0.0 0.0 0.0"/>
   </joint>
   <link name="pinky_pp_sens">
      <inertial>
         <origin xyz="0.0 0.0 0.0" rpy="0.0 0.0 0.0"/>
         <mass value="0.0"/>
         <inertia ixx="0.0" iyy="0.0" izz="0.0" ixy="0" ixz="0" iyz="0"/>
      </inertial>
   </link>
   <link name="pinky_pp2pinky_pp_sens_fixed_jointbody">
      <inertial>
         <origin xyz="0.0 0.0 0.0" rpy="0.0 0.0 0.0"/>
         <mass value="0.001"/>
         <inertia ixx="1e-09" iyy="1e-09" izz="1e-09" ixy="0" ixz="0" iyz="0"/>
      </inertial>
   </link>
   <joint type="fixed" name="pinky_pp2pinky_pp_sens_fixed">
      <parent link="pinky_pp"/>
      <child link="pinky_pp2pinky_pp_sens_fixed_jointbody"/>
      <origin xyz="0.0 0.0 0.0" rpy="0.0 0.0 0.0"/>
   </joint>
   <joint type="fixed" name="pinky_pp2pinky_pp_sens_fixed_offset">
      <parent link="pinky_pp2pinky_pp_sens_fixed_jointbody"/>
      <child link="pinky_pp_sens"/>
      <origin xyz="-0.0 -0.0 -0.0" rpy="0.0 0.0 0.0"/>
   </joint>
   <link name="pinky_mp_virt">
      <inertial>
         <origin xyz="0.0 0.0 0.0" rpy="0.0 0.0 0.0"/>
         <mass value="0.001"/>
         <inertia ixx="4e-10" iyy="4e-10" izz="3e-10" ixy="0" ixz="0" iyz="0"/>
      </inertial>
   </link>
   <link name="pinky_pp2mp_virt_jointbody">
      <inertial>
         <origin xyz="0.0 0.0 0.0" rpy="0.0 0.0 0.0"/>
         <mass value="0.001"/>
         <inertia ixx="1e-09" iyy="1e-09" izz="1e-09" ixy="0" ixz="0" iyz="0"/>
      </inertial>
   </link>
   <joint type="revolute" name="pinky_pp2mp_virt">
      <parent link="pinky_pp"/>
      <child link="pinky_pp2mp_virt_jointbody"/>
      <origin xyz="0.0 0.00057641 0.02611802" rpy="0.0 0.0 0.0"/>
      <axis xyz="1.0 0.0 0.0"/>
      <limit lower="-0.131" upper="0.96" effort="100" velocity="100"/>
   </joint>
   <joint type="fixed" name="pinky_pp2mp_virt_offset">
      <parent link="pinky_pp2mp_virt_jointbody"/>
      <child link="pinky_mp_virt"/>
      <origin xyz="-0.0 -0.0 -0.0" rpy="0.0 0.0 0.0"/>
   </joint>
   <link name="pinky_mp">
      <inertial>
         <origin xyz="0.00029668965848413434 -0.0011315360700857534 0.007590131503944136" rpy="0.0056787978904592196 0.009123149673579745 1.5738823026622906"/>
         <mass value="0.0036096163027472743"/>
         <inertia ixx="2.3670857595223327e-07" iyy="2.0588776340491657e-07" izz="6.81524873648359e-08" ixy="0" ixz="0" iyz="0"/>
      </inertial>
      <visual name="pinky_mp">
         <origin xyz="0.00029668965848413434 -0.0011315360700857534 0.007590131503944136" rpy="0.0056787978904592196 0.009123149673579745 1.573882302662291"/>
         <geometry>
            <mesh filename="package://viz/models/titans_hand/urdf/converted_mesh/converted_pinky_mp.stl"/>
         </geometry>
         <material name="white"/>
      </visual>
   </link>
   <link name="pinky_pp2mp_jointbody">
      <inertial>
         <origin xyz="0.0 0.0 0.0" rpy="0.0 0.0 0.0"/>
         <mass value="0.001"/>
         <inertia ixx="1e-09" iyy="1e-09" izz="1e-09" ixy="0" ixz="0" iyz="0"/>
      </inertial>
   </link>
   <joint type="revolute" name="pinky_pp2mp">
      <parent link="pinky_mp_virt"/>
      <child link="pinky_pp2mp_jointbody"/>
      <origin xyz="0.0 -0.00080968 0.01104305" rpy="0.0 0.0 0.0"/>
      <axis xyz="1.0 0.0 0.0"/>
      <limit lower="-0.131" upper="0.96" effort="100" velocity="100"/>
   </joint>
   <joint type="fixed" name="pinky_pp2mp_offset">
      <parent link="pinky_pp2mp_jointbody"/>
      <child link="pinky_mp"/>
      <origin xyz="-0.0 -0.0 -0.0" rpy="0.0 0.0 0.0"/>
   </joint>
   <link name="pinky_dp_virt">
      <inertial>
         <origin xyz="0.0 0.0 -0.1" rpy="0.0 0.0 0.0"/>
         <mass value="0.001"/>
         <inertia ixx="4e-10" iyy="4e-10" izz="3e-10" ixy="0" ixz="0" iyz="0"/>
      </inertial>
   </link>
   <link name="pinky_mp2dp_virt_jointbody">
      <inertial>
         <origin xyz="0.0 0.0 0.0" rpy="0.0 0.0 0.0"/>
         <mass value="0.001"/>
         <inertia ixx="1e-09" iyy="1e-09" izz="1e-09" ixy="0" ixz="0" iyz="0"/>
      </inertial>
   </link>
   <joint type="revolute" name="pinky_mp2dp_virt">
      <parent link="pinky_mp"/>
      <child link="pinky_mp2dp_virt_jointbody"/>
      <origin xyz="0.0 -0.00027599 0.01697596" rpy="0.0 0.0 0.0"/>
      <axis xyz="1.0 0.0 0.0"/>
      <limit lower="-0.093" upper="0.682" effort="100" velocity="100"/>
   </joint>
   <joint type="fixed" name="pinky_mp2dp_virt_offset">
      <parent link="pinky_mp2dp_virt_jointbody"/>
      <child link="pinky_dp_virt"/>
      <origin xyz="-0.0 -0.0 -0.0" rpy="0.0 0.0 0.0"/>
   </joint>
   <link name="pinky_dp">
      <inertial>
         <origin xyz="0.0004080281600351707 -0.0001609196067209539 0.004366833298723782" rpy="0.005320230753060984 0.04639366291748903 1.5713315351794575"/>
         <mass value="0.0014065189005047724"/>
         <inertia ixx="7.15765063531471e-08" iyy="6.265685623199896e-08" izz="1.6891661140100088e-08" ixy="0" ixz="0" iyz="0"/>
      </inertial>
      <visual name="pinky_dp">
         <origin xyz="0.0004080281600351707 -0.0001609196067209539 0.004366833298723782" rpy="0.005320230753060984 0.04639366291748925 1.571331535179458"/>
         <geometry>
            <mesh filename="package://viz/models/titans_hand/urdf/converted_mesh/converted_pinky_dp.stl"/>
         </geometry>
         <material name="white"/>
      </visual>
   </link>
   <link name="pinky_mp2dp_jointbody">
      <inertial>
         <origin xyz="0.0 0.0 0.0" rpy="0.0 0.0 0.0"/>
         <mass value="0.001"/>
         <inertia ixx="1e-09" iyy="1e-09" izz="1e-09" ixy="0" ixz="0" iyz="0"/>
      </inertial>
   </link>
   <joint type="revolute" name="pinky_mp2dp">
      <parent link="pinky_dp_virt"/>
      <child link="pinky_mp2dp_jointbody"/>
      <origin xyz="0.0 -0.00083781 0.00827539" rpy="0.0 0.0 0.0"/>
      <axis xyz="1.0 0.0 0.0"/>
      <limit lower="-0.093" upper="0.682" effort="100" velocity="100"/>
   </joint>
   <joint type="fixed" name="pinky_mp2dp_offset">
      <parent link="pinky_mp2dp_jointbody"/>
      <child link="pinky_dp"/>
      <origin xyz="-0.0 -0.0 -0.0" rpy="0.0 0.0 0.0"/>
   </joint>
   <link name="pinky_fingertip">
      <inertial>
         <origin xyz="0.0 0.0 0.01309" rpy="0.0 0.0 0.0"/>
         <mass value="0.0"/>
         <inertia ixx="0.0" iyy="0.0" izz="0.0" ixy="0" ixz="0" iyz="0"/>
      </inertial>
   </link>
   <link name="pinky_dp2pinky_fingertip_fixed_jointbody">
      <inertial>
         <origin xyz="0.0 0.0 0.0" rpy="0.0 0.0 0.0"/>
         <mass value="0.001"/>
         <inertia ixx="1e-09" iyy="1e-09" izz="1e-09" ixy="0" ixz="0" iyz="0"/>
      </inertial>
   </link>
   <joint type="fixed" name="pinky_dp2pinky_fingertip_fixed">
      <parent link="pinky_dp"/>
      <child link="pinky_dp2pinky_fingertip_fixed_jointbody"/>
      <origin xyz="0.0 0.0 0.01309" rpy="0.0 0.0 0.0"/>
   </joint>
   <joint type="fixed" name="pinky_dp2pinky_fingertip_fixed_offset">
      <parent link="pinky_dp2pinky_fingertip_fixed_jointbody"/>
      <child link="pinky_fingertip"/>
      <origin xyz="-0.0 -0.0 -0.0" rpy="0.0 0.0 0.0"/>
   </joint>
   <material name="white">
      <color rgba="1 1 1 1"/>
   </material>
</robot>
