<?xml version="1.0" ?>
<robot name="converted_robot">
   <link name="world">
      <inertial>
         <origin xyz="0.0 0.0 0.0" rpy="0.0 0.0 0.0"/>
         <mass value="0.0"/>
         <inertia ixx="0.0" iyy="0.0" izz="0.0" ixy="0" ixz="0" iyz="0"/>
      </inertial>
   </link>
   <link name="base">
      <inertial>
         <origin xyz="-4.8799707564326224e-09 0.005582185568398456 0.010226744006253653" rpy="1.5349507138249 0.0 0.0"/>
         <mass value="0.05900793869016234"/>
         <inertia ixx="4.388975198952572e-05" iyy="4.3634628030527895e-05" izz="8.300150544028685e-06" ixy="0" ixz="0" iyz="0"/>
      </inertial>
      <visual name="connector">
         <origin xyz="-4.8799707564326224e-09 0.005582185568398456 0.010226744006253653" rpy="1.5349507138249 0.0 0.0"/>
         <geometry>
            <mesh filename="package://viz/models/titans_hand/converted_connector.stl"/>
         </geometry>
         <material name="white"/>
      </visual>
   </link>
   <link name="world2base_fixed_jointbody">
      <inertial>
         <origin xyz="0.0 0.0 0.0" rpy="0.0 0.0 0.0"/>
         <mass value="0.001"/>
         <inertia ixx="1e-09" iyy="1e-09" izz="1e-09" ixy="0" ixz="0" iyz="0"/>
      </inertial>
   </link>
   <joint type="fixed" name="world2base_fixed">
      <parent link="world"/>
      <child link="world2base_fixed_jointbody"/>
      <origin xyz="0.0 0.0 0.0" rpy="0.0 0.0 0.0"/>
   </joint>
   <joint type="fixed" name="world2base_fixed_offset">
      <parent link="world2base_fixed_jointbody"/>
      <child link="base"/>
      <origin xyz="-0.0 -0.0 -0.0" rpy="0.0 0.0 0.0"/>
   </joint>
   <link name="hand">
      <inertial>
         <origin xyz="0.000562061327561651 0.00577931980475707 0.0636736226729795" rpy="2.019846101849213 0.0028366571213855885 -0.0012574293312483942"/>
         <mass value="0.12364236097799929"/>
         <inertia ixx="0.00012885090869033678" iyy="8.11084683924915e-05" izz="5.074465474696565e-05" ixy="0" ixz="0" iyz="0"/>
      </inertial>
      <visual name="palm">
         <origin xyz="0.000562061327561651 0.00577931980475707 0.0636736226729795" rpy="2.019846101849213 0.0028366571213855885 -0.0012574293312483942"/>
         <geometry>
            <mesh filename="package://viz/models/titans_hand/converted_palm.stl"/>
         </geometry>
         <material name="white"/>
      </visual>
   </link>
   <link name="revolute_base_hand_jointbody">
      <inertial>
         <origin xyz="0.0 0.0 0.0" rpy="0.0 0.0 0.0"/>
         <mass value="0.001"/>
         <inertia ixx="1e-09" iyy="1e-09" izz="1e-09" ixy="0" ixz="0" iyz="0"/>
      </inertial>
   </link>
   <joint type="revolute" name="revolute_base_hand">
      <parent link="base"/>
      <child link="revolute_base_hand_jointbody"/>
      <origin xyz="0.0 0.0 0.0295" rpy="0.0 0.0 0.0"/>
      <axis xyz="0.0 1.0 0.0"/>
      <limit lower="-1.5707" upper="1.5707" effort="100" velocity="100"/>
   </joint>
   <joint type="fixed" name="revolute_base_hand_offset">
      <parent link="revolute_base_hand_jointbody"/>
      <child link="hand"/>
      <origin xyz="-0.0 -0.0 -0.0295" rpy="0.0 0.0 0.0"/>
   </joint>
   <link name="thumb">
      <inertial>
         <origin xyz="-0.0024321580902199147 0.04547055201202439 0.06594428052585251" rpy="-1.818372072007934 -1.3851142024770866 -2.432251693514906"/>
         <mass value="0.011932463361551614"/>
         <inertia ixx="1.3316220598414493e-06" iyy="1.1875874826751407e-06" izz="8.101648035813821e-07" ixy="0" ixz="0" iyz="0"/>
      </inertial>
      <visual name="thumbHinge">
         <origin xyz="-0.0024321580902199147 0.04547055201202439 0.06594428052585251" rpy="-1.818372072007933 -1.3851142024770866 -2.4322516935149068"/>
         <geometry>
            <mesh filename="package://viz/models/titans_hand/converted_thumbHinge.stl"/>
         </geometry>
         <material name="white"/>
      </visual>
   </link>
   <link name="revolute_thumb_jointbody">
      <inertial>
         <origin xyz="0.0 0.0 0.0" rpy="0.0 0.0 0.0"/>
         <mass value="0.001"/>
         <inertia ixx="1e-09" iyy="1e-09" izz="1e-09" ixy="0" ixz="0" iyz="0"/>
      </inertial>
   </link>
   <joint type="revolute" name="revolute_thumb">
      <parent link="hand"/>
      <child link="revolute_thumb_jointbody"/>
      <origin xyz="0.0 0.03375066 0.0623" rpy="0.0 0.0 0.0"/>
      <axis xyz="0.0 0.34222508701641263 0.9396180020713785"/>
      <limit lower="-1.5707" upper="0.786" effort="100" velocity="100"/>
   </joint>
   <joint type="fixed" name="revolute_thumb_offset">
      <parent link="revolute_thumb_jointbody"/>
      <child link="thumb"/>
      <origin xyz="-0.0 -0.03375066 -0.0623" rpy="0.0 0.0 0.0"/>
   </joint>
   <link name="f_proximal_thumb">
      <inertial>
         <origin xyz="-0.004297951798048206 0.05580866566310336 0.0843086892036457" rpy="-0.0011210076065933552 -0.06049491111901317 0.00030069089551451074"/>
         <mass value="0.008513045671991154"/>
         <inertia ixx="1.306750938104563e-06" iyy="1.2910804936716028e-06" izz="1.9549737860115378e-07" ixy="0" ixz="0" iyz="0"/>
      </inertial>
      <visual name="f_proximal_thumb">
         <origin xyz="-0.004297951798048206 0.05580866566310336 0.0843086892036457" rpy="-0.0011210076065933552 -0.060494911119013395 0.0003006908955145107"/>
         <geometry>
            <mesh filename="package://viz/models/titans_hand/converted_f_proximal_thumb.stl"/>
         </geometry>
         <material name="white"/>
      </visual>
   </link>
   <link name="revolute_proximal_thumb_jointbody">
      <inertial>
         <origin xyz="0.0 0.0 0.0" rpy="0.0 0.0 0.0"/>
         <mass value="0.001"/>
         <inertia ixx="1e-09" iyy="1e-09" izz="1e-09" ixy="0" ixz="0" iyz="0"/>
      </inertial>
   </link>
   <joint type="revolute" name="revolute_proximal_thumb">
      <parent link="thumb"/>
      <child link="revolute_proximal_thumb_jointbody"/>
      <origin xyz="0.0 0.05580889 0.0673319" rpy="0.0 0.0 0.0"/>
      <axis xyz="1.0 0.0 0.0"/>
      <limit lower="-3.141592" upper="0.0" effort="100" velocity="100"/>
   </joint>
   <joint type="fixed" name="revolute_proximal_thumb_offset">
      <parent link="revolute_proximal_thumb_jointbody"/>
      <child link="f_proximal_thumb"/>
      <origin xyz="-0.0 -0.05580889 -0.0673319" rpy="0.0 0.0 0.0"/>
   </joint>
   <link name="f_medial_thumb">
      <inertial>
         <origin xyz="-0.004174282327362963 0.05580154098117887 0.12063842172314324" rpy="0.00349794092532671 0.05280161793271221 0.0015134589420470353"/>
         <mass value="0.00362575779796271"/>
         <inertia ixx="2.3818492454688547e-07" iyy="2.0716156344351367e-07" izz="6.832850505523552e-08" ixy="0" ixz="0" iyz="0"/>
      </inertial>
      <visual name="f_medial_thumb">
         <origin xyz="-0.004174282327362963 0.05580154098117887 0.12063842172314324" rpy="0.00349794092532671 0.05280161793271221 0.0015134589420470353"/>
         <geometry>
            <mesh filename="package://viz/models/titans_hand/converted_f_medial_thumb.stl"/>
         </geometry>
         <material name="white"/>
      </visual>
   </link>
   <link name="revolute_medial_thumb_jointbody">
      <inertial>
         <origin xyz="0.0 0.0 0.0" rpy="0.0 0.0 0.0"/>
         <mass value="0.001"/>
         <inertia ixx="1e-09" iyy="1e-09" izz="1e-09" ixy="0" ixz="0" iyz="0"/>
      </inertial>
   </link>
   <joint type="revolute" name="revolute_medial_thumb">
      <parent link="f_proximal_thumb"/>
      <child link="revolute_medial_thumb_jointbody"/>
      <origin xyz="-0.00682572 0.06231091 0.10204161" rpy="0.0 0.0 0.0"/>
      <axis xyz="0.0 1.0 0.0"/>
      <limit lower="0.0" upper="1.5707" effort="100" velocity="100"/>
   </joint>
   <joint type="fixed" name="revolute_medial_thumb_offset">
      <parent link="revolute_medial_thumb_jointbody"/>
      <child link="f_medial_thumb"/>
      <origin xyz="0.00682572 -0.06231091 -0.10204161" rpy="0.0 0.0 0.0"/>
   </joint>
   <link name="f_distal_thumb_virtual">
      <inertial>
         <origin xyz="0.0 0.0 0.0" rpy="0.0 0.0 0.0"/>
         <mass value="0.0"/>
         <inertia ixx="0.0" iyy="0.0" izz="0.0" ixy="0" ixz="0" iyz="0"/>
      </inertial>
   </link>
   <link name="f_medial_thumb2f_distal_thumb_virtual_fixed_jointbody">
      <inertial>
         <origin xyz="0.0 0.0 0.0" rpy="0.0 0.0 0.0"/>
         <mass value="0.001"/>
         <inertia ixx="1e-09" iyy="1e-09" izz="1e-09" ixy="0" ixz="0" iyz="0"/>
      </inertial>
   </link>
   <joint type="fixed" name="f_medial_thumb2f_distal_thumb_virtual_fixed">
      <parent link="f_medial_thumb"/>
      <child link="f_medial_thumb2f_distal_thumb_virtual_fixed_jointbody"/>
      <origin xyz="0.0 0.0 0.0" rpy="0.0 0.0 0.0"/>
   </joint>
   <joint type="fixed" name="f_medial_thumb2f_distal_thumb_virtual_fixed_offset">
      <parent link="f_medial_thumb2f_distal_thumb_virtual_fixed_jointbody"/>
      <child link="f_distal_thumb_virtual"/>
      <origin xyz="-0.0 -0.0 -0.0" rpy="0.0 0.0 0.0"/>
   </joint>
   <link name="f_distal_thumb">
      <inertial>
         <origin xyz="-0.002743183463667816 0.05578990650003305 0.1426735470904285" rpy="-0.0005608075343264459 0.010813348257990185 -0.00457552909443207"/>
         <mass value="0.0014065187417840303"/>
         <inertia ixx="7.157650622938779e-08" iyy="6.265685629206977e-08" izz="1.689165819994808e-08" ixy="0" ixz="0" iyz="0"/>
      </inertial>
      <visual name="f_distal_thumb">
         <origin xyz="-0.002743183463667816 0.05578990650003305 0.1426735470904285" rpy="-0.0005608075343264459 0.010813348257990407 -0.00457552909443207"/>
         <geometry>
            <mesh filename="package://viz/models/titans_hand/converted_f_distal_thumb.stl"/>
         </geometry>
         <material name="white"/>
      </visual>
   </link>
   <link name="revolute_distal_thumb_jointbody">
      <inertial>
         <origin xyz="0.0 0.0 0.0" rpy="0.0 0.0 0.0"/>
         <mass value="0.001"/>
         <inertia ixx="1e-09" iyy="1e-09" izz="1e-09" ixy="0" ixz="0" iyz="0"/>
      </inertial>
   </link>
   <joint type="revolute" name="revolute_distal_thumb">
      <parent link="f_distal_thumb_virtual"/>
      <child link="revolute_distal_thumb_jointbody"/>
      <origin xyz="-0.00444824 0.06230108 0.13012679" rpy="0.0 0.0 0.0"/>
      <axis xyz="0.0 1.0 0.0"/>
      <limit lower="0.0" upper="1.5707" effort="100" velocity="100"/>
   </joint>
   <joint type="fixed" name="revolute_distal_thumb_offset">
      <parent link="revolute_distal_thumb_jointbody"/>
      <child link="f_distal_thumb"/>
      <origin xyz="0.00444824 -0.06230108 -0.13012679" rpy="0.0 0.0 0.0"/>
   </joint>
   <link name="finger_1">
      <inertial>
         <origin xyz="0.0029687680810755604 0.03410714525654222 0.11178942929059522" rpy="0.00170760427217985 -0.270159979472987 -0.007818085328238942"/>
         <mass value="0.003620692851362423"/>
         <inertia ixx="1.6607591132839185e-07" iyy="1.5839640989381737e-07" izz="8.57536993653747e-08" ixy="0" ixz="0" iyz="0"/>
      </inertial>
      <visual name="f_base_1">
         <origin xyz="0.0029687680810755604 0.03410714525654222 0.11178942929059522" rpy="0.00170760427217985 -0.270159979472987 -0.007818085328238942"/>
         <geometry>
            <mesh filename="package://viz/models/titans_hand/converted_f_base_1.stl"/>
         </geometry>
         <material name="white"/>
      </visual>
   </link>
   <link name="hand2finger_1_fixed_jointbody">
      <inertial>
         <origin xyz="0.0 0.0 0.0" rpy="0.0 0.0 0.0"/>
         <mass value="0.001"/>
         <inertia ixx="1e-09" iyy="1e-09" izz="1e-09" ixy="0" ixz="0" iyz="0"/>
      </inertial>
   </link>
   <joint type="fixed" name="hand2finger_1_fixed">
      <parent link="hand"/>
      <child link="hand2finger_1_fixed_jointbody"/>
      <origin xyz="0.0 0.0 0.0" rpy="0.0 0.0 0.0"/>
   </joint>
   <joint type="fixed" name="hand2finger_1_fixed_offset">
      <parent link="hand2finger_1_fixed_jointbody"/>
      <child link="finger_1"/>
      <origin xyz="-0.0 -0.0 -0.0" rpy="0.0 0.0 0.0"/>
   </joint>
   <link name="f_joint_1">
      <inertial>
         <origin xyz="0.00208586770390702 0.034102497590881665 0.12737633203207016" rpy="3.1337612662740977 -1.1666236191142398 0.007404724188730283"/>
         <mass value="0.00205077724159981"/>
         <inertia ixx="5.3021042242846075e-08" iyy="4.456769422477217e-08" izz="4.1862233507098256e-08" ixy="0" ixz="0" iyz="0"/>
      </inertial>
      <visual name="f_joint_1">
         <origin xyz="0.00208586770390702 0.034102497590881665 0.12737633203207016" rpy="3.1337612662740977 -1.1666236191142398 0.007404724188730283"/>
         <geometry>
            <mesh filename="package://viz/models/titans_hand/converted_f_joint_1.stl"/>
         </geometry>
         <material name="white"/>
      </visual>
   </link>
   <link name="revolute_joint_1_jointbody">
      <inertial>
         <origin xyz="0.0 0.0 0.0" rpy="0.0 0.0 0.0"/>
         <mass value="0.001"/>
         <inertia ixx="1e-09" iyy="1e-09" izz="1e-09" ixy="0" ixz="0" iyz="0"/>
      </inertial>
   </link>
   <joint type="revolute" name="revolute_joint_1">
      <parent link="finger_1"/>
      <child link="revolute_joint_1_jointbody"/>
      <origin xyz="0.00885185 0.03410852 0.11250719" rpy="0.0 0.0 0.0"/>
      <axis xyz="1.0 0.0 0.0"/>
      <limit lower="-0.393" upper="0.393" effort="100" velocity="100"/>
   </joint>
   <joint type="fixed" name="revolute_joint_1_offset">
      <parent link="revolute_joint_1_jointbody"/>
      <child link="f_joint_1"/>
      <origin xyz="-0.00885185 -0.03410852 -0.11250719" rpy="0.0 0.0 0.0"/>
   </joint>
   <link name="f_proximal_1">
      <inertial>
         <origin xyz="0.0031190579550748757 0.03408189919150284 0.15230004011161824" rpy="0.0020249258799340322 0.0320982378591812 -0.012550217898010786"/>
         <mass value="0.007546045792178881"/>
         <inertia ixx="9.563533404431607e-07" iyy="9.274115947109677e-07" izz="1.7176053838506628e-07" ixy="0" ixz="0" iyz="0"/>
      </inertial>
      <visual name="f_proximal_1">
         <origin xyz="0.0031190579550748757 0.03408189919150284 0.15230004011161824" rpy="0.0020249258799340322 0.0320982378591812 -0.012550217898010786"/>
         <geometry>
            <mesh filename="package://viz/models/titans_hand/converted_f_proximal_1.stl"/>
         </geometry>
         <material name="white"/>
      </visual>
   </link>
   <link name="revolute_proximal_1_jointbody">
      <inertial>
         <origin xyz="0.0 0.0 0.0" rpy="0.0 0.0 0.0"/>
         <mass value="0.001"/>
         <inertia ixx="1e-09" iyy="1e-09" izz="1e-09" ixy="0" ixz="0" iyz="0"/>
      </inertial>
   </link>
   <joint type="revolute" name="revolute_proximal_1">
      <parent link="f_joint_1"/>
      <child link="revolute_proximal_1_jointbody"/>
      <origin xyz="1e-05 0.03961 0.12431" rpy="0.0 0.0 0.0"/>
      <axis xyz="0.0 1.0 0.0"/>
      <limit lower="0.0" upper="1.5707" effort="100" velocity="100"/>
   </joint>
   <joint type="fixed" name="revolute_proximal_1_offset">
      <parent link="revolute_proximal_1_jointbody"/>
      <child link="f_proximal_1"/>
      <origin xyz="-1e-05 -0.03961 -0.12431" rpy="0.0 0.0 0.0"/>
   </joint>
   <link name="f_medial_1">
      <inertial>
         <origin xyz="0.005387258235178706 0.03409935854176851 0.18615389567478657" rpy="-0.0006624714835370715 0.061877435271356473 0.0030478826210008055"/>
         <mass value="0.003609616075415664"/>
         <inertia ixx="2.3670853829117485e-07" iyy="2.0588772578344367e-07" izz="6.815248479532083e-08" ixy="0" ixz="0" iyz="0"/>
      </inertial>
      <visual name="f_medial_1">
         <origin xyz="0.005387258235178706 0.03409935854176851 0.18615389567478657" rpy="-0.0006624714835370719 0.061877435271356473 0.003047882621000806"/>
         <geometry>
            <mesh filename="package://viz/models/titans_hand/converted_f_medial_1.stl"/>
         </geometry>
         <material name="white"/>
      </visual>
   </link>
   <link name="revolute_medial_1_jointbody">
      <inertial>
         <origin xyz="0.0 0.0 0.0" rpy="0.0 0.0 0.0"/>
         <mass value="0.001"/>
         <inertia ixx="1e-09" iyy="1e-09" izz="1e-09" ixy="0" ixz="0" iyz="0"/>
      </inertial>
   </link>
   <joint type="revolute" name="revolute_medial_1">
      <parent link="f_proximal_1"/>
      <child link="revolute_medial_1_jointbody"/>
      <origin xyz="0.00213 0.04061 0.16771" rpy="0.0 0.0 0.0"/>
      <axis xyz="0.0 1.0 0.0"/>
      <limit lower="0.0" upper="1.5707" effort="100" velocity="100"/>
   </joint>
   <joint type="fixed" name="revolute_medial_1_offset">
      <parent link="revolute_medial_1_jointbody"/>
      <child link="f_medial_1"/>
      <origin xyz="-0.00213 -0.04061 -0.16771" rpy="0.0 0.0 0.0"/>
   </joint>
   <link name="f_distal_1">
      <inertial>
         <origin xyz="0.0070655200574758405 0.034104964607814627 0.20811444458329728" rpy="-0.0004941105941255493 0.021028496265301122 0.0003120875215016336"/>
         <mass value="0.0014065191101151845"/>
         <inertia ixx="7.157651836700943e-08" iyy="6.26568649782473e-08" izz="1.6891665830819875e-08" ixy="0" ixz="0" iyz="0"/>
      </inertial>
      <visual name="f_distal_1">
         <origin xyz="0.0070655200574758405 0.034104964607814627 0.20811444458329728" rpy="-0.0004941105941255492 0.021028496265301344 0.0003120875215016335"/>
         <geometry>
            <mesh filename="package://viz/models/titans_hand/converted_f_distal_1.stl"/>
         </geometry>
         <material name="white"/>
      </visual>
   </link>
   <link name="revolute_distal_1_jointbody">
      <inertial>
         <origin xyz="0.0 0.0 0.0" rpy="0.0 0.0 0.0"/>
         <mass value="0.001"/>
         <inertia ixx="1e-09" iyy="1e-09" izz="1e-09" ixy="0" ixz="0" iyz="0"/>
      </inertial>
   </link>
   <joint type="revolute" name="revolute_distal_1">
      <parent link="f_medial_1"/>
      <child link="revolute_distal_1_jointbody"/>
      <origin xyz="0.0052 0.04011 0.19559" rpy="0.0 0.0 0.0"/>
      <axis xyz="0.0 1.0 0.0"/>
      <limit lower="0.0" upper="1.5707" effort="100" velocity="100"/>
   </joint>
   <joint type="fixed" name="revolute_distal_1_offset">
      <parent link="revolute_distal_1_jointbody"/>
      <child link="f_distal_1"/>
      <origin xyz="-0.0052 -0.04011 -0.19559" rpy="0.0 0.0 0.0"/>
   </joint>
   <link name="finger_2">
      <inertial>
         <origin xyz="0.0029447268671506668 0.01429271298222884 0.110055817015949" rpy="0.18256705438298965 -0.2643925590830212 -0.058132657398470775"/>
         <mass value="0.0036206924209375257"/>
         <inertia ixx="1.6607588120603963e-07" iyy="1.5839638102660363e-07" izz="8.575369277113502e-08" ixy="0" ixz="0" iyz="0"/>
      </inertial>
      <visual name="f_base_2">
         <origin xyz="0.0029447268671506668 0.01429271298222884 0.110055817015949" rpy="0.18256705438298965 -0.2643925590830212 -0.058132657398470775"/>
         <geometry>
            <mesh filename="package://viz/models/titans_hand/converted_f_base_2.stl"/>
         </geometry>
         <material name="white"/>
      </visual>
   </link>
   <link name="hand2finger_2_fixed_jointbody">
      <inertial>
         <origin xyz="0.0 0.0 0.0" rpy="0.0 0.0 0.0"/>
         <mass value="0.001"/>
         <inertia ixx="1e-09" iyy="1e-09" izz="1e-09" ixy="0" ixz="0" iyz="0"/>
      </inertial>
   </link>
   <joint type="fixed" name="hand2finger_2_fixed">
      <parent link="hand"/>
      <child link="hand2finger_2_fixed_jointbody"/>
      <origin xyz="0.0 0.0 0.0" rpy="0.0 0.0 0.0"/>
   </joint>
   <joint type="fixed" name="hand2finger_2_fixed_offset">
      <parent link="hand2finger_2_fixed_jointbody"/>
      <child link="finger_2"/>
      <origin xyz="-0.0 -0.0 -0.0" rpy="0.0 0.0 0.0"/>
   </joint>
   <link name="f_joint_2">
      <inertial>
         <origin xyz="0.002058534532073282 0.01158388538188816 0.1254053440175476" rpy="-2.7270098695477527 -1.133464752154149 -0.38159593283953774"/>
         <mass value="0.002050777715342269"/>
         <inertia ixx="5.3021055932695205e-08" iyy="4.456771025300793e-08" izz="4.186224802262042e-08" ixy="0" ixz="0" iyz="0"/>
      </inertial>
      <visual name="f_joint_2">
         <origin xyz="0.002058534532073282 0.01158388538188816 0.1254053440175476" rpy="-2.7270098695477527 -1.1334647521541488 -0.38159593283953774"/>
         <geometry>
            <mesh filename="package://viz/models/titans_hand/converted_f_joint_2.stl"/>
         </geometry>
         <material name="white"/>
      </visual>
   </link>
   <link name="revolute_joint_2_jointbody">
      <inertial>
         <origin xyz="0.0 0.0 0.0" rpy="0.0 0.0 0.0"/>
         <mass value="0.001"/>
         <inertia ixx="1e-09" iyy="1e-09" izz="1e-09" ixy="0" ixz="0" iyz="0"/>
      </inertial>
   </link>
   <joint type="revolute" name="revolute_joint_2">
      <parent link="finger_2"/>
      <child link="revolute_joint_2_jointbody"/>
      <origin xyz="0.00883 0.01416 0.11076" rpy="0.0 0.0 0.0"/>
      <axis xyz="1.0 0.0 0.0"/>
      <limit lower="-0.393" upper="0.393" effort="100" velocity="100"/>
   </joint>
   <joint type="fixed" name="revolute_joint_2_offset">
      <parent link="revolute_joint_2_jointbody"/>
      <child link="f_joint_2"/>
      <origin xyz="-0.00883 -0.01416 -0.11076" rpy="0.0 0.0 0.0"/>
   </joint>
   <link name="f_proximal_2">
      <inertial>
         <origin xyz="0.003060846205633814 0.00723352366783981 0.1499473097214772" rpy="0.17663569727982528 0.032634425458659466 -0.009433166148778316"/>
         <mass value="0.0075460471240385634"/>
         <inertia ixx="9.563536008978057e-07" iyy="9.274118602498793e-07" izz="1.7176056719609934e-07" ixy="0" ixz="0" iyz="0"/>
      </inertial>
      <visual name="f_proximal_2">
         <origin xyz="0.003060846205633814 0.00723352366783981 0.1499473097214772" rpy="0.1766356972798253 0.032634425458659244 -0.00943316614877833"/>
         <geometry>
            <mesh filename="package://viz/models/titans_hand/converted_f_proximal_2.stl"/>
         </geometry>
         <material name="white"/>
      </visual>
   </link>
   <link name="revolute_proximal_2_jointbody">
      <inertial>
         <origin xyz="0.0 0.0 0.0" rpy="0.0 0.0 0.0"/>
         <mass value="0.001"/>
         <inertia ixx="1e-09" iyy="1e-09" izz="1e-09" ixy="0" ixz="0" iyz="0"/>
      </inertial>
   </link>
   <joint type="revolute" name="revolute_proximal_2">
      <parent link="f_joint_2"/>
      <child link="revolute_proximal_2_jointbody"/>
      <origin xyz="0.0 0.01853 0.12351" rpy="0.0 0.0 0.0"/>
      <axis xyz="0.0 0.9848072075841259 0.17365127091488977"/>
      <limit lower="0.0" upper="1.5707" effort="100" velocity="100"/>
   </joint>
   <joint type="fixed" name="revolute_proximal_2_offset">
      <parent link="revolute_proximal_2_jointbody"/>
      <child link="f_proximal_2"/>
      <origin xyz="-0.0 -0.01853 -0.12351" rpy="0.0 0.0 0.0"/>
   </joint>
   <link name="f_medial_2">
      <inertial>
         <origin xyz="0.005275023429847027 0.0013667341685768403 0.18329257485070996" rpy="0.17415907615769513 0.059252471848857624 0.011108839104358448"/>
         <mass value="0.0036096160859730524"/>
         <inertia ixx="2.3670856228715804e-07" iyy="2.0588775129681034e-07" izz="6.815248571337438e-08" ixy="0" ixz="0" iyz="0"/>
      </inertial>
      <visual name="f_medial_2">
         <origin xyz="0.005275023429847027 0.0013667341685768403 0.18329257485070996" rpy="0.17415907615769513 0.059252471848857624 0.011108839104358448"/>
         <geometry>
            <mesh filename="package://viz/models/titans_hand/converted_f_medial_2.stl"/>
         </geometry>
         <material name="white"/>
      </visual>
   </link>
   <link name="revolute_medial_2_jointbody">
      <inertial>
         <origin xyz="0.0 0.0 0.0" rpy="0.0 0.0 0.0"/>
         <mass value="0.001"/>
         <inertia ixx="1e-09" iyy="1e-09" izz="1e-09" ixy="0" ixz="0" iyz="0"/>
      </inertial>
   </link>
   <joint type="revolute" name="revolute_medial_2">
      <parent link="f_proximal_2"/>
      <child link="revolute_medial_2_jointbody"/>
      <origin xyz="0.00206 0.01099 0.16626" rpy="0.0 0.0 0.0"/>
      <axis xyz="0.0 0.9848072075841259 0.17365127091488977"/>
      <limit lower="0.0" upper="1.5707" effort="100" velocity="100"/>
   </joint>
   <joint type="fixed" name="revolute_medial_2_offset">
      <parent link="revolute_medial_2_jointbody"/>
      <child link="f_medial_2"/>
      <origin xyz="-0.00206 -0.01099 -0.16626" rpy="0.0 0.0 0.0"/>
   </joint>
   <link name="f_distal_2">
      <inertial>
         <origin xyz="0.006918227841553544 -0.002445157463405754 0.20492245535229708" rpy="0.17406280323115986 0.019500450031886052 0.0013103579631986162"/>
         <mass value="0.0014065191067448842"/>
         <inertia ixx="7.157650906226636e-08" iyy="6.265685614708838e-08" izz="1.6891665616681946e-08" ixy="0" ixz="0" iyz="0"/>
      </inertial>
      <visual name="f_distal_2">
         <origin xyz="0.006918227841553544 -0.002445157463405754 0.20492245535229708" rpy="0.17406280323115986 0.019500450031886274 0.00131035796319863"/>
         <geometry>
            <mesh filename="package://viz/models/titans_hand/converted_f_distal_2.stl"/>
         </geometry>
         <material name="white"/>
      </visual>
   </link>
   <link name="revolute_distal_2_jointbody">
      <inertial>
         <origin xyz="0.0 0.0 0.0" rpy="0.0 0.0 0.0"/>
         <mass value="0.001"/>
         <inertia ixx="1e-09" iyy="1e-09" izz="1e-09" ixy="0" ixz="0" iyz="0"/>
      </inertial>
   </link>
   <joint type="revolute" name="revolute_distal_2">
      <parent link="f_medial_2"/>
      <child link="revolute_distal_2_jointbody"/>
      <origin xyz="0.00508 0.00442 0.19341" rpy="0.0 0.0 0.0"/>
      <axis xyz="0.0 0.9848072075841259 0.17365127091488977"/>
      <limit lower="0.0" upper="1.5707" effort="100" velocity="100"/>
   </joint>
   <joint type="fixed" name="revolute_distal_2_offset">
      <parent link="revolute_distal_2_jointbody"/>
      <child link="f_distal_2"/>
      <origin xyz="-0.00508 -0.00442 -0.19341" rpy="0.0 0.0 0.0"/>
   </joint>
   <link name="finger_3">
      <inertial>
         <origin xyz="0.00287334073885369 -0.004919625746767773 0.1049081327711756" rpy="0.36242286733050033 -0.25001376322336943 -0.1064275412221466"/>
         <mass value="0.0036206926896220986"/>
         <inertia ixx="1.6607589499972824e-07" iyy="1.5839639043472208e-07" izz="8.575369800401134e-08" ixy="0" ixz="0" iyz="0"/>
      </inertial>
      <visual name="f_base_3">
         <origin xyz="0.00287334073885369 -0.004919625746767773 0.1049081327711756" rpy="0.36242286733050033 -0.25001376322336943 -0.1064275412221466"/>
         <geometry>
            <mesh filename="package://viz/models/titans_hand/converted_f_base_3.stl"/>
         </geometry>
         <material name="white"/>
      </visual>
   </link>
   <link name="hand2finger_3_fixed_jointbody">
      <inertial>
         <origin xyz="0.0 0.0 0.0" rpy="0.0 0.0 0.0"/>
         <mass value="0.001"/>
         <inertia ixx="1e-09" iyy="1e-09" izz="1e-09" ixy="0" ixz="0" iyz="0"/>
      </inertial>
   </link>
   <joint type="fixed" name="hand2finger_3_fixed">
      <parent link="hand"/>
      <child link="hand2finger_3_fixed_jointbody"/>
      <origin xyz="0.0 0.0 0.0" rpy="0.0 0.0 0.0"/>
   </joint>
   <joint type="fixed" name="hand2finger_3_fixed_offset">
      <parent link="hand2finger_3_fixed_jointbody"/>
      <child link="finger_3"/>
      <origin xyz="-0.0 -0.0 -0.0" rpy="0.0 0.0 0.0"/>
   </joint>
   <link name="f_joint_3">
      <inertial>
         <origin xyz="0.0019773956754786126 -0.010250327929200114 0.11955435893351203" rpy="-2.4005744947693994 -1.044467505714008 -0.6740736106319707"/>
         <mass value="0.002050777844707917"/>
         <inertia ixx="5.302105945368402e-08" iyy="4.456771016350984e-08" izz="4.1862248821523e-08" ixy="0" ixz="0" iyz="0"/>
      </inertial>
      <visual name="f_joint_3">
         <origin xyz="0.0019773956754786126 -0.010250327929200114 0.11955435893351203" rpy="-2.4005744947693994 -1.0444675057140078 -0.6740736106319707"/>
         <geometry>
            <mesh filename="package://viz/models/titans_hand/converted_f_joint_3.stl"/>
         </geometry>
         <material name="white"/>
      </visual>
   </link>
   <link name="revolute_joint_3_jointbody">
      <inertial>
         <origin xyz="0.0 0.0 0.0" rpy="0.0 0.0 0.0"/>
         <mass value="0.001"/>
         <inertia ixx="1e-09" iyy="1e-09" izz="1e-09" ixy="0" ixz="0" iyz="0"/>
      </inertial>
   </link>
   <joint type="revolute" name="revolute_joint_3">
      <parent link="finger_3"/>
      <child link="revolute_joint_3_jointbody"/>
      <origin xyz="0.00876 -0.00519 0.10558" rpy="0.0 0.0 0.0"/>
      <axis xyz="1.0 0.0 0.0"/>
      <limit lower="-0.393" upper="0.393" effort="100" velocity="100"/>
   </joint>
   <joint type="fixed" name="revolute_joint_3_offset">
      <parent link="revolute_joint_3_jointbody"/>
      <child link="f_joint_3"/>
      <origin xyz="-0.00876 0.00519 -0.10558" rpy="0.0 0.0 0.0"/>
   </joint>
   <link name="f_proximal_3">
      <inertial>
         <origin xyz="0.0029445036928082485 -0.018798332956460488 0.1429684252315403" rpy="0.3512448157096612 0.03299132257671955 -0.006391947358808825"/>
         <mass value="0.007546046244962271"/>
         <inertia ixx="9.563534622084716e-07" iyy="9.274117157184805e-07" izz="1.7176054040797138e-07" ixy="0" ixz="0" iyz="0"/>
      </inertial>
      <visual name="f_proximal_3">
         <origin xyz="0.0029445036928082485 -0.018798332956460488 0.1429684252315403" rpy="0.35124481570966115 0.03299132257671933 -0.006391947358808853"/>
         <geometry>
            <mesh filename="package://viz/models/titans_hand/converted_f_proximal_3.stl"/>
         </geometry>
         <material name="white"/>
      </visual>
   </link>
   <link name="revolute_proximal_3_jointbody">
      <inertial>
         <origin xyz="0.0 0.0 0.0" rpy="0.0 0.0 0.0"/>
         <mass value="0.001"/>
         <inertia ixx="1e-09" iyy="1e-09" izz="1e-09" ixy="0" ixz="0" iyz="0"/>
      </inertial>
   </link>
   <joint type="revolute" name="revolute_proximal_3">
      <parent link="f_joint_3"/>
      <child link="revolute_proximal_3_jointbody"/>
      <origin xyz="-6e-05 -0.00308 0.1189" rpy="0.0 0.0 0.0"/>
      <axis xyz="0.0 0.9400032368184845 0.3411655240067088"/>
      <limit lower="0.0" upper="1.5707" effort="100" velocity="100"/>
   </joint>
   <joint type="fixed" name="revolute_proximal_3_offset">
      <parent link="revolute_proximal_3_jointbody"/>
      <child link="f_proximal_3"/>
      <origin xyz="6e-05 0.00308 -0.1189" rpy="0.0 0.0 0.0"/>
   </joint>
   <link name="f_medial_3">
      <inertial>
         <origin xyz="0.0051016406505764895 -0.03037173991175558 0.17479029691562517" rpy="0.3489260314491369 0.05563788761241528 0.018466716151594398"/>
         <mass value="0.0036096164065753684"/>
         <inertia ixx="2.3670858957914472e-07" iyy="2.0588777577576836e-07" izz="6.815248924201918e-08" ixy="0" ixz="0" iyz="0"/>
      </inertial>
      <visual name="f_medial_3">
         <origin xyz="0.0051016406505764895 -0.03037173991175558 0.17479029691562517" rpy="0.3489260314491369 0.05563788761241506 0.01846671615159437"/>
         <geometry>
            <mesh filename="package://viz/models/titans_hand/converted_f_medial_3.stl"/>
         </geometry>
         <material name="white"/>
      </visual>
   </link>
   <link name="revolute_medial_3_jointbody">
      <inertial>
         <origin xyz="0.0 0.0 0.0" rpy="0.0 0.0 0.0"/>
         <mass value="0.001"/>
         <inertia ixx="1e-09" iyy="1e-09" izz="1e-09" ixy="0" ixz="0" iyz="0"/>
      </inertial>
   </link>
   <joint type="revolute" name="revolute_medial_3">
      <parent link="f_proximal_3"/>
      <child link="revolute_medial_3_jointbody"/>
      <origin xyz="0.00194 -0.01793 0.15968" rpy="0.0 0.0 0.0"/>
      <axis xyz="0.0 0.9400032368184845 0.3411655240067088"/>
      <limit lower="0.0" upper="1.5707" effort="100" velocity="100"/>
   </joint>
   <joint type="fixed" name="revolute_medial_3_offset">
      <parent link="revolute_medial_3_jointbody"/>
      <child link="f_medial_3"/>
      <origin xyz="-0.00194 0.01793 -0.15968" rpy="0.0 0.0 0.0"/>
   </joint>
   <link name="f_distal_3">
      <inertial>
         <origin xyz="0.006707827846415839 -0.037885786117765476 0.19543107070677315" rpy="0.34861175654735777 0.018191521844554526 0.0019064361888620207"/>
         <mass value="0.0014065189189228198"/>
         <inertia ixx="7.157651379246746e-08" iyy="6.265686226383923e-08" izz="1.6891662377127975e-08" ixy="0" ixz="0" iyz="0"/>
      </inertial>
      <visual name="f_distal_3">
         <origin xyz="0.006707827846415839 -0.037885786117765476 0.19543107070677315" rpy="0.34861175654735765 0.018191521844554526 0.0019064361888620207"/>
         <geometry>
            <mesh filename="package://viz/models/titans_hand/converted_f_distal_3.stl"/>
         </geometry>
         <material name="white"/>
      </visual>
   </link>
   <link name="revolute_distal_3_jointbody">
      <inertial>
         <origin xyz="0.0 0.0 0.0" rpy="0.0 0.0 0.0"/>
         <mass value="0.001"/>
         <inertia ixx="1e-09" iyy="1e-09" izz="1e-09" ixy="0" ixz="0" iyz="0"/>
      </inertial>
   </link>
   <joint type="revolute" name="revolute_distal_3">
      <parent link="f_medial_3"/>
      <child link="revolute_distal_3_jointbody"/>
      <origin xyz="0.00491 -0.02748 0.18588" rpy="0.0 0.0 0.0"/>
      <axis xyz="0.0 0.9400032368184845 0.3411655240067088"/>
      <limit lower="0.0" upper="1.5707" effort="100" velocity="100"/>
   </joint>
   <joint type="fixed" name="revolute_distal_3_offset">
      <parent link="revolute_distal_3_jointbody"/>
      <child link="f_distal_3"/>
      <origin xyz="-0.00491 0.02748 -0.18588" rpy="0.0 0.0 0.0"/>
   </joint>
   <link name="finger_4">
      <inertial>
         <origin xyz="0.0027695714124540086 -0.02298619285180325 0.09742530459746236" rpy="0.45174172827163417 -0.2397463601142107 -0.12930722719572943"/>
         <mass value="0.0036206928907530425"/>
         <inertia ixx="1.6607590452631965e-07" iyy="1.5839640586271052e-07" izz="8.575369804142303e-08" ixy="0" ixz="0" iyz="0"/>
      </inertial>
      <visual name="f_base_4">
         <origin xyz="0.0027695714124540086 -0.02298619285180325 0.09742530459746236" rpy="0.4517417282716341 -0.2397463601142107 -0.12930722719572946"/>
         <geometry>
            <mesh filename="package://viz/models/titans_hand/converted_f_base_4.stl"/>
         </geometry>
         <material name="white"/>
      </visual>
   </link>
   <link name="hand2finger_4_fixed_jointbody">
      <inertial>
         <origin xyz="0.0 0.0 0.0" rpy="0.0 0.0 0.0"/>
         <mass value="0.001"/>
         <inertia ixx="1e-09" iyy="1e-09" izz="1e-09" ixy="0" ixz="0" iyz="0"/>
      </inertial>
   </link>
   <joint type="fixed" name="hand2finger_4_fixed">
      <parent link="hand"/>
      <child link="hand2finger_4_fixed_jointbody"/>
      <origin xyz="0.0 0.0 0.0" rpy="0.0 0.0 0.0"/>
   </joint>
   <joint type="fixed" name="hand2finger_4_fixed_offset">
      <parent link="hand2finger_4_fixed_jointbody"/>
      <child link="finger_4"/>
      <origin xyz="-0.0 -0.0 -0.0" rpy="0.0 0.0 0.0"/>
   </joint>
   <link name="f_joint_4">
      <inertial>
         <origin xyz="0.0018664118301764693 -0.02957190751533808 0.11155130030407574" rpy="-2.2767849208009316 -0.9863551477875403 -0.7804404493784074"/>
         <mass value="0.002050777487611732"/>
         <inertia ixx="5.30210521443784e-08" iyy="4.456770330935976e-08" izz="4.18622399209406e-08" ixy="0" ixz="0" iyz="0"/>
      </inertial>
      <visual name="f_joint_4">
         <origin xyz="0.0018664118301764693 -0.02957190751533808 0.11155130030407574" rpy="-2.2767849208009316 -0.9863551477875403 -0.7804404493784081"/>
         <geometry>
            <mesh filename="package://viz/models/titans_hand/converted_f_joint_4.stl"/>
         </geometry>
         <material name="white"/>
      </visual>
   </link>
   <link name="revolute_joint_4_jointbody">
      <inertial>
         <origin xyz="0.0 0.0 0.0" rpy="0.0 0.0 0.0"/>
         <mass value="0.001"/>
         <inertia ixx="1e-09" iyy="1e-09" izz="1e-09" ixy="0" ixz="0" iyz="0"/>
      </inertial>
   </link>
   <joint type="revolute" name="revolute_joint_4">
      <parent link="finger_4"/>
      <child link="revolute_joint_4_jointbody"/>
      <origin xyz="0.00865 -0.02332 0.09807" rpy="0.0 0.0 0.0"/>
      <axis xyz="1.0 0.0 0.0"/>
      <limit lower="-0.393" upper="0.393" effort="100" velocity="100"/>
   </joint>
   <joint type="fixed" name="revolute_joint_4_offset">
      <parent link="revolute_joint_4_jointbody"/>
      <child link="f_joint_4"/>
      <origin xyz="-0.00865 0.02332 -0.09807" rpy="0.0 0.0 0.0"/>
   </joint>
   <link name="f_proximal_4">
      <inertial>
         <origin xyz="0.002748420788454541 -0.04012924460752692 0.1341327832134435" rpy="0.43854644558191824 0.029864073010889225 -0.00638368261173719"/>
         <mass value="0.0075460461834587446"/>
         <inertia ixx="9.56353416097486e-07" iyy="9.274116691614614e-07" izz="1.717605301331336e-07" ixy="0" ixz="0" iyz="0"/>
      </inertial>
      <visual name="f_proximal_4">
         <origin xyz="0.002748420788454541 -0.04012924460752692 0.1341327832134435" rpy="0.43854644558191824 0.029864073010889225 -0.00638368261173719"/>
         <geometry>
            <mesh filename="package://viz/models/titans_hand/converted_f_proximal_4.stl"/>
         </geometry>
         <material name="white"/>
      </visual>
   </link>
   <link name="revolute_proximal_4_jointbody">
      <inertial>
         <origin xyz="0.0 0.0 0.0" rpy="0.0 0.0 0.0"/>
         <mass value="0.001"/>
         <inertia ixx="1e-09" iyy="1e-09" izz="1e-09" ixy="0" ixz="0" iyz="0"/>
      </inertial>
   </link>
   <joint type="revolute" name="revolute_proximal_4">
      <parent link="f_joint_4"/>
      <child link="revolute_proximal_4_jointbody"/>
      <origin xyz="-0.00016 -0.02237 0.11152" rpy="0.0 0.0 0.0"/>
      <axis xyz="0.0 0.9067486699488351 0.42167149482271005"/>
      <limit lower="0.0" upper="1.5707" effort="100" velocity="100"/>
   </joint>
   <joint type="fixed" name="revolute_proximal_4_offset">
      <parent link="revolute_proximal_4_jointbody"/>
      <child link="f_proximal_4"/>
      <origin xyz="0.00016 0.02237 -0.11152" rpy="0.0 0.0 0.0"/>
   </joint>
   <link name="f_medial_4">
      <inertial>
         <origin xyz="0.004754949148978116 -0.05443718706149976 0.1648327051989323" rpy="0.43619723873075494 0.05025979277372339 0.02035114194529547"/>
         <mass value="0.003609616674872929"/>
         <inertia ixx="2.367085849623129e-07" iyy="2.0588776969080577e-07" izz="6.815249540002653e-08" ixy="0" ixz="0" iyz="0"/>
      </inertial>
      <visual name="f_medial_4">
         <origin xyz="0.004754949148978116 -0.05443718706149976 0.1648327051989323" rpy="0.436197238730755 0.050259792773723166 0.020351141945295442"/>
         <geometry>
            <mesh filename="package://viz/models/titans_hand/converted_f_medial_4.stl"/>
         </geometry>
         <material name="white"/>
      </visual>
   </link>
   <link name="revolute_medial_4_jointbody">
      <inertial>
         <origin xyz="0.0 0.0 0.0" rpy="0.0 0.0 0.0"/>
         <mass value="0.001"/>
         <inertia ixx="1e-09" iyy="1e-09" izz="1e-09" ixy="0" ixz="0" iyz="0"/>
      </inertial>
   </link>
   <joint type="revolute" name="revolute_medial_4">
      <parent link="f_proximal_4"/>
      <child link="revolute_medial_4_jointbody"/>
      <origin xyz="0.00168 -0.04072 0.15086" rpy="0.0 0.0 0.0"/>
      <axis xyz="0.0 0.9067486699488351 0.42167149482271005"/>
      <limit lower="0.0" upper="1.5707" effort="100" velocity="100"/>
   </joint>
   <joint type="fixed" name="revolute_medial_4_offset">
      <parent link="revolute_medial_4_jointbody"/>
      <child link="f_medial_4"/>
      <origin xyz="-0.00168 0.04072 -0.15086" rpy="0.0 0.0 0.0"/>
   </joint>
   <link name="f_distal_4">
      <inertial>
         <origin xyz="0.0062634247188262755 -0.0637255184023173 0.18474585899549972" rpy="0.43585440777130924 0.014397741628137117 0.0005918102479726406"/>
         <mass value="0.0014065188486264036"/>
         <inertia ixx="7.157650465114436e-08" iyy="6.265685331616462e-08" izz="1.689166112160818e-08" ixy="0" ixz="0" iyz="0"/>
      </inertial>
      <visual name="f_distal_4">
         <origin xyz="0.0062634247188262755 -0.0637255184023173 0.18474585899549972" rpy="0.43585440777130924 0.014397741628137117 0.0005918102479726406"/>
         <geometry>
            <mesh filename="package://viz/models/titans_hand/converted_f_distal_4.stl"/>
         </geometry>
         <material name="white"/>
      </visual>
   </link>
   <link name="revolute_distal_4_jointbody">
      <inertial>
         <origin xyz="0.0 0.0 0.0" rpy="0.0 0.0 0.0"/>
         <mass value="0.001"/>
         <inertia ixx="1e-09" iyy="1e-09" izz="1e-09" ixy="0" ixz="0" iyz="0"/>
      </inertial>
   </link>
   <joint type="revolute" name="revolute_distal_4">
      <parent link="f_medial_4"/>
      <child link="revolute_distal_4_jointbody"/>
      <origin xyz="0.00453 -0.05252 0.17613" rpy="0.0 0.0 0.0"/>
      <axis xyz="0.0 0.9067486699488351 0.42167149482271005"/>
      <limit lower="0.0" upper="1.5707" effort="100" velocity="100"/>
   </joint>
   <joint type="fixed" name="revolute_distal_4_offset">
      <parent link="revolute_distal_4_jointbody"/>
      <child link="f_distal_4"/>
      <origin xyz="-0.00453 0.05252 -0.17613" rpy="0.0 0.0 0.0"/>
   </joint>
   <material name="white">
      <color rgba="1 1 1 1"/>
   </material>
</robot>
