<mujoco model="titans_hand_structure">
        <body name="wrist" pos="0 0 0.03">
            <geom mesh="wrist" name="wrist_geom" pos ="0 0 -0.03"/>


            <body name = "connector_base" pos="0 0 -0.03000"> 
                <joint name="revolute_base_hand" axis="1 0 0" limited="true" range="-1.5707 1.5707" pos="0 0 0.03"/>
                <geom mesh="connector_base" name="connector_geom"/>
            </body>
                <body name="palm" pos = "0 0 0.025">
                    <geom mesh="palm" name="palm_geom" pos = "0 0 -0.055"/>

                    <body name="thumb_base" pos="0.03930 0 0.023115" euler = "0 0.34906585 0">
                    <joint name="thumb_hinge" axis="0 0 1" limited="true" range="-1.75 0.1"/>
                    <geom mesh="thumb_hinge" pos = "-0.0120 0 -0.088115" quat="0.9848 0 -0.1736 0"/>
                    <body name="thumb_pp" pos="0.02053 0.0 0.007747733972">
                        <joint name="thumb_base2pp" axis="0 1 0" limited="true" range="-0.2 1.35"/>
                        <geom mesh="thumb_pp" pos="-0.06283 0 -0.07849" euler = "0 0 -1.5707"/>
                        <body name="thumb_mp_virt" pos="0 0.00790 0.03471">
                            <joint name="thumb_pp2mp_virt" axis="1 0 0" range="-0.131 0.960"/>
                            <inertial pos ="0 0 0" mass="0.001" diaginertia="4E-10 4E-10 3E-10"/>
                            <body name="thumb_mp" pos="0 -0.00094 0.01115">
                                <joint name="thumb_pp2mp" axis="1 0 0" range="-0.131 0.960"/>
                                <geom mesh="thumb_mp" euler = "0 0 -1.5707" pos="-0.06283 -0.00696 -0.1236"/>
                                <body name="thumb_dp_virt" pos="0 -0.00110 0.01693">
                                    <joint name="thumb_mp2dp_virt" axis="1 0 0" range="-0.093 0.682"/>
                                    <inertial pos ="0 0 -0.1" mass="0.001" diaginertia="4E-10 4E-10 3E-10"/>
                                        <body name="thumb_dp" pos="0 -0.00121 0.00845">
                                        <joint type = "hinge" name="thumb_mp2dp" axis="1 0 0" range="-0.093 0.682"/>
                                        <geom mesh="thumb_dp" pos="-0.06282 -0.00463 -0.14876" euler = "0 0 -1.5707"/>
                                        <body name="thumb_fingertip" pos="0 0 0.01465">
                                        </body>
                                    </body>
                                </body>
                            </body>
                        </body>
                    </body>
                </body>
                    
                    <body name="index_base" pos="0.04096 -0.002 0.063" euler="0.0 0.0 0.0"> <!-- y x z-->
                        <geom mesh="index_base"/>
                        <body name="index_um_virt" pos="0 0 0.00527505">
                            <joint name="index_abd_virt" axis="0 1 0" range="-0.264 0.264"/>
                            <inertial pos ="0 0 0" mass = "0.001" diaginertia="4E-10 4E-10 3E-10"/>
                            <body name="index_um" pos="0 0 0.01789991">
                                <joint name="index_abd" axis="0 1 0" range="-0.264 0.264"/>
                                <geom mesh="index_um" pos="0 0 -0.02317496"/>
                                <body name="index_pp_virt" pos="0 0.0033 -0.00625608">
                                    <joint name="root2index_pp_virt" axis="1 0 0" range="-0.157 0.829"/>
                                    <inertial pos ="0 0 0" mass="0.001" diaginertia="4E-10 4E-10 3E-10"/>
                                    <body name="index_pp" pos="0 -0.00015683 0.01722519">
                                        <joint name="root2index_pp" axis="1 0 0" range="-0.157 0.829"/>
                                        <geom mesh="index_pp" pos= "0 -0.00345683 -0.03414407"/>
                                        <body name="index_pp_sens">
                                        </body>
                                        <body name="index_mp_virt" pos="0 0.00057641 0.02611802">
                                            <joint name="index_pp2mp_virt" axis="1 0 0" range="-0.131 0.960"/>
                                            <inertial pos ="0 0 0" mass="0.001" diaginertia="4E-10 4E-10 3E-10"/>
                                            <body name="index_mp" pos="0 -0.00080968 0.01104305">
                                                <joint name="index_pp2mp" axis="1 0 0" range="-0.131 0.960"/>
                                                <geom mesh="index_mp" pos="0 -0.0029099 -0.07130514"/>
                                                <body name="index_dp_virt" pos="0 -0.00027599 0.01697596">
                                                    <joint name="index_mp2dp_virt" axis="1 0 0" range="-0.093 0.682"/>
                                                    <inertial pos ="0 0 -0.1" mass="0.001" diaginertia="4E-10 4E-10 3E-10"/>
                                                    <body name="index_dp" pos="0 -0.00083781 0.00827539">
                                                        <joint name="index_mp2dp" axis="1 0 0" range="-0.093 0.682"/>
                                                        <geom mesh="index_dp" pos="0 -0.0017961 -0.09655649"/>
                                                        <body name="index_fingertip" pos="0 0 0.01309">
                                                        </body>
                                                    </body>
                                                </body>
                                            </body>
                                        </body>
                                    </body>
                                </body>
                            </body>
                        </body>
                    </body>
                    
                    <body name="middle_base" pos = " 0.02163081458 -0.002 0.060168462" euler="0.0 -0.174533  0.0">
                        <geom mesh="middle_base"/>
                        <body name="middle_um_virt" pos="0 0 0.00527505">
                            <joint name="middle_abd_virt" axis="0 1 0" range="-0.264 0.264"/>
                            <inertial pos ="0 0 0" mass = "0.001" diaginertia="4E-10 4E-10 3E-10"/>
                            <body name="middle_um" pos="0 0 0.01789991">
                                <joint name="middle_abd" axis="0 1 0" range="-0.264 0.264"/>
                                <geom mesh="middle_um" pos = "0 0 -0.02317496" />
                                <body name="middle_pp_virt" pos="0 0.0033 -0.00625608">
                                    <joint name="root2middle_pp_virt" axis="1 0 0"  range="-0.157 0.829"/>
                                    <inertial pos ="0 0 0" mass="0.001" diaginertia="4E-10 4E-10 3E-10"/>
                                    <body name="middle_pp" pos="0 -0.00015683 0.01722519" >
                                        <joint name="root2middle_pp" axis="1 0 0" range="-0.157 0.829"/>
                                        <geom mesh="middle_pp" pos= "0 -0.00345683 -0.03414407"/>
                                        <body name="middle_pp_sens">
                                        </body>
                                        <body name="middle_mp_virt" pos="0 0.00057641 0.02611802">
                                            <joint name="middle_pp2mp_virt" axis="1 0 0" range="-0.131 0.960"/>
                                            <inertial pos ="0 0 0" mass="0.001" diaginertia="4E-10 4E-10 3E-10"/>
                                            <body name="middle_mp" pos="0 -0.00080968 0.01104305">
                                                <joint name="middle_pp2mp" axis="1 0 0" range="-0.131 0.960" />
                                                <geom mesh="middle_mp" pos="0 -0.0029099 -0.07130514"/>
                                                <body name="middle_dp_virt" pos="0 -0.00027599 0.01697596">
                                                    <joint name="middle_mp2dp_virt" axis="1 0 0" range="-0.093 0.682"/>
                                                    <inertial pos ="0 0 -0.1" mass="0.001" diaginertia="4E-10 4E-10 3E-10"/>
                                                    <body name="middle_dp" pos="0 -0.00083781 0.00827539">
                                                        <joint name="middle_mp2dp" axis="1 0 0" range="-0.093 0.682"/>
                                                        <geom mesh="middle_dp" pos="0 -0.0017961 -0.09655649"/>
                                                        <body name="middle_fingertip" pos="0 0 0.01309">
                                                        </body>
                                                    </body>
                                                </body>
                                            </body>
                                        </body>
                                    </body>
                                </body>
                            </body>
                        </body>
                    </body>

                    <body name="ring_base" pos="0.002691840889 -0.002 0.056250672" euler="0.0 -0.3490658504  0.0">
                        <geom mesh="ring_base"/>
                        <body name="ring_um_virt" pos="0 0 0.00527505">
                            <joint name="ring_abd_virt" axis="0 1 0" range="-0.264 0.264"/>
                            <inertial pos ="0 0 0" mass = "0.001" diaginertia="4E-10 4E-10 3E-10"/>
                            <body name="ring_um" pos="0 0 0.01789991">
                                <joint name="ring_abd" axis="0 1 0" range="-0.264 0.264"/>
                                <geom mesh="ring_um" pos = "0 0 -0.02317496"/>
                                <body name="ring_pp_virt" pos="0 0.0033 -0.00625608">
                                    <joint name="root2ring_pp_virt" axis="1 0 0" range="-0.157 0.829"/>
                                    <inertial pos ="0 0 0" mass="0.001" diaginertia="4E-10 4E-10 3E-10"/>
                                    <body name="ring_pp" pos="0 -0.00015683 0.01722519" >
                                        <joint name="root2ring_pp" axis="1 0 0" range="-0.157 0.829"/>
                                        <geom mesh="ring_pp" pos= "0 -0.00345683 -0.03414407"/>
                                        <body name="ring_pp_sens">
                                        </body>
                                        <body name="ring_mp_virt" pos="0 0.00057641 0.02611802">
                                            <joint name="ring_pp2mp_virt" axis="1 0 0" range="-0.131 0.960"/>
                                            <inertial pos ="0 0 0" mass="0.001" diaginertia="4E-10 4E-10 3E-10"/>
                                            <body name="ring_mp" pos="0 -0.00080968 0.01104305">
                                                <joint name="ring_pp2mp" axis="1 0 0" range="-0.131 0.960"/>
                                                <geom mesh="ring_mp" pos="0 -0.0029099 -0.07130514"/>
                                                <body name="ring_dp_virt" pos="0 -0.00027599 0.01697596">
                                                    <joint name="ring_mp2dp_virt" axis="1 0 0" range="-0.093 0.682"/>
                                                    <inertial pos ="0  0 0.01" mass="0.001" diaginertia="4E-10 4E-10 3E-10"/>
                                                    <body name="ring_dp" pos="0 -0.00083781 0.00827539">
                                                        <joint name="ring_mp2dp" axis="1 0 0" range="-0.093 0.682"/>
                                                        <geom mesh="ring_dp" pos="0 -0.0017961 -0.09655649"/>
                                                        <body name="ring_fingertip" pos="0 0 0.01309">
                                                        </body>
                                                    </body>
                                                </body>
                                            </body>
                                        </body>
                                    </body>
                                </body>
                            </body>
                        </body>
                    </body>

                    <body name="pinky_base" pos="-0.01537994548 -0.002 0.048767481" euler="0.0 -0.436332313 0.0">
                        <geom mesh="pinky_base"/>
                        <body name="pinky_um_virt" pos="0 0 0.00527505">
                            <joint name="pinky_abd_virt" axis="0 1 0" range="-0.264 0.264"/>
                            <inertial pos ="0 0 0" mass = "0.001" diaginertia="4E-10 4E-10 3E-10"/>
                            <body name="pinky_um" pos="0 0 0.01789991">
                                <joint name="pinky_abd" axis="0 1 0" range="-0.264 0.264"/>
                                <geom mesh="pinky_um" pos = "0 0 -0.02317496"/>
                                <body name="pinky_pp_virt" pos="0 0.0033 -0.00625608">
                                    <joint name="root2pinky_pp_virt" axis="1 0 0" range="-0.157 0.829"/>
                                    <inertial pos ="0 0 0" mass="0.001" diaginertia="4E-10 4E-10 3E-10"/>
                                    <body name="pinky_pp" pos="0 -0.00015683 0.01722519" >
                                        <joint name="root2pinky_pp" axis="1 0 0" range="-0.157 0.829"/>
                                        <geom mesh="pinky_pp" pos= "0 -0.00345683 -0.03414407"/>
                                        <body name="pinky_pp_sens">
                                        </body>
                                        <body name="pinky_mp_virt" pos="0 0.00057641 0.02611802">
                                            <joint name="pinky_pp2mp_virt" axis="1 0 0" range="-0.131 0.960"/>
                                            <inertial pos ="0 0 0" mass="0.001" diaginertia="4E-10 4E-10 3E-10"/>
                                            <body name="pinky_mp" pos="0 -0.00080968 0.01104305">
                                                <joint name="pinky_pp2mp" axis="1 0 0" range="-0.131 0.960"/>
                                                <geom mesh="pinky_mp" pos="0 -0.0029099 -0.07130514"/>
                                                <body name="pinky_dp_virt" pos="0 -0.00027599 0.01697596">
                                                    <joint name="pinky_mp2dp_virt" axis="1 0 0" range="-0.093 0.682"/>
                                                    <inertial pos ="0 0 -0.1" mass="0.001" diaginertia="4E-10 4E-10 3E-10"/>
                                                    <body name="pinky_dp" pos="0 -0.00083781 0.00827539">
                                                        <joint name="pinky_mp2dp" axis="1 0 0" range="-0.093 0.682"/>
                                                        <geom mesh="pinky_dp" pos="0 -0.0017961 -0.09655649"/>
                                                        <body name="pinky_fingertip" pos="0 0 0.01309">
                                                        </body>
                                                    </body>
                                                </body>
                                            </body>
                                        </body>
                                    </body>
                                </body>
                            </body>
                        </body>
                    </body>
                    
            </body>
        </body>
</mujoco>